Workbook

Sheet 目录
D2: 百万股 | E2: 股票名称 | F2: XXXX
C3: 财务估值模型V.12 | D3: 4 | E3: 最新报告期 | F3: XXXX-XX-XX
D4: 3 | E4: 最新年报报告期 | F4: XXXX-XX-XX
B5: 版权所有： 上海携宁计算机科技股份有限公司 | D5: 百万元 | E5: 估值日期 | F5: XXXX-XX-XX
B6: 联系电话： 18101638931(工作日)，18117554345(值班) | D6: 1e-06 | E6: 最新收盘价（元） | F6: XXXX
B7: E-mail ： modelsupport@sinitek.com | D7: =IF(D4>10,10,D4) -> 3 | E7: 最新总股本（百万） | F7: XXXX
B8: WebSite： www.sinitek.com | D8: =IF(LEN(D5)=1,"元",LEFT(D5,LEN(D5)-1)) -> 百万 | E8: 最新流通A股股本（百万） | F8: XXXX
B9: 下载地址： https://cloudmodel.sinitek.com | D9: 0 | E9: 最新行情日 | F9: XXXX-XX-XX
B11: 使用步骤： | E11: 重要提示：
B12: 1.使用本模型前请确保已下载并安装估值模型插件(携宁科技云估值)； | E12: 1.修改股票代码或重新选择历史数据年数后，需重新点击“提取历史数据”按钮来更新数据；
B13: 2.点击“提取历史数据”，在股票代码框中输入代码或名称，支持模糊搜索； | E13: 2.不能修改单元格内的公式，否则可能导致报表不平；
B14: 选择历史数据年数、货币单位等选项，可以设置更新范围； | E14: 3.不能增加/删除已有Sheet及已有Sheet中的行或列；
B15: 3.点击“预测数据设置”按钮可实现销售预测、资产预测的参数设置； | E15: 4.如有需要，可以自由增加Sheet，但不能修改已有Sheet名称；
B16: 4.点击“显示季度数据”可以展示/隐藏季度数据； | E16: 5.若弹窗提示"折旧摊销异常"，请前往投资与减值表填写折旧摊销数据；
B17: 5.点击“添加输出表”可进行输出表更新； | E17: 6.若弹窗提示"资本开支异常"，请前往投资与减值表填写当期资产增加值；
B18: 6.点击“导入历史模型”可实现历史预测数据迁移，支持V6-V12版本导入。 | E18: 7.若弹窗提示"资产负债表不平"，请打开空模型并通过"导入历史模型"功能将未配平模型导入。
B20: 公司经营数据 | C20: 自动生成的收入拆分数据 | E20: 参数填写说明：
B21: 销售预测 | C21: 用户填写相关假设，自动生成数据 | F21: 黄色底纹需手工填写数据
B22: 资产预测 | C22: 用户填写相关假设，自动生成数据
B23: 投资与减值 | C23: 用户填写相关假设，自动生成数据
B24: 主要财务摘要 | C24: 自动生成的财务指标计算结果 | F24: 金色边框可自由修改参数
B25: 报表摘要 | C25: 自动生成的财务指标计算结果
B26: 资产负债表 | C26: 用户填写相关假设，自动生成数据
B27: 利润表 | C27: 用户填写相关假设，自动生成数据 | F27: 蓝色底纹可以手工填写数据
B28: 现金流量表 | C28: 用户填写相关假设，自动生成数据
B29: 财务分析 | C29: 自动生成的财务指标计算结果
B30: 参数计算 | C30: 自动生成的财务指标计算结果
B31: 估值 | C31: 用户填写相关假设，自动生成数据
B32: 同业分析 | C32: 自动生成的同业分析数据
B33: 盈利敏感性分析 | C33: 用户填写相关假设，自动生成数据
B34: 单季度利润表 | C34: 自动生成的单季度利润表
B35: 财务基础数据 | C35: 自动生成的财务基础数据
B36: 财务附注数据 | C36: 自动生成的财务附注数据

Sheet 公司经营数据
A1: =目录!F2 -> XXXX | O1: 说明：1、预测年度可分项直接在黄色单元格填写各项目收入、成本金额，最后可以在第5行、第7行求和；
A2: ="单位:人民币"&目录!D5 -> 单位:人民币百万元 | O2: 2、请不要在A-AD列插入或删除列，不要更改表名，可能会影响数据提取！
O3: 3、此页数据更新可能会导致结构发生变化，可新建一个副本保存数据。
C4: 收入项目 | E4: =财务基础数据!J5 -> 2016 | F4: =财务基础数据!L5 -> 1H17 | G4: =财务基础数据!N5 -> 2017 | H4: =财务基础数据!P5 -> 1H18 | I4: =财务基础数据!R5 -> 2018 | J4: =财务基础数据!T5 -> 1H19 | K4: =财务基础数据!V5 -> 2019 | L4: =财务基础数据!X5 -> 1H20 | M4: =财务基础数据!Z5 -> 2020 | N4: =财务基础数据!AB5 -> 1H21 | O4: =财务基础数据!AD5 -> 2021 | P4: =财务基础数据!AF5 -> 1H22 | Q4: =财务基础数据!AH5 -> 2022 | R4: =财务基础数据!AJ5 -> 1H23 | S4: =财务基础数据!AL5 -> 2023 | T4: =财务基础数据!AN5 -> 1H24 | U4: =财务基础数据!AP5 -> 2024 | V4: =财务基础数据!AP5+1 -> 2025 | W4: =V4+1 -> 2026 | X4: =W4+1 -> 2027 | Y4: =X4+1 -> 2028 | Z4: =Y4+1 -> 2029 | AA4: =Z4+1 -> 2030 | AB4: =AA4+1 -> 2031 | AC4: =AB4+1 -> 2032 | AD4: =AC4+1 -> 2033
C5: 营业收入 | E5: =利润表!E8 -> 0 | F5: =利润表!G8 -> 0 | G5: =利润表!I8 -> 0 | H5: =利润表!K8 -> 0 | I5: =利润表!M8 -> 0 | J5: =利润表!O8 -> 0 | K5: =利润表!Q8 -> 0 | L5: =利润表!S8 -> 0 | M5: =利润表!U8 -> 0 | N5: =利润表!W8 -> 0 | O5: =利润表!Y8 -> 0 | P5: =利润表!AA8 -> 0 | Q5: =利润表!AC8 -> 0 | R5: =利润表!AE8 -> 0 | S5: =利润表!AG8 -> 0 | T5: =利润表!AI8 -> 0
C6: 增长率% | G6: =利润表!I9 -> — | H6: =利润表!K9 -> — | I6: =利润表!M9 -> — | J6: =利润表!O9 -> — | K6: =利润表!Q9 -> — | L6: =利润表!S9 -> — | M6: =利润表!U9 -> — | N6: =利润表!W9 -> — | O6: =利润表!Y9 -> — | P6: =利润表!AA9 -> — | Q6: =利润表!AC9 -> — | R6: =利润表!AE9 -> — | S6: =利润表!AG9 -> — | T6: =利润表!AI9 -> — | U6: =IF(ISERROR(U5/S5-1),0,U5/S5-1) -> 0 | V6: =IF(ISERROR(V5/U5-1),0,V5/U5-1) -> 0 | W6: =IF(ISERROR(W5/V5-1),0,W5/V5-1) -> 0 | X6: =IF(ISERROR(X5/W5-1),0,X5/W5-1) -> 0 | Y6: =IF(ISERROR(Y5/X5-1),0,Y5/X5-1) -> 0 | Z6: =IF(ISERROR(Z5/Y5-1),0,Z5/Y5-1) -> 0 | AA6: =IF(ISERROR(AA5/Z5-1),0,AA5/Z5-1) -> 0 | AB6: =IF(ISERROR(AB5/AA5-1),0,AB5/AA5-1) -> 0 | AC6: =IF(ISERROR(AC5/AB5-1),0,AC5/AB5-1) -> 0 | AD6: =IF(ISERROR(AD5/AC5-1),0,AD5/AC5-1) -> 0
C7: 营业成本 | E7: =利润表!E15 -> 0 | F7: =利润表!G15 -> 0 | G7: =利润表!I15 -> 0 | H7: =利润表!K15 -> 0 | I7: =利润表!M15 -> 0 | J7: =利润表!O15 -> 0 | K7: =利润表!Q15 -> 0 | L7: =利润表!S15 -> 0 | M7: =利润表!U15 -> 0 | N7: =利润表!W15 -> 0 | O7: =利润表!Y15 -> 0 | P7: =利润表!AA15 -> 0 | Q7: =利润表!AC15 -> 0 | R7: =利润表!AE15 -> 0 | S7: =利润表!AG15 -> 0 | T7: =利润表!AI15 -> 0
C8: 增长率% | G8: =利润表!I18 -> — | H8: =利润表!K18 -> — | I8: =利润表!M18 -> — | J8: =利润表!O18 -> — | K8: =利润表!Q18 -> — | L8: =利润表!S18 -> — | M8: =利润表!U18 -> — | N8: =利润表!W18 -> — | O8: =利润表!Y18 -> — | P8: =利润表!AA18 -> — | Q8: =利润表!AC18 -> — | R8: =利润表!AE18 -> — | S8: =利润表!AG18 -> — | T8: =利润表!AI18 -> — | U8: =IF(ISERROR(U7/S7-1),0,U7/S7-1) -> 0 | V8: =IF(ISERROR(V7/U7-1),0,V7/U7-1) -> 0 | W8: =IF(ISERROR(W7/V7-1),0,W7/V7-1) -> 0 | X8: =IF(ISERROR(X7/W7-1),0,X7/W7-1) -> 0 | Y8: =IF(ISERROR(Y7/X7-1),0,Y7/X7-1) -> 0 | Z8: =IF(ISERROR(Z7/Y7-1),0,Z7/Y7-1) -> 0 | AA8: =IF(ISERROR(AA7/Z7-1),0,AA7/Z7-1) -> 0 | AB8: =IF(ISERROR(AB7/AA7-1),0,AB7/AA7-1) -> 0 | AC8: =IF(ISERROR(AC7/AB7-1),0,AC7/AB7-1) -> 0 | AD8: =IF(ISERROR(AD7/AC7-1),0,AD7/AC7-1) -> 0
C9: 毛利 | E9: =E5-E7 -> 0 | F9: =F5-F7 -> 0 | G9: =G5-G7 -> 0 | H9: =H5-H7 -> 0 | I9: =I5-I7 -> 0 | J9: =J5-J7 -> 0 | K9: =K5-K7 -> 0 | L9: =L5-L7 -> 0 | ... U9: =U5-U7 -> 0 | V9: =IF(ISERROR(V5-V7),0,V5-V7) -> 0 | W9: =IF(ISERROR(W5-W7),0,W5-W7) -> 0 | X9: =IF(ISERROR(X5-X7),0,X5-X7) -> 0 | Y9: =IF(ISERROR(Y5-Y7),0,Y5-Y7) -> 0 | Z9: =IF(ISERROR(Z5-Z7),0,Z5-Z7) -> 0 | AA9: =IF(ISERROR(AA5-AA7),0,AA5-AA7) -> 0 | AB9: =IF(ISERROR(AB5-AB7),0,AB5-AB7) -> 0 | AC9: =IF(ISERROR(AC5-AC7),0,AC5-AC7) -> 0 | AD9: =IF(ISERROR(AD5-AD7),0,AD5-AD7) -> 0
C10: 毛利率 | E10: =IF(ISERROR(E9/E5),"—",E9/E5) -> — | F10: =IF(ISERROR(F9/F5),"—",F9/F5) -> — | G10: =IF(ISERROR(G9/G5),"—",G9/G5) -> — | H10: =IF(ISERROR(H9/H5),"—",H9/H5) -> — | I10: =IF(ISERROR(I9/I5),"—",I9/I5) -> — | J10: =IF(ISERROR(J9/J5),"—",J9/J5) -> — | K10: =IF(ISERROR(K9/K5),"—",K9/K5) -> — | L10: =IF(ISERROR(L9/L5),"—",L9/L5) -> — | ... T10: =IF(ISERROR(T9/T5),"—",T9/T5) -> — | U10: =IF(ISERROR(U9/U5),0,U9/U5) -> 0 | V10: =IF(ISERROR(V9/V5),0,V9/V5) -> 0 | W10: =IF(ISERROR(W9/W5),0,W9/W5) -> 0 | X10: =IF(ISERROR(X9/X5),0,X9/X5) -> 0 | Y10: =IF(ISERROR(Y9/Y5),0,Y9/Y5) -> 0 | Z10: =IF(ISERROR(Z9/Z5),0,Z9/Z5) -> 0 | AA10: =IF(ISERROR(AA9/AA5),0,AA9/AA5) -> 0 | AB10: =IF(ISERROR(AB9/AB5),0,AB9/AB5) -> 0 | ... AD10: =IF(ISERROR(AD9/AD5),0,AD9/AD5) -> 0

Sheet 销售预测
B1: 此页季度数据为单季度数据
B2: 产品收入成本 | I2: 注意：预测前三年可按照季度数据进行预测（如当前三季报已出，可直接在蓝色单元格填写第四季度数据），也可直接在黄色单元格填写年度预测数据
B3: ="单位：人民币"&目录!D5 -> 单位：人民币百万元
B4: 项 目 | I4: =利润表!Y4 -> 2021 | J4: =利润表!AC4 -> 2022 | K4: =利润表!AG4 -> 2023 | L4: =资产负债表!AK4 -> 2024E | M4: =资产负债表!AL4 -> 2025 | N4: =资产负债表!AM4 -> 2026 | O4: =资产负债表!AN4 -> 2027 | P4: =资产负债表!AO4 -> 2028 | Q4: =资产负债表!AP4 -> 2029 | R4: =资产负债表!AQ4 -> 2030 | S4: =资产负债表!AR4 -> 2031 | ... U4: =资产负债表!AT4 -> 2033 | W4: ="1Q"&利润表!Y4 -> 1Q2021 | X4: ="2Q"&利润表!Y4 -> 2Q2021 | Y4: ="3Q"&利润表!Y4 -> 3Q2021 | Z4: ="4Q"&利润表!Y4 -> 4Q2021 | AA4: ="1Q"&利润表!AC4 -> 1Q2022 | AB4: ="2Q"&利润表!AC4 -> 2Q2022 | AC4: ="3Q"&利润表!AC4 -> 3Q2022 | AD4: ="4Q"&利润表!AC4 -> 4Q2022 | AE4: ="1Q"&利润表!AG4 -> 1Q2023 | AF4: ="2Q"&利润表!AG4 -> 2Q2023 | AG4: ="3Q"&利润表!AG4 -> 3Q2023 | AH4: ="4Q"&利润表!AG4 -> 4Q2023 | AI4: ="1Q"&财务基础数据!AP5 -> 1Q2024 | AJ4: ="2Q"&财务基础数据!AP5 -> 2Q2024 | AK4: ="3Q"&财务基础数据!AP5 -> 3Q2024 | AL4: ="1Q"&财务基础数据!AP5 -> 1Q2024 | AM4: ="2Q"&财务基础数据!AP5 -> 2Q2024 | AN4: ="3Q"&财务基础数据!AP5 -> 3Q2024 | AO4: ="4Q"&财务基础数据!AP5 -> 4Q2024 | AP4: ="1Q"&财务基础数据!AP5+1 -> 1Q2025 | AQ4: ="2Q"&财务基础数据!AP5+1 -> 2Q2025 | AR4: ="3Q"&财务基础数据!AP5+1 -> 3Q2025 | AS4: ="4Q"&财务基础数据!AP5+1 -> 4Q2025 | AT4: ="1Q"&财务基础数据!AP5+2 -> 1Q2026 | AU4: ="2Q"&财务基础数据!AP5+2 -> 2Q2026 | AV4: ="3Q"&财务基础数据!AP5+2 -> 3Q2026 | AW4: ="4Q"&财务基础数据!AP5+2 -> 4Q2026
B5: 营业总收入 | I5: =利润表!Y6 -> 0 | J5: =利润表!AC6 -> 0 | K5: =利润表!AG6 -> 0 | L5: =L6+L8 -> 0 | M5: =M6+M8 -> 0 | N5: =N6+N8 -> 0 | O5: =O6+O8 -> 0 | P5: =P6+P8 -> 0 | Q5: =Q6+Q8 -> 0 | R5: =R6+R8 -> 0 | S5: =S6+S8 -> 0 | ... U5: =U6+U8 -> 0 | W5: =W6+W8 -> 0 | X5: =X6+X8 -> 0 | Y5: =Y6+Y8 -> 0 | Z5: =Z6+Z8 -> 0 | AA5: =AA6+AA8 -> 0 | AB5: =AB6+AB8 -> 0 | AC5: =AC6+AC8 -> 0 | AD5: =AD6+AD8 -> 0 | ... AK5: =AK6+AK8 -> 0 | AL5: =IF(ISERROR(AL6+AL8),"—",AL6+AL8) -> — | AM5: =IF(ISERROR(AM6+AM8),"—",AM6+AM8) -> — | AN5: =IF(ISERROR(AN6+AN8),"—",AN6+AN8) -> — | AO5: =AO6+AO8 -> 0 | AP5: =AP6+AP8 -> 0 | AQ5: =AQ6+AQ8 -> 0 | AR5: =AR6+AR8 -> 0 | AS5: =AS6+AS8 -> 0 | AT5: =AT6+AT8 -> 0 | AU5: =AU6+AU8 -> 0 | AV5: =AV6+AV8 -> 0 | AW5: =AW6+AW8 -> 0
B6: 营业收入 | I6: =利润表!Y8 -> 0 | J6: =利润表!AC8 -> 0 | K6: =利润表!AG8 -> 0 | W6: =利润表!V8 -> 0 | X6: =利润表!W8-利润表!V8 -> 0 | Y6: =利润表!X8-利润表!W8 -> 0 | Z6: =利润表!Y8-利润表!X8 -> 0 | AA6: =利润表!Z8 -> 0 | AB6: =利润表!AA8-利润表!Z8 -> 0 | AC6: =利润表!AB8-利润表!AA8 -> 0 | AD6: =利润表!AC8-利润表!AB8 -> 0 | AE6: =利润表!AD8 -> 0 | AF6: =利润表!AE8-利润表!AD8 -> 0 | AG6: =利润表!AF8-利润表!AE8 -> 0 | AH6: =利润表!AG8-利润表!AF8 -> 0 | AI6: =IF(财务基础数据!AM4=0,0,利润表!AH8) -> 0 | AJ6: =IF(财务基础数据!AM4<=1,0,利润表!AI8-利润表!AH8) -> 0 | AK6: =IF(财务基础数据!AM4<=2,0,利润表!AJ8-利润表!AI8) -> 0 | AL6: =IF(财务基础数据!AM4=0,"",AI6) | AM6: =IF(财务基础数据!AM4<=1,"",AJ6) | AN6: =IF(财务基础数据!AM4<=2,"",AK6)
B7: yoy(%) | I7: =IF(ISERROR((I6-利润表!U8)/ABS(利润表!U8)),"—",(I6-利润表!U8)/ABS(利润表!U8)) -> — | J7: =IF(ISERROR((J6-I6)/ABS(I6)),"—",(J6-I6)/ABS(I6)) -> — | K7: =IF(ISERROR((K6-J6)/ABS(J6)),"—",(K6-J6)/ABS(J6)) -> — | L7: =IF(ISERROR((L6-K6)/ABS(K6)),"—",(L6-K6)/ABS(K6)) -> — | M7: =IF(ISERROR((M6-L6)/ABS(L6)),"—",(M6-L6)/ABS(L6)) -> — | N7: =IF(ISERROR((N6-M6)/ABS(M6)),"—",(N6-M6)/ABS(M6)) -> — | O7: =IF(ISERROR((O6-N6)/ABS(N6)),"—",(O6-N6)/ABS(N6)) -> — | P7: =IF(ISERROR((P6-O6)/ABS(O6)),"—",(P6-O6)/ABS(O6)) -> — | Q7: =IF(ISERROR((Q6-P6)/ABS(P6)),"—",(Q6-P6)/ABS(P6)) -> — | ... U7: =IF(ISERROR((U6-T6)/ABS(T6)),"—",(U6-T6)/ABS(T6)) -> — | AA7: =IF(ISERROR((AA6-W6)/ABS(W6)),"—",(AA6-W6)/ABS(W6)) -> — | AB7: =IF(ISERROR((AB6-X6)/ABS(X6)),"—",(AB6-X6)/ABS(X6)) -> — | AC7: =IF(ISERROR((AC6-Y6)/ABS(Y6)),"—",(AC6-Y6)/ABS(Y6)) -> — | AD7: =IF(ISERROR((AD6-Z6)/ABS(Z6)),"—",(AD6-Z6)/ABS(Z6)) -> — | AE7: =IF(ISERROR((AE6-AA6)/ABS(AA6)),"—",(AE6-AA6)/ABS(AA6)) -> — | AF7: =IF(ISERROR((AF6-AB6)/ABS(AB6)),"—",(AF6-AB6)/ABS(AB6)) -> — | AG7: =IF(ISERROR((AG6-AC6)/ABS(AC6)),"—",(AG6-AC6)/ABS(AC6)) -> — | AH7: =IF(ISERROR((AH6-AD6)/ABS(AD6)),"—",(AH6-AD6)/ABS(AD6)) -> — | ... AK7: =IF(ISERROR((AK6-AG6)/ABS(AG6)),"—",(AK6-AG6)/ABS(AG6)) -> — | AL7: =IF(ISERROR((AL6-AE6)/ABS(AE6)),"—",(AL6-AE6)/ABS(AE6)) -> — | AM7: =IF(ISERROR((AM6-AF6)/ABS(AF6)),"—",(AM6-AF6)/ABS(AF6)) -> — | AN7: =IF(ISERROR((AN6-AG6)/ABS(AG6)),"—",(AN6-AG6)/ABS(AG6)) -> — | AO7: =IF(ISERROR((AO6-AH6)/ABS(AH6)),"—",(AO6-AH6)/ABS(AH6)) -> — | AP7: =IF(ISERROR((AP6-AL6)/ABS(AL6)),"—",(AP6-AL6)/ABS(AL6)) -> — | AQ7: =IF(ISERROR((AQ6-AM6)/ABS(AM6)),"—",(AQ6-AM6)/ABS(AM6)) -> — | AR7: =IF(ISERROR((AR6-AN6)/ABS(AN6)),"—",(AR6-AN6)/ABS(AN6)) -> — | AS7: =IF(ISERROR((AS6-AO6)/ABS(AO6)),"—",(AS6-AO6)/ABS(AO6)) -> — | AT7: =IF(ISERROR((AT6-AP6)/ABS(AP6)),"—",(AT6-AP6)/ABS(AP6)) -> — | AU7: =IF(ISERROR((AU6-AQ6)/ABS(AQ6)),"—",(AU6-AQ6)/ABS(AQ6)) -> — | AV7: =IF(ISERROR((AV6-AR6)/ABS(AR6)),"—",(AV6-AR6)/ABS(AR6)) -> — | AW7: =IF(ISERROR((AW6-AS6)/ABS(AS6)),"—",(AW6-AS6)/ABS(AS6)) -> —
B8: 其他金融类业务收入 | I8: =利润表!Y10 -> 0 | J8: =利润表!AC10 -> 0 | K8: =利润表!AG10 -> 0 | W8: =利润表!V10 -> 0 | X8: =利润表!W10-利润表!V10 -> 0 | Y8: =利润表!X10-利润表!W10 -> 0 | Z8: =利润表!Y10-利润表!X10 -> 0 | AA8: =利润表!Z10 -> 0 | AB8: =利润表!AA10-利润表!Z10 -> 0 | AC8: =利润表!AB10-利润表!AA10 -> 0 | AD8: =利润表!AC10-利润表!AB10 -> 0 | AE8: =利润表!AD10 -> 0 | AF8: =利润表!AE10-利润表!AD10 -> 0 | AG8: =利润表!AF10-利润表!AE10 -> 0 | AH8: =利润表!AG10-利润表!AF10 -> 0 | AI8: =IF(财务基础数据!AM4=0,0,利润表!AH10) -> 0 | AJ8: =IF(财务基础数据!AM4<=1,0,利润表!AI10-利润表!AH10) -> 0 | AK8: =IF(财务基础数据!AM4<=2,0,利润表!AJ10-利润表!AI10) -> 0 | AL8: =IF(财务基础数据!AM4=0,"",AI8) | AM8: =IF(财务基础数据!AM4<=1,"",AJ8) | AN8: =IF(财务基础数据!AM4<=2,"",AK8)
B9: 营业成本 | I9: =I10+I12 -> 0 | J9: =J10+J12 -> 0 | K9: =K10+K12 -> 0 | L9: =L10+L12 -> 0 | M9: =M10+M12 -> 0 | N9: =N10+N12 -> 0 | O9: =O10+O12 -> 0 | P9: =P10+P12 -> 0 | ... U9: =U10+U12 -> 0 | W9: =W10+W12 -> 0 | X9: =X10+X12 -> 0 | Y9: =Y10+Y12 -> 0 | Z9: =Z10+Z12 -> 0 | AA9: =AA10+AA12 -> 0 | AB9: =AB10+AB12 -> 0 | AC9: =AC10+AC12 -> 0 | AD9: =AD10+AD12 -> 0 | ... AK9: =AK10+AK12 -> 0 | AL9: =IF(ISERROR(AL10+AL12),"—",AL10+AL12) -> — | AM9: =IF(ISERROR(AM10+AM12),"—",AM10+AM12) -> — | AN9: =IF(ISERROR(AN10+AN12),"—",AN10+AN12) -> — | AO9: =AO10+AO12 -> 0 | AP9: =AP10+AP12 -> 0 | AQ9: =AQ10+AQ12 -> 0 | AR9: =AR10+AR12 -> 0 | AS9: =AS10+AS12 -> 0 | AT9: =AT10+AT12 -> 0 | AU9: =AU10+AU12 -> 0 | AV9: =AV10+AV12 -> 0 | AW9: =AW10+AW12 -> 0
B10: 营业成本 | I10: =利润表!Y15 -> 0 | J10: =利润表!AC15 -> 0 | K10: =利润表!AG15 -> 0 | W10: =利润表!V15 -> 0 | X10: =利润表!W15-利润表!V15 -> 0 | Y10: =利润表!X15-利润表!W15 -> 0 | Z10: =利润表!Y15-利润表!X15 -> 0 | AA10: =利润表!Z15 -> 0 | AB10: =利润表!AA15-利润表!Z15 -> 0 | AC10: =利润表!AB15-利润表!AA15 -> 0 | AD10: =利润表!AC15-利润表!AB15 -> 0 | AE10: =利润表!AD15 -> 0 | AF10: =利润表!AE15-利润表!AD15 -> 0 | AG10: =利润表!AF15-利润表!AE15 -> 0 | AH10: =利润表!AG15-利润表!AF15 -> 0 | AI10: =IF(财务基础数据!AM4=0,0,利润表!AH15) -> 0 | AJ10: =IF(财务基础数据!AM4<=1,0,利润表!AI15-利润表!AH15) -> 0 | AK10: =IF(财务基础数据!AM4<=2,0,利润表!AJ15-利润表!AI15) -> 0 | AL10: =IF(财务基础数据!AM4=0,"",AI10) | AM10: =IF(财务基础数据!AM4<=1,"",AJ10) | AN10: =IF(财务基础数据!AM4<=2,"",AK10)
B11: yoy(%) | I11: =IF(ISERROR((I10-利润表!U15)/ABS(利润表!U15)),"—",(I10-利润表!U15)/ABS(利润表!U15)) -> — | J11: =IF(ISERROR((J10-I10)/ABS(I10)),"—",(J10-I10)/ABS(I10)) -> — | K11: =IF(ISERROR((K10-J10)/ABS(J10)),"—",(K10-J10)/ABS(J10)) -> — | L11: =IF(ISERROR((L10-K10)/ABS(K10)),"—",(L10-K10)/ABS(K10)) -> — | M11: =IF(ISERROR((M10-L10)/ABS(L10)),"—",(M10-L10)/ABS(L10)) -> — | N11: =IF(ISERROR((N10-M10)/ABS(M10)),"—",(N10-M10)/ABS(M10)) -> — | O11: =IF(ISERROR((O10-N10)/ABS(N10)),"—",(O10-N10)/ABS(N10)) -> — | P11: =IF(ISERROR((P10-O10)/ABS(O10)),"—",(P10-O10)/ABS(O10)) -> — | Q11: =IF(ISERROR((Q10-P10)/ABS(P10)),"—",(Q10-P10)/ABS(P10)) -> — | ... U11: =IF(ISERROR((U10-T10)/ABS(T10)),"—",(U10-T10)/ABS(T10)) -> — | AA11: =IF(ISERROR((AA10-W10)/ABS(W10)),"—",(AA10-W10)/ABS(W10)) -> — | AB11: =IF(ISERROR((AB10-X10)/ABS(X10)),"—",(AB10-X10)/ABS(X10)) -> — | AC11: =IF(ISERROR((AC10-Y10)/ABS(Y10)),"—",(AC10-Y10)/ABS(Y10)) -> — | AD11: =IF(ISERROR((AD10-Z10)/ABS(Z10)),"—",(AD10-Z10)/ABS(Z10)) -> — | AE11: =IF(ISERROR((AE10-AA10)/ABS(AA10)),"—",(AE10-AA10)/ABS(AA10)) -> — | AF11: =IF(ISERROR((AF10-AB10)/ABS(AB10)),"—",(AF10-AB10)/ABS(AB10)) -> — | AG11: =IF(ISERROR((AG10-AC10)/ABS(AC10)),"—",(AG10-AC10)/ABS(AC10)) -> — | AH11: =IF(ISERROR((AH10-AD10)/ABS(AD10)),"—",(AH10-AD10)/ABS(AD10)) -> — | ... AK11: =IF(ISERROR((AK10-AG10)/ABS(AG10)),"—",(AK10-AG10)/ABS(AG10)) -> — | AL11: =IF(ISERROR((AL10-AE10)/ABS(AE10)),"—",(AL10-AE10)/ABS(AE10)) -> — | AM11: =IF(ISERROR((AM10-AF10)/ABS(AF10)),"—",(AM10-AF10)/ABS(AF10)) -> — | AN11: =IF(ISERROR((AN10-AG10)/ABS(AG10)),"—",(AN10-AG10)/ABS(AG10)) -> — | AO11: =IF(ISERROR((AO10-AH10)/ABS(AH10)),"—",(AO10-AH10)/ABS(AH10)) -> — | AP11: =IF(ISERROR((AP10-AL10)/ABS(AL10)),"—",(AP10-AL10)/ABS(AL10)) -> — | AQ11: =IF(ISERROR((AQ10-AM10)/ABS(AM10)),"—",(AQ10-AM10)/ABS(AM10)) -> — | AR11: =IF(ISERROR((AR10-AN10)/ABS(AN10)),"—",(AR10-AN10)/ABS(AN10)) -> — | AS11: =IF(ISERROR((AS10-AO10)/ABS(AO10)),"—",(AS10-AO10)/ABS(AO10)) -> — | AT11: =IF(ISERROR((AT10-AP10)/ABS(AP10)),"—",(AT10-AP10)/ABS(AP10)) -> — | AU11: =IF(ISERROR((AU10-AQ10)/ABS(AQ10)),"—",(AU10-AQ10)/ABS(AQ10)) -> — | AV11: =IF(ISERROR((AV10-AR10)/ABS(AR10)),"—",(AV10-AR10)/ABS(AR10)) -> — | AW11: =IF(ISERROR((AW10-AS10)/ABS(AS10)),"—",(AW10-AS10)/ABS(AS10)) -> —
B12: 其他金融类业务成本 | I12: =利润表!Y19 -> 0 | J12: =利润表!AC19 -> 0 | K12: =利润表!AG19 -> 0 | W12: =利润表!V19 -> 0 | X12: =利润表!W19-利润表!V19 -> 0 | Y12: =利润表!X19-利润表!W19 -> 0 | Z12: =利润表!Y19-利润表!X19 -> 0 | AA12: =利润表!Z19 -> 0 | AB12: =利润表!AA19-利润表!Z19 -> 0 | AC12: =利润表!AB19-利润表!AA19 -> 0 | AD12: =利润表!AC19-利润表!AB19 -> 0 | AE12: =利润表!AD19 -> 0 | AF12: =利润表!AE19-利润表!AD19 -> 0 | AG12: =利润表!AF19-利润表!AE19 -> 0 | AH12: =利润表!AG19-利润表!AF19 -> 0 | AI12: =IF(财务基础数据!AM4=0,0,利润表!AH19) -> 0 | AJ12: =IF(财务基础数据!AM4<=1,0,利润表!AI19-利润表!AH19) -> 0 | AK12: =IF(财务基础数据!AM4<=2,0,利润表!AJ19-利润表!AI19) -> 0 | AL12: =IF(财务基础数据!AM4=0,"",AI12) | AM12: =IF(财务基础数据!AM4<=1,"",AJ12) | AN12: =IF(财务基础数据!AM4<=2,"",AK12)
B14: 毛利 | I14: =I6-I10 -> 0 | J14: =J6-J10 -> 0 | K14: =K6-K10 -> 0 | L14: =L6-L10 -> 0 | M14: =M6-M10 -> 0 | N14: =N6-N10 -> 0 | O14: =O6-O10 -> 0 | P14: =P6-P10 -> 0 | ... U14: =U6-U10 -> 0 | W14: =W6-W10 -> 0 | X14: =X6-X10 -> 0 | Y14: =Y6-Y10 -> 0 | Z14: =Z6-Z10 -> 0 | AA14: =AA6-AA10 -> 0 | AB14: =AB6-AB10 -> 0 | AC14: =AC6-AC10 -> 0 | AD14: =AD6-AD10 -> 0 | ... AK14: =AK6-AK10 -> 0 | AL14: =IF(ISERROR(AL6-AL10),"—",AL6-AL10) -> — | AM14: =IF(ISERROR(AM6-AM10),"—",AM6-AM10) -> — | AN14: =IF(ISERROR(AN6-AN10),"—",AN6-AN10) -> — | AO14: =IF(ISERROR(AO6-AO10),"—",AO6-AO10) -> 0 | AP14: =AP6-AP10 -> 0 | AQ14: =AQ6-AQ10 -> 0 | AR14: =AR6-AR10 -> 0 | AS14: =AS6-AS10 -> 0 | AT14: =AT6-AT10 -> 0 | AU14: =AU6-AU10 -> 0 | AV14: =AV6-AV10 -> 0 | AW14: =AW6-AW10 -> 0
B15: 毛利率 | I15: =IF(ISERROR(I14/I6),"—",I14/I6) -> — | J15: =IF(ISERROR(J14/J6),"—",J14/J6) -> — | K15: =IF(ISERROR(K14/K6),"—",K14/K6) -> — | L15: =IF(ISERROR(L14/L6),"—",L14/L6) -> — | M15: =IF(ISERROR(M14/M6),"—",M14/M6) -> — | N15: =IF(ISERROR(N14/N6),"—",N14/N6) -> — | O15: =IF(ISERROR(O14/O6),"—",O14/O6) -> — | P15: =IF(ISERROR(P14/P6),"—",P14/P6) -> — | ... U15: =IF(ISERROR(U14/U6),"—",U14/U6) -> — | W15: =IF(ISERROR(W14/W6),"—",W14/W6) -> — | X15: =IF(ISERROR(X14/X6),"—",X14/X6) -> — | Y15: =IF(ISERROR(Y14/Y6),"—",Y14/Y6) -> — | Z15: =IF(ISERROR(Z14/Z6),"—",Z14/Z6) -> — | AA15: =IF(ISERROR(AA14/AA6),"—",AA14/AA6) -> — | AB15: =IF(ISERROR(AB14/AB6),"—",AB14/AB6) -> — | AC15: =IF(ISERROR(AC14/AC6),"—",AC14/AC6) -> — | AD15: =IF(ISERROR(AD14/AD6),"—",AD14/AD6) -> — | ... AW15: =IF(ISERROR(AW14/AW6),"—",AW14/AW6) -> —
B18: 经营收益的其他假设 | I18: 说明：季度数据预测和年度数据预测不可同时生效，只可选择其中一种预测方式
B20: 项 目 | I20: =I4 -> 2021 | J20: =J4 -> 2022 | K20: =K4 -> 2023 | W20: =W4 -> 1Q2021 | X20: =X4 -> 2Q2021 | Y20: =Y4 -> 3Q2021 | Z20: =Z4 -> 4Q2021 | AA20: =AA4 -> 1Q2022 | AB20: =AB4 -> 2Q2022 | AC20: =AC4 -> 3Q2022 | AD20: =AD4 -> 4Q2022 | ... AW20: =AW4 -> 4Q2026
B21: 税金及附加 | I21: =利润表!Y27 -> 0 | J21: =利润表!AC27 -> 0 | K21: =利润表!AG27 -> 0 | L21: =IF(COUNT(AL22:AO22)=4,SUM(AL21:AO21),L22*L6) -> 0 | M21: =IF(COUNT(AP22:AS22)=4,SUM(AP21:AS21),M22*M6) -> 0 | N21: =IF(COUNT(AT22:AW22)=4,SUM(AT21:AW21),N22*N6) -> 0 | O21: =IF(ISERROR(O22*O6),"—",O22*O6) -> 0 | P21: =IF(ISERROR(P22*P6),"—",P22*P6) -> 0 | Q21: =IF(ISERROR(Q22*Q6),"—",Q22*Q6) -> 0 | R21: =IF(ISERROR(R22*R6),"—",R22*R6) -> 0 | S21: =IF(ISERROR(S22*S6),"—",S22*S6) -> 0 | T21: =IF(ISERROR(T22*T6),"—",T22*T6) -> 0 | U21: =IF(ISERROR(U22*U6),"—",U22*U6) -> 0 | W21: =利润表!V27 -> 0 | X21: =利润表!W27-利润表!V27 -> 0 | Y21: =利润表!X27-利润表!W27 -> 0 | Z21: =利润表!Y27-利润表!X27 -> 0 | AA21: =利润表!Z27 -> 0 | AB21: =利润表!AA27-利润表!Z27 -> 0 | AC21: =利润表!AB27-利润表!AA27 -> 0 | AD21: =利润表!AC27-利润表!AB27 -> 0 | AE21: =利润表!AD27 -> 0 | AF21: =利润表!AE27-利润表!AD27 -> 0 | AG21: =利润表!AF27-利润表!AE27 -> 0 | AH21: =利润表!AG27-利润表!AF27 -> 0 | AI21: =IF(财务基础数据!AM4=0,0,利润表!AH27) -> 0 | AJ21: =IF(财务基础数据!AM4<=1,0,利润表!AI27-利润表!AH27) -> 0 | AK21: =IF(财务基础数据!AM4<=2,0,利润表!AJ27-利润表!AI27) -> 0 | AL21: =IF(ISERROR(AL22*AL6),"—",AL22*AL6) -> — | AM21: =IF(ISERROR(AM22*AM6),"—",AM22*AM6) -> — | AN21: =IF(ISERROR(AN22*AN6),"—",AN22*AN6) -> — | AO21: =IF(ISERROR(AO22*AO6),"—",AO22*AO6) -> 0 | AP21: =IF(ISERROR(AP22*AP6),"—",AP22*AP6) -> 0 | AQ21: =IF(ISERROR(AQ22*AQ6),"—",AQ22*AQ6) -> 0 | AR21: =IF(ISERROR(AR22*AR6),"—",AR22*AR6) -> 0 | AS21: =IF(ISERROR(AS22*AS6),"—",AS22*AS6) -> 0 | ... AW21: =IF(ISERROR(AW22*AW6),"—",AW22*AW6) -> 0
B22: 税金及附加/营业收入 | I22: =IF(ISERROR(I21/I6),"—",I21/I6) -> — | J22: =IF(ISERROR(J21/J6),"—",J21/J6) -> — | K22: =IF(ISERROR(K21/K6),"—",K21/K6) -> — | W22: =IF(ISERROR(W21/W6),"—",W21/W6) -> — | X22: =IF(ISERROR(X21/X6),"—",X21/X6) -> — | Y22: =IF(ISERROR(Y21/Y6),"—",Y21/Y6) -> — | Z22: =IF(ISERROR(Z21/Z6),"—",Z21/Z6) -> — | AA22: =IF(ISERROR(AA21/AA6),"—",AA21/AA6) -> — | AB22: =IF(ISERROR(AB21/AB6),"—",AB21/AB6) -> — | AC22: =IF(ISERROR(AC21/AC6),"—",AC21/AC6) -> — | AD22: =IF(ISERROR(AD21/AD6),"—",AD21/AD6) -> — | ... AK22: =IF(ISERROR(AK21/AK6),"—",AK21/AK6) -> — | AL22: =IF(财务基础数据!AM4=0,"",AI22) | AM22: =IF(财务基础数据!AM4<=1,"",AJ22) | AN22: =IF(财务基础数据!AM4<=2,"",AK22)
B24: 销售费用 | I24: =利润表!Y29 -> 0 | J24: =利润表!AC29 -> 0 | K24: =利润表!AG29 -> 0 | L24: =IF(COUNT(AL25:AO25)=4,SUM(AL24:AO24),L25*L6) -> 0 | M24: =IF(COUNT(AP25:AS25)=4,SUM(AP24:AS24),M25*M6) -> 0 | N24: =IF(COUNT(AT25:AW25)=4,SUM(AT24:AW24),N25*N6) -> 0 | O24: =IF(ISERROR(O25*O6),"—",O25*O6) -> 0 | P24: =IF(ISERROR(P25*P6),"—",P25*P6) -> 0 | Q24: =IF(ISERROR(Q25*Q6),"—",Q25*Q6) -> 0 | R24: =IF(ISERROR(R25*R6),"—",R25*R6) -> 0 | S24: =IF(ISERROR(S25*S6),"—",S25*S6) -> 0 | T24: =IF(ISERROR(T25*T6),"—",T25*T6) -> 0 | U24: =IF(ISERROR(U25*U6),"—",U25*U6) -> 0 | W24: =利润表!V29 -> 0 | X24: =利润表!W29-利润表!V29 -> 0 | Y24: =利润表!X29-利润表!W29 -> 0 | Z24: =利润表!Y29-利润表!X29 -> 0 | AA24: =利润表!Z29 -> 0 | AB24: =利润表!AA29-利润表!Z29 -> 0 | AC24: =利润表!AB29-利润表!AA29 -> 0 | AD24: =利润表!AC29-利润表!AB29 -> 0 | AE24: =利润表!AD29 -> 0 | AF24: =利润表!AE29-利润表!AD29 -> 0 | AG24: =利润表!AF29-利润表!AE29 -> 0 | AH24: =利润表!AG29-利润表!AF29 -> 0 | AI24: =IF(财务基础数据!AM4=0,0,利润表!AH29) -> 0 | AJ24: =IF(财务基础数据!AM4<=1,0,利润表!AI29-利润表!AH29) -> 0 | AK24: =IF(财务基础数据!AM4<=2,0,利润表!AJ29-利润表!AI29) -> 0 | AL24: =IF(ISERROR(AL25*AL6),"—",AL25*AL6) -> — | AM24: =IF(ISERROR(AM25*AM6),"—",AM25*AM6) -> — | AN24: =IF(ISERROR(AN25*AN6),"—",AN25*AN6) -> — | AO24: =IF(ISERROR(AO25*AO6),"—",AO25*AO6) -> 0 | AP24: =IF(ISERROR(AP25*AP6),"—",AP25*AP6) -> 0 | AQ24: =IF(ISERROR(AQ25*AQ6),"—",AQ25*AQ6) -> 0 | AR24: =IF(ISERROR(AR25*AR6),"—",AR25*AR6) -> 0 | AS24: =IF(ISERROR(AS25*AS6),"—",AS25*AS6) -> 0 | ... AW24: =IF(ISERROR(AW25*AW6),"—",AW25*AW6) -> 0
B25: 销售费用/营业收入 | I25: =IF(ISERROR(I24/I6),"—",I24/I6) -> — | J25: =IF(ISERROR(J24/J6),"—",J24/J6) -> — | K25: =IF(ISERROR(K24/K6),"—",K24/K6) -> — | W25: =IF(ISERROR(W24/W6),"—",W24/W6) -> — | X25: =IF(ISERROR(X24/X6),"—",X24/X6) -> — | Y25: =IF(ISERROR(Y24/Y6),"—",Y24/Y6) -> — | Z25: =IF(ISERROR(Z24/Z6),"—",Z24/Z6) -> — | AA25: =IF(ISERROR(AA24/AA6),"—",AA24/AA6) -> — | AB25: =IF(ISERROR(AB24/AB6),"—",AB24/AB6) -> — | AC25: =IF(ISERROR(AC24/AC6),"—",AC24/AC6) -> — | AD25: =IF(ISERROR(AD24/AD6),"—",AD24/AD6) -> — | ... AK25: =IF(ISERROR(AK24/AK6),"—",AK24/AK6) -> — | AL25: =IF(财务基础数据!AM4=0,"",AI25) | AM25: =IF(财务基础数据!AM4<=1,"",AJ25) | AN25: =IF(财务基础数据!AM4<=2,"",AK25)
B27: 管理费用 | I27: =利润表!Y31 -> 0 | J27: =利润表!AC31 -> 0 | K27: =利润表!AG31 -> 0 | L27: =IF(COUNT(AL28:AO28)=4,SUM(AL27:AO27),L28*L6) -> 0 | M27: =IF(COUNT(AP28:AS28)=4,SUM(AP27:AS27),M28*M6) -> 0 | N27: =IF(COUNT(AT28:AW28)=4,SUM(AT27:AW27),N28*N6) -> 0 | O27: =IF(ISERROR(O28*O6),"—",O28*O6) -> 0 | P27: =IF(ISERROR(P28*P6),"—",P28*P6) -> 0 | Q27: =IF(ISERROR(Q28*Q6),"—",Q28*Q6) -> 0 | R27: =IF(ISERROR(R28*R6),"—",R28*R6) -> 0 | S27: =IF(ISERROR(S28*S6),"—",S28*S6) -> 0 | T27: =IF(ISERROR(T28*T6),"—",T28*T6) -> 0 | U27: =IF(ISERROR(U28*U6),"—",U28*U6) -> 0 | W27: =利润表!V31 -> 0 | X27: =利润表!W31-利润表!V31 -> 0 | Y27: =利润表!X31-利润表!W31 -> 0 | Z27: =利润表!Y31-利润表!X31 -> 0 | AA27: =利润表!Z31 -> 0 | AB27: =利润表!AA31-利润表!Z31 -> 0 | AC27: =利润表!AB31-利润表!AA31 -> 0 | AD27: =利润表!AC31-利润表!AB31 -> 0 | AE27: =利润表!AD31 -> 0 | AF27: =利润表!AE31-利润表!AD31 -> 0 | AG27: =利润表!AF31-利润表!AE31 -> 0 | AH27: =利润表!AG31-利润表!AF31 -> 0 | AI27: =IF(财务基础数据!AM4=0,0,利润表!AH31) -> 0 | AJ27: =IF(财务基础数据!AM4<=1,0,利润表!AI31-利润表!AH31) -> 0 | AK27: =IF(财务基础数据!AM4<=2,0,利润表!AJ31-利润表!AI31) -> 0 | AL27: =IF(ISERROR(AL28*AL6),"—",AL28*AL6) -> — | AM27: =IF(ISERROR(AM28*AM6),"—",AM28*AM6) -> — | AN27: =IF(ISERROR(AN28*AN6),"—",AN28*AN6) -> — | AO27: =IF(ISERROR(AO28*AO6),"—",AO28*AO6) -> 0 | AP27: =IF(ISERROR(AP28*AP6),"—",AP28*AP6) -> 0 | AQ27: =IF(ISERROR(AQ28*AQ6),"—",AQ28*AQ6) -> 0 | AR27: =IF(ISERROR(AR28*AR6),"—",AR28*AR6) -> 0 | AS27: =IF(ISERROR(AS28*AS6),"—",AS28*AS6) -> 0 | ... AW27: =IF(ISERROR(AW28*AW6),"—",AW28*AW6) -> 0
B28: 管理费用/营业收入 | I28: =IF(ISERROR(I27/I6),"—",I27/I6) -> — | J28: =IF(ISERROR(J27/J6),"—",J27/J6) -> — | K28: =IF(ISERROR(K27/K6),"—",K27/K6) -> — | W28: =IF(ISERROR(W27/W6),"—",W27/W6) -> — | X28: =IF(ISERROR(X27/X6),"—",X27/X6) -> — | Y28: =IF(ISERROR(Y27/Y6),"—",Y27/Y6) -> — | Z28: =IF(ISERROR(Z27/Z6),"—",Z27/Z6) -> — | AA28: =IF(ISERROR(AA27/AA6),"—",AA27/AA6) -> — | AB28: =IF(ISERROR(AB27/AB6),"—",AB27/AB6) -> — | AC28: =IF(ISERROR(AC27/AC6),"—",AC27/AC6) -> — | AD28: =IF(ISERROR(AD27/AD6),"—",AD27/AD6) -> — | ... AK28: =IF(ISERROR(AK27/AK6),"—",AK27/AK6) -> — | AL28: =IF(财务基础数据!AM4=0,"",AI28) | AM28: =IF(财务基础数据!AM4<=1,"",AJ28) | AN28: =IF(财务基础数据!AM4<=2,"",AK28)
B30: 研发费用 | I30: =利润表!Y33 -> 0 | J30: =利润表!AC33 -> 0 | K30: =利润表!AG33 -> 0 | L30: =IF(COUNT(AL31:AO31)=4,SUM(AL30:AO30),L31*L6) -> 0 | M30: =IF(COUNT(AP31:AS31)=4,SUM(AP30:AS30),M31*M6) -> 0 | N30: =IF(COUNT(AT31:AW31)=4,SUM(AT30:AW30),N31*N6) -> 0 | O30: =IF(ISERROR(O31*O6),"—",O31*O6) -> 0 | P30: =IF(ISERROR(P31*P6),"—",P31*P6) -> 0 | Q30: =IF(ISERROR(Q31*Q6),"—",Q31*Q6) -> 0 | R30: =IF(ISERROR(R31*R6),"—",R31*R6) -> 0 | S30: =IF(ISERROR(S31*S6),"—",S31*S6) -> 0 | T30: =IF(ISERROR(T31*T6),"—",T31*T6) -> 0 | U30: =IF(ISERROR(U31*U6),"—",U31*U6) -> 0 | W30: =利润表!V33 -> 0 | X30: =利润表!W33-利润表!V33 -> 0 | Y30: =利润表!X33-利润表!W33 -> 0 | Z30: =利润表!Y33-利润表!X33 -> 0 | AA30: =利润表!Z33 -> 0 | AB30: =利润表!AA33-利润表!Z33 -> 0 | AC30: =利润表!AB33-利润表!AA33 -> 0 | AD30: =利润表!AC33-利润表!AB33 -> 0 | AE30: =利润表!AD33 -> 0 | AF30: =利润表!AE33-利润表!AD33 -> 0 | AG30: =利润表!AF33-利润表!AE33 -> 0 | AH30: =利润表!AG33-利润表!AF33 -> 0 | AI30: =IF(财务基础数据!AM4=0,0,利润表!AH33) -> 0 | AJ30: =IF(财务基础数据!AM4<=1,0,利润表!AI33-利润表!AH33) -> 0 | AK30: =IF(财务基础数据!AM4<=2,0,利润表!AJ33-利润表!AI33) -> 0 | AL30: =IF(ISERROR(AL31*AL6),"—",AL31*AL6) -> — | AM30: =IF(ISERROR(AM31*AM6),"—",AM31*AM6) -> — | AN30: =IF(ISERROR(AN31*AN6),"—",AN31*AN6) -> — | AO30: =IF(ISERROR(AO31*AO6),"—",AO31*AO6) -> 0 | AP30: =IF(ISERROR(AP31*AP6),"—",AP31*AP6) -> 0 | AQ30: =IF(ISERROR(AQ31*AQ6),"—",AQ31*AQ6) -> 0 | AR30: =IF(ISERROR(AR31*AR6),"—",AR31*AR6) -> 0 | AS30: =IF(ISERROR(AS31*AS6),"—",AS31*AS6) -> 0 | ... AW30: =IF(ISERROR(AW31*AW6),"—",AW31*AW6) -> 0
B31: 研发费用/营业收入 | I31: =IF(ISERROR(I30/I6),"—",I30/I6) -> — | J31: =IF(ISERROR(J30/J6),"—",J30/J6) -> — | K31: =IF(ISERROR(K30/K6),"—",K30/K6) -> — | W31: =IF(ISERROR(W30/W6),"—",W30/W6) -> — | X31: =IF(ISERROR(X30/X6),"—",X30/X6) -> — | Y31: =IF(ISERROR(Y30/Y6),"—",Y30/Y6) -> — | Z31: =IF(ISERROR(Z30/Z6),"—",Z30/Z6) -> — | AA31: =IF(ISERROR(AA30/AA6),"—",AA30/AA6) -> — | AB31: =IF(ISERROR(AB30/AB6),"—",AB30/AB6) -> — | AC31: =IF(ISERROR(AC30/AC6),"—",AC30/AC6) -> — | AD31: =IF(ISERROR(AD30/AD6),"—",AD30/AD6) -> — | ... AK31: =IF(ISERROR(AK30/AK6),"—",AK30/AK6) -> — | AL31: =IF(财务基础数据!AM4=0,"",AI31) | AM31: =IF(财务基础数据!AM4<=1,"",AJ31) | AN31: =IF(财务基础数据!AM4<=2,"",AK31)
B33: 其他收益 | I33: =利润表!Y49 -> 0 | J33: =利润表!AC49 -> 0 | K33: =利润表!AG49 -> 0 | L33: =IF(COUNT(AL34:AO34)=4,SUM(AL33:AO33),L34*L6) -> 0 | M33: =IF(COUNT(AP34:AS34)=4,SUM(AP33:AS33),M34*M6) -> 0 | N33: =IF(COUNT(AT34:AW34)=4,SUM(AT33:AW33),N34*N6) -> 0 | O33: =O34*O6 -> 0 | P33: =P34*P6 -> 0 | Q33: =Q34*Q6 -> 0 | R33: =R34*R6 -> 0 | S33: =S34*S6 -> 0 | T33: =T34*T6 -> 0 | U33: =U34*U6 -> 0 | W33: =利润表!V49 -> 0 | X33: =利润表!W49-利润表!V49 -> 0 | Y33: =利润表!X49-利润表!W49 -> 0 | Z33: =利润表!Y49-利润表!X49 -> 0 | AA33: =利润表!Z49 -> 0 | AB33: =利润表!AA49-利润表!Z49 -> 0 | AC33: =利润表!AB49-利润表!AA49 -> 0 | AD33: =利润表!AC49-利润表!AB49 -> 0 | AE33: =利润表!AD49 -> 0 | AF33: =利润表!AE49-利润表!AD49 -> 0 | AG33: =利润表!AF49-利润表!AE49 -> 0 | AH33: =利润表!AG49-利润表!AF49 -> 0 | AI33: =IF(财务基础数据!AM4=0,0,利润表!AH49) -> 0 | AJ33: =IF(财务基础数据!AM4<=1,0,利润表!AI49-利润表!AH49) -> 0 | AK33: =IF(财务基础数据!AM4<=2,0,利润表!AJ49-利润表!AI49) -> 0 | AL33: =IF(ISERROR(AL34*AL6),"—",AL34*AL6) -> — | AM33: =IF(ISERROR(AM34*AM6),"—",AM34*AM6) -> — | AN33: =IF(ISERROR(AN34*AN6),"—",AN34*AN6) -> — | AO33: =IF(ISERROR(AO34*AO6),"—",AO34*AO6) -> 0 | AP33: =IF(ISERROR(AP34*AP6),"—",AP34*AP6) -> 0 | AQ33: =IF(ISERROR(AQ34*AQ6),"—",AQ34*AQ6) -> 0 | AR33: =IF(ISERROR(AR34*AR6),"—",AR34*AR6) -> 0 | AS33: =IF(ISERROR(AS34*AS6),"—",AS34*AS6) -> 0 | ... AW33: =IF(ISERROR(AW34*AW6),"—",AW34*AW6) -> 0
B34: 其他收益/营业收入 | I34: =IF(ISERROR(I33/I6),"—",I33/I6) -> — | J34: =IF(ISERROR(J33/J6),"—",J33/J6) -> — | K34: =IF(ISERROR(K33/K6),"—",K33/K6) -> — | W34: =IF(ISERROR(W33/W6),"—",W33/W6) -> — | X34: =IF(ISERROR(X33/X6),"—",X33/X6) -> — | Y34: =IF(ISERROR(Y33/Y6),"—",Y33/Y6) -> — | Z34: =IF(ISERROR(Z33/Z6),"—",Z33/Z6) -> — | AA34: =IF(ISERROR(AA33/AA6),"—",AA33/AA6) -> — | AB34: =IF(ISERROR(AB33/AB6),"—",AB33/AB6) -> — | AC34: =IF(ISERROR(AC33/AC6),"—",AC33/AC6) -> — | AD34: =IF(ISERROR(AD33/AD6),"—",AD33/AD6) -> — | ... AK34: =IF(ISERROR(AK33/AK6),"—",AK33/AK6) -> — | AL34: =IF(财务基础数据!AM4=0,"",AI34) | AM34: =IF(财务基础数据!AM4<=1,"",AJ34) | AN34: =IF(财务基础数据!AM4<=2,"",AK34)
B36: 投资收益 | I36: =利润表!Y51 -> 0 | J36: =利润表!AC51 -> 0 | K36: =利润表!AG51 -> 0 | L36: =IF(COUNT(AL37:AO37)=4,SUM(AL36:AO36),L37*L6) -> 0 | M36: =IF(COUNT(AP37:AS37)=4,SUM(AP36:AS36),M37*M6) -> 0 | N36: =IF(COUNT(AT37:AW37)=4,SUM(AT36:AW36),N37*N6) -> 0 | O36: =O37*O6 -> 0 | P36: =P37*P6 -> 0 | Q36: =Q37*Q6 -> 0 | R36: =R37*R6 -> 0 | S36: =S37*S6 -> 0 | T36: =T37*T6 -> 0 | U36: =U37*U6 -> 0 | W36: =利润表!V51 -> 0 | X36: =利润表!W51-利润表!V51 -> 0 | Y36: =利润表!X51-利润表!W51 -> 0 | Z36: =利润表!Y51-利润表!X51 -> 0 | AA36: =利润表!Z51 -> 0 | AB36: =利润表!AA51-利润表!Z51 -> 0 | AC36: =利润表!AB51-利润表!AA51 -> 0 | AD36: =利润表!AC51-利润表!AB51 -> 0 | AE36: =利润表!AD51 -> 0 | AF36: =利润表!AE51-利润表!AD51 -> 0 | AG36: =利润表!AF51-利润表!AE51 -> 0 | AH36: =利润表!AG51-利润表!AF51 -> 0 | AI36: =IF(财务基础数据!AM4=0,0,利润表!AH51) -> 0 | AJ36: =IF(财务基础数据!AM4<=1,0,利润表!AI51-利润表!AH51) -> 0 | AK36: =IF(财务基础数据!AM4<=2,0,利润表!AJ51-利润表!AI51) -> 0 | AL36: =IF(ISERROR(AL37*AL6),"—",AL37*AL6) -> — | AM36: =IF(ISERROR(AM37*AM6),"—",AM37*AM6) -> — | AN36: =IF(ISERROR(AN37*AN6),"—",AN37*AN6) -> — | AO36: =IF(ISERROR(AO37*AO6),"—",AO37*AO6) -> 0 | AP36: =IF(ISERROR(AP37*AP6),"—",AP37*AP6) -> 0 | AQ36: =IF(ISERROR(AQ37*AQ6),"—",AQ37*AQ6) -> 0 | AR36: =IF(ISERROR(AR37*AR6),"—",AR37*AR6) -> 0 | AS36: =IF(ISERROR(AS37*AS6),"—",AS37*AS6) -> 0 | ... AW36: =IF(ISERROR(AW37*AW6),"—",AW37*AW6) -> 0
B37: 投资收益/营业收入 | I37: =IF(ISERROR(I36/I6),"—",I36/I6) -> — | J37: =IF(ISERROR(J36/J6),"—",J36/J6) -> — | K37: =IF(ISERROR(K36/K6),"—",K36/K6) -> — | W37: =IF(ISERROR(W36/W6),"—",W36/W6) -> — | X37: =IF(ISERROR(X36/X6),"—",X36/X6) -> — | Y37: =IF(ISERROR(Y36/Y6),"—",Y36/Y6) -> — | Z37: =IF(ISERROR(Z36/Z6),"—",Z36/Z6) -> — | AA37: =IF(ISERROR(AA36/AA6),"—",AA36/AA6) -> — | AB37: =IF(ISERROR(AB36/AB6),"—",AB36/AB6) -> — | AC37: =IF(ISERROR(AC36/AC6),"—",AC36/AC6) -> — | AD37: =IF(ISERROR(AD36/AD6),"—",AD36/AD6) -> — | ... AK37: =IF(ISERROR(AK36/AK6),"—",AK36/AK6) -> — | AL37: =IF(财务基础数据!AM4=0,"",AI37) | AM37: =IF(财务基础数据!AM4<=1,"",AJ37) | AN37: =IF(财务基础数据!AM4<=2,"",AK37)
B39: 资产处置收益 | I39: =利润表!Y66 -> 0 | J39: =利润表!AC66 -> 0 | K39: =利润表!AG66 -> 0 | L39: =IF(COUNT(AL40:AO40)=4,SUM(AL39:AO39),L40*L6) -> 0 | M39: =IF(COUNT(AP40:AS40)=4,SUM(AP39:AS39),M40*M6) -> 0 | N39: =IF(COUNT(AT40:AW40)=4,SUM(AT39:AW39),N40*N6) -> 0 | O39: =O40*O6 -> 0 | P39: =P40*P6 -> 0 | Q39: =Q40*Q6 -> 0 | R39: =R40*R6 -> 0 | S39: =S40*S6 -> 0 | T39: =T40*T6 -> 0 | U39: =U40*U6 -> 0 | W39: =利润表!V66 -> 0 | X39: =利润表!W66-利润表!V66 -> 0 | Y39: =利润表!X66-利润表!W66 -> 0 | Z39: =利润表!Y66-利润表!X66 -> 0 | AA39: =利润表!Z66 -> 0 | AB39: =利润表!AA66-利润表!Z66 -> 0 | AC39: =利润表!AB66-利润表!AA66 -> 0 | AD39: =利润表!AC66-利润表!AB66 -> 0 | AE39: =利润表!AD66 -> 0 | AF39: =利润表!AE66-利润表!AD66 -> 0 | AG39: =利润表!AF66-利润表!AE66 -> 0 | AH39: =利润表!AG66-利润表!AF66 -> 0 | AI39: =IF(财务基础数据!AM4=0,0,利润表!AH66) -> 0 | AJ39: =IF(财务基础数据!AM4<=1,0,利润表!AI66-利润表!AH66) -> 0 | AK39: =IF(财务基础数据!AM4<=2,0,利润表!AJ66-利润表!AI66) -> 0 | AL39: =IF(ISERROR(AL40*AL6),"—",AL40*AL6) -> — | AM39: =IF(ISERROR(AM40*AM6),"—",AM40*AM6) -> — | AN39: =IF(ISERROR(AN40*AN6),"—",AN40*AN6) -> — | AO39: =IF(ISERROR(AO40*AO6),"—",AO40*AO6) -> 0 | AP39: =IF(ISERROR(AP40*AP6),"—",AP40*AP6) -> 0 | AQ39: =IF(ISERROR(AQ40*AQ6),"—",AQ40*AQ6) -> 0 | AR39: =IF(ISERROR(AR40*AR6),"—",AR40*AR6) -> 0 | AS39: =IF(ISERROR(AS40*AS6),"—",AS40*AS6) -> 0 | ... AW39: =IF(ISERROR(AW40*AW6),"—",AW40*AW6) -> 0
B40: 资产处置收益/营业收入 | I40: =IF(ISERROR(I39/I6),"—",I39/I6) -> — | J40: =IF(ISERROR(J39/J6),"—",J39/J6) -> — | K40: =IF(ISERROR(K39/K6),"—",K39/K6) -> — | W40: =IF(ISERROR(W39/W6),"—",W39/W6) -> — | X40: =IF(ISERROR(X39/X6),"—",X39/X6) -> — | Y40: =IF(ISERROR(Y39/Y6),"—",Y39/Y6) -> — | Z40: =IF(ISERROR(Z39/Z6),"—",Z39/Z6) -> — | AA40: =IF(ISERROR(AA39/AA6),"—",AA39/AA6) -> — | AB40: =IF(ISERROR(AB39/AB6),"—",AB39/AB6) -> — | AC40: =IF(ISERROR(AC39/AC6),"—",AC39/AC6) -> — | AD40: =IF(ISERROR(AD39/AD6),"—",AD39/AD6) -> — | ... AK40: =IF(ISERROR(AK39/AK6),"—",AK39/AK6) -> — | AL40: =IF(财务基础数据!AM4=0,"",AI40) | AM40: =IF(财务基础数据!AM4<=1,"",AJ40) | AN40: =IF(财务基础数据!AM4<=2,"",AK40)
B42: 营业外收入 | I42: =利润表!Y77 -> 0 | J42: =利润表!AC77 -> 0 | K42: =利润表!AG77 -> 0 | W42: =利润表!V77 -> 0 | X42: =利润表!W77-利润表!V77 -> 0 | Y42: =利润表!X77-利润表!W77 -> 0 | Z42: =利润表!Y77-利润表!X77 -> 0 | AA42: =利润表!Z77 -> 0 | AB42: =利润表!AA77-利润表!Z77 -> 0 | AC42: =利润表!AB77-利润表!AA77 -> 0 | AD42: =利润表!AC77-利润表!AB77 -> 0 | AE42: =利润表!AD77 -> 0 | AF42: =利润表!AE77-利润表!AD77 -> 0 | AG42: =利润表!AF77-利润表!AE77 -> 0 | AH42: =利润表!AG77-利润表!AF77 -> 0 | AI42: =IF(财务基础数据!AM4=0,0,利润表!AH77) -> 0 | AJ42: =IF(财务基础数据!AM4<=1,0,利润表!AI77-利润表!AH77) -> 0 | AK42: =IF(财务基础数据!AM4<=2,0,利润表!AJ77-利润表!AI77) -> 0 | AL42: =IF(财务基础数据!AM4=0,"",AI42) | AM42: =IF(财务基础数据!AM4<=1,"",AJ42) | AN42: =IF(财务基础数据!AM4<=2,"",AK42)
B43: 营业外支出 | I43: =利润表!Y79 -> 0 | J43: =利润表!AC79 -> 0 | K43: =利润表!AG79 -> 0 | W43: =利润表!V79 -> 0 | X43: =利润表!W79-利润表!V79 -> 0 | Y43: =利润表!X79-利润表!W79 -> 0 | Z43: =利润表!Y79-利润表!X79 -> 0 | AA43: =利润表!Z79 -> 0 | AB43: =利润表!AA79-利润表!Z79 -> 0 | AC43: =利润表!AB79-利润表!AA79 -> 0 | AD43: =利润表!AC79-利润表!AB79 -> 0 | AE43: =利润表!AD79 -> 0 | AF43: =利润表!AE79-利润表!AD79 -> 0 | AG43: =利润表!AF79-利润表!AE79 -> 0 | AH43: =利润表!AG79-利润表!AF79 -> 0 | AI43: =IF(财务基础数据!AM4=0,0,利润表!AH79) -> 0 | AJ43: =IF(财务基础数据!AM4<=1,0,利润表!AI79-利润表!AH79) -> 0 | AK43: =IF(财务基础数据!AM4<=2,0,利润表!AJ79-利润表!AI79) -> 0 | AL43: =IF(财务基础数据!AM4=0,"",AI43) | AM43: =IF(财务基础数据!AM4<=1,"",AJ43) | AN43: =IF(财务基础数据!AM4<=2,"",AK43)
B44: 营业外收支 | I44: =利润表!Y81 -> 0 | J44: =利润表!AC81 -> 0 | K44: =利润表!AG81 -> 0 | L44: =IF(ISERROR(L42-L43),"—",L42-L43) -> 0 | M44: =M42-M43 -> 0 | N44: =N42-N43 -> 0 | O44: =O42-O43 -> 0 | P44: =P42-P43 -> 0 | Q44: =Q42-Q43 -> 0 | R44: =R42-R43 -> 0 | S44: =S42-S43 -> 0 | T44: =T42-T43 -> 0 | U44: =U42-U43 -> 0 | W44: =利润表!V81 -> 0 | X44: =利润表!W81-利润表!V81 -> 0 | Y44: =利润表!X81-利润表!W81 -> 0 | Z44: =利润表!Y81-利润表!X81 -> 0 | AA44: =利润表!Z81 -> 0 | AB44: =利润表!AA81-利润表!Z81 -> 0 | AC44: =利润表!AB81-利润表!AA81 -> 0 | AD44: =利润表!AC81-利润表!AB81 -> 0 | AE44: =利润表!AD81 -> 0 | AF44: =利润表!AE81-利润表!AD81 -> 0 | AG44: =利润表!AF81-利润表!AE81 -> 0 | AH44: =利润表!AG81-利润表!AF81 -> 0 | AI44: =IF(财务基础数据!AM4=0,0,利润表!AH81) -> 0 | AJ44: =IF(财务基础数据!AM4<=1,0,利润表!AI81-利润表!AH81) -> 0 | AK44: =IF(财务基础数据!AM4<=2,0,利润表!AJ81-利润表!AI81) -> 0 | AL44: =IF(ISERROR(AL42-AL43),"—",AL42-AL43) -> — | AM44: =IF(ISERROR(AM42-AM43),"—",AM42-AM43) -> — | AN44: =IF(ISERROR(AN42-AN43),"—",AN42-AN43) -> — | AO44: =IF(ISERROR(AO42-AO43),"—",AO42-AO43) -> 0 | AP44: =IF(ISERROR(AP42-AP43),"—",AP42-AP43) -> 0 | AQ44: =IF(ISERROR(AQ42-AQ43),"—",AQ42-AQ43) -> 0 | AR44: =IF(ISERROR(AR42-AR43),"—",AR42-AR43) -> 0 | AS44: =IF(ISERROR(AS42-AS43),"—",AS42-AS43) -> 0 | ... AW44: =IF(ISERROR(AW42-AW43),"—",AW42-AW43) -> 0
B45: 其中：与处置资产无关的收支
B47: 所得税费用 | I47: =利润表!Y86 -> 0 | J47: =利润表!AC86 -> 0 | K47: =利润表!AG86 -> 0 | L47: =IF(COUNT(AL47:AO47)=4,SUM(AL47:AO47),利润表!AK84*L48) -> 0 | M47: =IF(COUNT(AP47:AS47)=4,SUM(AP47:AS47),利润表!AL84*M48) -> 0 | N47: =IF(COUNT(AT47:AW47)=4,SUM(AT47:AW47),利润表!AM84*N48) -> 0 | O47: =IF(ISERROR(利润表!AN84*O48),"—",利润表!AN84*O48) -> 0 | P47: =IF(ISERROR(利润表!AO84*P48),"—",利润表!AO84*P48) -> 0 | Q47: =IF(ISERROR(利润表!AP84*Q48),"—",利润表!AP84*Q48) -> 0 | R47: =IF(ISERROR(利润表!AQ84*R48),"—",利润表!AQ84*R48) -> 0 | S47: =IF(ISERROR(利润表!AR84*S48),"—",利润表!AR84*S48) -> 0 | T47: =IF(ISERROR(利润表!AS84*T48),"—",利润表!AS84*T48) -> 0 | U47: =IF(ISERROR(利润表!AT84*U48),"—",利润表!AT84*U48) -> 0 | W47: =利润表!V86 -> 0 | X47: =利润表!W86-利润表!V86 -> 0 | Y47: =利润表!X86-利润表!W86 -> 0 | Z47: =利润表!Y86-利润表!X86 -> 0 | AA47: =利润表!Z86 -> 0 | AB47: =利润表!AA86-利润表!Z86 -> 0 | AC47: =利润表!AB86-利润表!AA86 -> 0 | AD47: =利润表!AC86-利润表!AB86 -> 0 | AE47: =利润表!AD86 -> 0 | AF47: =利润表!AE86-利润表!AD86 -> 0 | AG47: =利润表!AF86-利润表!AE86 -> 0 | AH47: =利润表!AG86-利润表!AF86 -> 0 | AI47: =IF(财务基础数据!AM4=0,0,利润表!AH86) -> 0 | AJ47: =IF(财务基础数据!AM4<=1,0,利润表!AI86-利润表!AH86) -> 0 | AK47: =IF(财务基础数据!AM4<=2,0,利润表!AJ86-利润表!AI86) -> 0 | AL47: =IF(财务基础数据!AM4=0,"",AI47) | AM47: =IF(财务基础数据!AM4<=1,"",AJ47) | AN47: =IF(财务基础数据!AM4<=2,"",AK47)
B48: 所得税税率 | I48: =利润表!Y87 -> — | J48: =利润表!AC87 -> — | K48: =利润表!AG87 -> — | W48: =利润表!V87 -> — | X48: =X47/(利润表!W84-利润表!V84) -> #DIV/0! | Y48: =Y47/(利润表!X84-利润表!W84) -> #DIV/0! | Z48: =Z47/(利润表!Y84-利润表!X84) -> #DIV/0! | AA48: =利润表!Z87 -> — | AB48: =AB47/(利润表!AA84-利润表!Z84) -> #DIV/0! | AC48: =AC47/(利润表!AB84-利润表!AA84) -> #DIV/0! | AD48: =AD47/(利润表!AC84-利润表!AB84) -> #DIV/0! | AE48: =利润表!AD87 -> — | AF48: =AF47/(利润表!AE84-利润表!AD84) -> #DIV/0! | AG48: =AG47/(利润表!AF84-利润表!AE84) -> #DIV/0! | AH48: =AH47/(利润表!AG84-利润表!AF84) -> #DIV/0!
B50: 少数股东损益 | I50: =利润表!Y91 -> 0 | J50: =利润表!AC91 -> 0 | K50: =利润表!AG91 -> 0 | L50: =IF(COUNT(AL50:AO50)=4,SUM(AL50:AO50),L51*利润表!AK88) -> 0 | M50: =IF(COUNT(AP50:AS50)=4,SUM(AP50:AS50),M51*利润表!AL88) -> 0 | N50: =IF(COUNT(AT50:AW50)=4,SUM(AT50:AW50),N51*利润表!AM88) -> 0 | O50: =IF(ISERROR(O51*利润表!AN88),"—",O51*利润表!AN88) -> 0 | P50: =IF(ISERROR(P51*利润表!AO88),"—",P51*利润表!AO88) -> 0 | Q50: =IF(ISERROR(Q51*利润表!AP88),"—",Q51*利润表!AP88) -> 0 | R50: =IF(ISERROR(R51*利润表!AQ88),"—",R51*利润表!AQ88) -> 0 | S50: =IF(ISERROR(S51*利润表!AR88),"—",S51*利润表!AR88) -> 0 | T50: =IF(ISERROR(T51*利润表!AS88),"—",T51*利润表!AS88) -> 0 | U50: =IF(ISERROR(U51*利润表!AT88),"—",U51*利润表!AT88) -> 0 | W50: =利润表!V91 -> 0 | X50: =利润表!W91-利润表!V91 -> 0 | Y50: =利润表!X91-利润表!W91 -> 0 | Z50: =利润表!Y91-利润表!X91 -> 0 | AA50: =利润表!Z91 -> 0 | AB50: =利润表!AA91-利润表!Z91 -> 0 | AC50: =利润表!AB91-利润表!AA91 -> 0 | AD50: =利润表!AC91-利润表!AB91 -> 0 | AE50: =利润表!AD91 -> 0 | AF50: =利润表!AE91-利润表!AD91 -> 0 | AG50: =利润表!AF91-利润表!AE91 -> 0 | AH50: =利润表!AG91-利润表!AF91 -> 0 | AI50: =IF(财务基础数据!AM4=0,0,利润表!AH91) -> 0 | AJ50: =IF(财务基础数据!AM4<=1,0,利润表!AI91-利润表!AH91) -> 0 | AK50: =IF(财务基础数据!AM4<=2,0,利润表!AJ91-利润表!AI91) -> 0 | AL50: =IF(财务基础数据!AM4=0,"",AI50) | AM50: =IF(财务基础数据!AM4<=1,"",AJ50) | AN50: =IF(财务基础数据!AM4<=2,"",AK50)
B51: 少数股东损益/净利润 | I51: =利润表!Y92 -> — | J51: =利润表!AC92 -> — | K51: =利润表!AG92 -> — | W51: =利润表!V92 -> — | X51: =X50/(利润表!W88-利润表!V88) -> #DIV/0! | Y51: =Y50/(利润表!X88-利润表!W88) -> #DIV/0! | Z51: =Z50/(利润表!Y88-利润表!X88) -> #DIV/0! | AA51: =利润表!Z92 -> — | AB51: =AB50/(利润表!AA88-利润表!Z88) -> #DIV/0! | AC51: =AC50/(利润表!AB88-利润表!AA88) -> #DIV/0! | AD51: =AD50/(利润表!AC88-利润表!AB88) -> #DIV/0! | AE51: =利润表!AD92 -> — | AF51: =AF50/(利润表!AE88-利润表!AD88) -> #DIV/0! | AG51: =AG50/(利润表!AF88-利润表!AE88) -> #DIV/0! | AH51: =AH50/(利润表!AG88-利润表!AF88) -> #DIV/0!
B52: 合并产生的损益（直接计入权益）

Sheet 资产预测
B2: 营运资金
B3: ="单位：人民币"&目录!D5 -> 单位：人民币百万元
B4: 会计年度截止日：12/31 | F4: =资产负债表!Y4 -> 2021 | G4: =资产负债表!AC4 -> 2022 | H4: =资产负债表!AG4 -> 2023 | I4: =资产负债表!AH4 -> 1Q24 | J4: =资产负债表!AI4 -> 1H24 | K4: =资产负债表!AJ4 -> 3Q24 | L4: =资产负债表!AK4 -> 2024E | M4: =资产负债表!AL4 -> 2025 | N4: =资产负债表!AM4 -> 2026 | O4: =资产负债表!AN4 -> 2027 | ... U4: =资产负债表!AT4 -> 2033
B5: 营业收入 | F5: =利润表!Y8 -> 0 | G5: =利润表!AC8 -> 0 | H5: =利润表!AG8 -> 0 | I5: =利润表!AH8 -> 0 | J5: =利润表!AI8 -> 0 | K5: =利润表!AJ8 -> 0 | L5: =利润表!AK8 -> 0 | M5: =利润表!AL8 -> 0 | N5: =利润表!AM8 -> 0 | O5: =利润表!AN8 -> 0 | ... U5: =利润表!AT8 -> 0
B6: 营业成本 | F6: =利润表!Y15 -> 0 | G6: =利润表!AC15 -> 0 | H6: =利润表!AG15 -> 0 | I6: =利润表!AH15 -> 0 | J6: =利润表!AI15 -> 0 | K6: =利润表!AJ15 -> 0 | L6: =利润表!AK15 -> 0 | M6: =利润表!AL15 -> 0 | N6: =利润表!AM15 -> 0 | O6: =利润表!AN15 -> 0 | ... U6: =利润表!AT15 -> 0
B8: 流动资产
B9: 以下周转天数指标按照资产/负债科目的期末值计算
B10: 应收票据 | F10: =IF(ISERROR(资产负债表!Y11),0,资产负债表!Y11) -> 0 | G10: =IF(ISERROR(资产负债表!AC11),0,资产负债表!AC11) -> 0 | H10: =IF(ISERROR(资产负债表!AG11),0,资产负债表!AG11) -> 0 | I10: =IF(ISERROR(资产负债表!AH11),0,资产负债表!AH11) -> 0 | J10: =IF(ISERROR(资产负债表!AI11),0,资产负债表!AI11) -> 0 | K10: =IF(ISERROR(资产负债表!AJ11),0,资产负债表!AJ11) -> 0 | L10: =IF(ISERROR(L5/(360/L11)),0,L5/(360/L11)) -> 0 | M10: =IF(ISERROR(M5/(360/M11)),0,M5/(360/M11)) -> 0 | N10: =IF(ISERROR(N5/(360/N11)),0,N5/(360/N11)) -> 0 | O10: =IF(ISERROR(O5/(360/O11)),0,O5/(360/O11)) -> 0 | P10: =IF(ISERROR(P5/(360/P11)),0,P5/(360/P11)) -> 0 | Q10: =IF(ISERROR(Q5/(360/Q11)),0,Q5/(360/Q11)) -> 0 | R10: =IF(ISERROR(R5/(360/R11)),0,R5/(360/R11)) -> 0 | S10: =IF(ISERROR(S5/(360/S11)),0,S5/(360/S11)) -> 0 | ... U10: =IF(ISERROR(U5/(360/U11)),0,U5/(360/U11)) -> 0
C11: 周转天数（相对于营业收入） | F11: =IF(ISERROR(360/(F5/F10)),0,360/(F5/F10)) -> 0 | G11: =IF(ISERROR(360/(G5/G10)),0,360/(G5/G10)) -> 0 | H11: =IF(ISERROR(360/(H5/H10)),0,360/(H5/H10)) -> 0 | I11: =IF(ISERROR(360/(I5/I10)),0,360/(I5/I10)) -> 0 | J11: =IF(ISERROR(360/(J5/J10)),0,360/(J5/J10)) -> 0 | K11: =IF(ISERROR(360/(K5/K10)),0,360/(K5/K10)) -> 0
C12: 应收票据/营业收入（%） | F12: =IF(ISERROR(F10/F5),0,F10/F5) -> 0 | G12: =IF(ISERROR(G10/G5),0,G10/G5) -> 0 | H12: =IF(ISERROR(H10/H5),0,H10/H5) -> 0 | I12: =IF(ISERROR(I10/I5),0,I10/I5) -> 0 | J12: =IF(ISERROR(J10/J5),0,J10/J5) -> 0 | K12: =IF(ISERROR(K10/K5),0,K10/K5) -> 0 | L12: =IF(ISERROR(L10/L5),0,L10/L5) -> 0 | M12: =IF(ISERROR(M10/M5),0,M10/M5) -> 0 | ... U12: =IF(ISERROR(U10/U5),0,U10/U5) -> 0
B14: 应收账款 | F14: =IF(ISERROR(资产负债表!Y12),0,资产负债表!Y12) -> 0 | G14: =IF(ISERROR(资产负债表!AC12),0,资产负债表!AC12) -> 0 | H14: =IF(ISERROR(资产负债表!AG12),0,资产负债表!AG12) -> 0 | I14: =IF(ISERROR(资产负债表!AH12),0,资产负债表!AH12) -> 0 | J14: =IF(ISERROR(资产负债表!AI12),0,资产负债表!AI12) -> 0 | K14: =IF(ISERROR(资产负债表!AJ12),0,资产负债表!AJ12) -> 0 | L14: =IF(ISERROR(L5/(360/L15)),0,L5/(360/L15)) -> 0 | M14: =IF(ISERROR(M5/(360/M15)),0,M5/(360/M15)) -> 0 | N14: =IF(ISERROR(N5/(360/N15)),0,N5/(360/N15)) -> 0 | O14: =IF(ISERROR(O5/(360/O15)),0,O5/(360/O15)) -> 0 | P14: =IF(ISERROR(P5/(360/P15)),0,P5/(360/P15)) -> 0 | Q14: =IF(ISERROR(Q5/(360/Q15)),0,Q5/(360/Q15)) -> 0 | R14: =IF(ISERROR(R5/(360/R15)),0,R5/(360/R15)) -> 0 | S14: =IF(ISERROR(S5/(360/S15)),0,S5/(360/S15)) -> 0 | ... U14: =IF(ISERROR(U5/(360/U15)),0,U5/(360/U15)) -> 0
C15: 周转天数（相对于营业收入） | F15: =IF(ISERROR(360/(F5/F14)),0,360/(F5/F14)) -> 0 | G15: =IF(ISERROR(360/(G5/G14)),0,360/(G5/G14)) -> 0 | H15: =IF(ISERROR(360/(H5/H14)),0,360/(H5/H14)) -> 0 | I15: =IF(ISERROR(360/(I5/I14)),0,360/(I5/I14)) -> 0 | J15: =IF(ISERROR(360/(J5/J14)),0,360/(J5/J14)) -> 0 | K15: =IF(ISERROR(360/(K5/K14)),0,360/(K5/K14)) -> 0
C16: 应收账款/营业收入（%） | F16: =IF(ISERROR(F14/F5),0,F14/F5) -> 0 | G16: =IF(ISERROR(G14/G5),0,G14/G5) -> 0 | H16: =IF(ISERROR(H14/H5),0,H14/H5) -> 0 | I16: =IF(ISERROR(I14/I5),0,I14/I5) -> 0 | J16: =IF(ISERROR(J14/J5),0,J14/J5) -> 0 | K16: =IF(ISERROR(K14/K5),0,K14/K5) -> 0 | L16: =IF(ISERROR(L14/L5),0,L14/L5) -> 0 | M16: =IF(ISERROR(M14/M5),0,M14/M5) -> 0 | ... U16: =IF(ISERROR(U14/U5),0,U14/U5) -> 0
B18: 应收款项融资 | F18: =IF(ISERROR(资产负债表!Y13),0,资产负债表!Y13) -> 0 | G18: =IF(ISERROR(资产负债表!AC13),0,资产负债表!AC13) -> 0 | H18: =IF(ISERROR(资产负债表!AG13),0,资产负债表!AG13) -> 0 | I18: =IF(ISERROR(资产负债表!AH13),0,资产负债表!AH13) -> 0 | J18: =IF(ISERROR(资产负债表!AI13),0,资产负债表!AI13) -> 0 | K18: =IF(ISERROR(资产负债表!AJ13),0,资产负债表!AJ13) -> 0 | L18: =IF(ISERROR(L5*L19),0,L5*L19) -> 0 | M18: =IF(ISERROR(M5*M19),0,M5*M19) -> 0 | N18: =IF(ISERROR(N5*N19),0,N5*N19) -> 0 | O18: =IF(ISERROR(O5*O19),0,O5*O19) -> 0 | P18: =IF(ISERROR(P5*P19),0,P5*P19) -> 0 | Q18: =IF(ISERROR(Q5*Q19),0,Q5*Q19) -> 0 | R18: =IF(ISERROR(R5*R19),0,R5*R19) -> 0 | S18: =IF(ISERROR(S5*S19),0,S5*S19) -> 0 | ... U18: =IF(ISERROR(U5*U19),0,U5*U19) -> 0
C19: 比营业收入（%） | F19: =IF(ISERROR(F18/F5),0,F18/F5) -> 0 | G19: =IF(ISERROR(G18/G5),0,G18/G5) -> 0 | H19: =IF(ISERROR(H18/H5),0,H18/H5) -> 0 | I19: =IF(ISERROR(I18/I5),0,I18/I5) -> 0 | J19: =IF(ISERROR(J18/J5),0,J18/J5) -> 0 | K19: =IF(ISERROR(K18/K5),0,K18/K5) -> 0
B21: 预付账款 | F21: =资产负债表!Y14 -> 0 | G21: =资产负债表!AC14 -> 0 | H21: =资产负债表!AG14 -> 0 | I21: =资产负债表!AH14 -> 0 | J21: =资产负债表!AI14 -> 0 | K21: =资产负债表!AJ14 -> 0 | L21: =IF(ISERROR(L6*L22),0,L6*L22) -> 0 | M21: =IF(ISERROR(M6*M22),0,M6*M22) -> 0 | N21: =IF(ISERROR(N6*N22),0,N6*N22) -> 0 | O21: =IF(ISERROR(O6*O22),0,O6*O22) -> 0 | P21: =IF(ISERROR(P6*P22),0,P6*P22) -> 0 | Q21: =IF(ISERROR(Q6*Q22),0,Q6*Q22) -> 0 | R21: =IF(ISERROR(R6*R22),0,R6*R22) -> 0 | S21: =IF(ISERROR(S6*S22),0,S6*S22) -> 0 | ... U21: =IF(ISERROR(U6*U22),0,U6*U22) -> 0
C22: 比营业成本（%） | F22: =IF(ISERROR(F21/F6),0,F21/F6) -> 0 | G22: =IF(ISERROR(G21/G6),0,G21/G6) -> 0 | H22: =IF(ISERROR(H21/H6),0,H21/H6) -> 0 | I22: =IF(ISERROR(I21/I6),0,I21/I6) -> 0 | J22: =IF(ISERROR(J21/J6),0,J21/J6) -> 0 | K22: =IF(ISERROR(K21/K6),0,K21/K6) -> 0
B24: 其他应收款 | F24: =资产负债表!Y15 -> 0 | G24: =资产负债表!AC15 -> 0 | H24: =资产负债表!AG15 -> 0 | I24: =资产负债表!AH15 -> 0 | J24: =资产负债表!AI15 -> 0 | K24: =资产负债表!AJ15 -> 0 | L24: =IF(ISERROR(L5/(360/L25)),0,L5/(360/L25)) -> 0 | M24: =IF(ISERROR(M5/(360/M25)),0,M5/(360/M25)) -> 0 | N24: =IF(ISERROR(N5/(360/N25)),0,N5/(360/N25)) -> 0 | O24: =IF(ISERROR(O5/(360/O25)),0,O5/(360/O25)) -> 0 | P24: =IF(ISERROR(P5/(360/P25)),0,P5/(360/P25)) -> 0 | Q24: =IF(ISERROR(Q5/(360/Q25)),0,Q5/(360/Q25)) -> 0 | R24: =IF(ISERROR(R5/(360/R25)),0,R5/(360/R25)) -> 0 | S24: =IF(ISERROR(S5/(360/S25)),0,S5/(360/S25)) -> 0 | ... U24: =IF(ISERROR(U5/(360/U25)),0,U5/(360/U25)) -> 0
C25: 周转天数（相对于营业收入） | F25: =IF(ISERROR(360/(F5/F24)),0,360/(F5/F24)) -> 0 | G25: =IF(ISERROR(360/(G5/G24)),0,360/(G5/G24)) -> 0 | H25: =IF(ISERROR(360/(H5/H24)),0,360/(H5/H24)) -> 0 | I25: =IF(ISERROR(360/(I5/I24)),0,360/(I5/I24)) -> 0 | J25: =IF(ISERROR(360/(J5/J24)),0,360/(J5/J24)) -> 0 | K25: =IF(ISERROR(360/(K5/K24)),0,360/(K5/K24)) -> 0
C26: 其他应收款/营业收入（%） | F26: =IF(ISERROR(F24/F5),0,F24/F5) -> 0 | G26: =IF(ISERROR(G24/G5),0,G24/G5) -> 0 | H26: =IF(ISERROR(H24/H5),0,H24/H5) -> 0 | I26: =IF(ISERROR(I24/I5),0,I24/I5) -> 0 | J26: =IF(ISERROR(J24/J5),0,J24/J5) -> 0 | K26: =IF(ISERROR(K24/K5),0,K24/K5) -> 0 | L26: =IF(ISERROR(L24/L5),0,L24/L5) -> 0 | M26: =IF(ISERROR(M24/M5),0,M24/M5) -> 0 | ... U26: =IF(ISERROR(U24/U5),0,U24/U5) -> 0
B28: 存货 | F28: =资产负债表!Y16 -> 0 | G28: =资产负债表!AC16 -> 0 | H28: =资产负债表!AG16 -> 0 | I28: =资产负债表!AH16 -> 0 | J28: =资产负债表!AI16 -> 0 | K28: =资产负债表!AJ16 -> 0 | L28: =IF(ISERROR(L6/(360/L29)),0,L6/(360/L29)) -> 0 | M28: =IF(ISERROR(M6/(360/M29)),0,M6/(360/M29)) -> 0 | N28: =IF(ISERROR(N6/(360/N29)),0,N6/(360/N29)) -> 0 | O28: =IF(ISERROR(O6/(360/O29)),0,O6/(360/O29)) -> 0 | P28: =IF(ISERROR(P6/(360/P29)),0,P6/(360/P29)) -> 0 | Q28: =IF(ISERROR(Q6/(360/Q29)),0,Q6/(360/Q29)) -> 0 | R28: =IF(ISERROR(R6/(360/R29)),0,R6/(360/R29)) -> 0 | S28: =IF(ISERROR(S6/(360/S29)),0,S6/(360/S29)) -> 0 | ... U28: =IF(ISERROR(U6/(360/U29)),0,U6/(360/U29)) -> 0
C29: 周转天数（相对于营业成本） | F29: =IF(ISERROR(360/(F6/F28)),0,360/(F6/F28)) -> 0 | G29: =IF(ISERROR(360/(G6/G28)),0,360/(G6/G28)) -> 0 | H29: =IF(ISERROR(360/(H6/H28)),0,360/(H6/H28)) -> 0 | I29: =IF(ISERROR(360/(I6/I28)),0,360/(I6/I28)) -> 0 | J29: =IF(ISERROR(360/(J6/J28)),0,360/(J6/J28)) -> 0 | K29: =IF(ISERROR(360/(K6/K28)),0,360/(K6/K28)) -> 0
C30: 存货/营业成本（%） | F30: =IF(ISERROR(F28/F6),0,F28/F6) -> 0 | G30: =IF(ISERROR(G28/G6),0,G28/G6) -> 0 | H30: =IF(ISERROR(H28/H6),0,H28/H6) -> 0 | I30: =IF(ISERROR(I28/I6),0,I28/I6) -> 0 | J30: =IF(ISERROR(J28/J6),0,J28/J6) -> 0 | K30: =IF(ISERROR(K28/K6),0,K28/K6) -> 0 | L30: =IF(ISERROR(L28/L6),0,L28/L6) -> 0 | M30: =IF(ISERROR(M28/M6),0,M28/M6) -> 0 | ... U30: =IF(ISERROR(U28/U6),0,U28/U6) -> 0
B32: 合同资产 | F32: =资产负债表!Y17 -> 0 | G32: =资产负债表!AC17 -> 0 | H32: =资产负债表!AG17 -> 0 | I32: =资产负债表!AH17 -> 0 | J32: =资产负债表!AI17 -> 0 | K32: =资产负债表!AJ17 -> 0 | L32: =IF(ISERROR(L5*L33),0,L5*L33) -> 0 | M32: =IF(ISERROR(M5*M33),0,M5*M33) -> 0 | N32: =IF(ISERROR(N5*N33),0,N5*N33) -> 0 | O32: =IF(ISERROR(O5*O33),0,O5*O33) -> 0 | P32: =IF(ISERROR(P5*P33),0,P5*P33) -> 0 | Q32: =IF(ISERROR(Q5*Q33),0,Q5*Q33) -> 0 | R32: =IF(ISERROR(R5*R33),0,R5*R33) -> 0 | S32: =IF(ISERROR(S5*S33),0,S5*S33) -> 0 | ... U32: =IF(ISERROR(U5*U33),0,U5*U33) -> 0
C33: 比营业收入（%） | F33: =IF(ISERROR(F32/F5),0,F32/F5) -> 0 | G33: =IF(ISERROR(G32/G5),0,G32/G5) -> 0 | H33: =IF(ISERROR(H32/H5),0,H32/H5) -> 0 | I33: =IF(ISERROR(I32/I5),0,I32/I5) -> 0 | J33: =IF(ISERROR(J32/J5),0,J32/J5) -> 0 | K33: =IF(ISERROR(K32/K5),0,K32/K5) -> 0
B37: 流动负债
B38: 应付票据 | F38: =资产负债表!Y52 -> 0 | G38: =资产负债表!AC52 -> 0 | H38: =资产负债表!AG52 -> 0 | I38: =资产负债表!AH52 -> 0 | J38: =资产负债表!AI52 -> 0 | K38: =资产负债表!AJ52 -> 0 | L38: =IF(ISERROR(L6/(360/L39)),0,L6/(360/L39)) -> 0 | M38: =IF(ISERROR(M6/(360/M39)),0,M6/(360/M39)) -> 0 | N38: =IF(ISERROR(N6/(360/N39)),0,N6/(360/N39)) -> 0 | O38: =IF(ISERROR(O6/(360/O39)),0,O6/(360/O39)) -> 0 | P38: =IF(ISERROR(P6/(360/P39)),0,P6/(360/P39)) -> 0 | Q38: =IF(ISERROR(Q6/(360/Q39)),0,Q6/(360/Q39)) -> 0 | R38: =IF(ISERROR(R6/(360/R39)),0,R6/(360/R39)) -> 0 | S38: =IF(ISERROR(S6/(360/S39)),0,S6/(360/S39)) -> 0 | ... U38: =IF(ISERROR(U6/(360/U39)),0,U6/(360/U39)) -> 0
C39: 周转天数（相对于营业成本） | F39: =IF(ISERROR(360/(F6/F38)),0,360/(F6/F38)) -> 0 | G39: =IF(ISERROR(360/(G6/G38)),0,360/(G6/G38)) -> 0 | H39: =IF(ISERROR(360/(H6/H38)),0,360/(H6/H38)) -> 0 | I39: =IF(ISERROR(360/(I6/I38)),0,360/(I6/I38)) -> 0 | J39: =IF(ISERROR(360/(J6/J38)),0,360/(J6/J38)) -> 0 | K39: =IF(ISERROR(360/(K6/K38)),0,360/(K6/K38)) -> 0
C40: 应付票据/营业成本（%） | F40: =IF(ISERROR(F38/F6),0,F38/F6) -> 0 | G40: =IF(ISERROR(G38/G6),0,G38/G6) -> 0 | H40: =IF(ISERROR(H38/H6),0,H38/H6) -> 0 | I40: =IF(ISERROR(I38/I6),0,I38/I6) -> 0 | J40: =IF(ISERROR(J38/J6),0,J38/J6) -> 0 | K40: =IF(ISERROR(K38/K6),0,K38/K6) -> 0 | L40: =IF(ISERROR(L38/L6),0,L38/L6) -> 0 | M40: =IF(ISERROR(M38/M6),0,M38/M6) -> 0 | ... U40: =IF(ISERROR(U38/U6),0,U38/U6) -> 0
B42: 应付账款 | F42: =资产负债表!Y53 -> 0 | G42: =资产负债表!AC53 -> 0 | H42: =资产负债表!AG53 -> 0 | I42: =资产负债表!AH53 -> 0 | J42: =资产负债表!AI53 -> 0 | K42: =资产负债表!AJ53 -> 0 | L42: =IF(ISERROR(L6/(360/L43)),0,L6/(360/L43)) -> 0 | M42: =IF(ISERROR(M6/(360/M43)),0,M6/(360/M43)) -> 0 | N42: =IF(ISERROR(N6/(360/N43)),0,N6/(360/N43)) -> 0 | O42: =IF(ISERROR(O6/(360/O43)),0,O6/(360/O43)) -> 0 | P42: =IF(ISERROR(P6/(360/P43)),0,P6/(360/P43)) -> 0 | Q42: =IF(ISERROR(Q6/(360/Q43)),0,Q6/(360/Q43)) -> 0 | R42: =IF(ISERROR(R6/(360/R43)),0,R6/(360/R43)) -> 0 | S42: =IF(ISERROR(S6/(360/S43)),0,S6/(360/S43)) -> 0 | ... U42: =IF(ISERROR(U6/(360/U43)),0,U6/(360/U43)) -> 0
C43: 周转天数（相对于营业成本） | F43: =IF(ISERROR(360/(F6/F42)),0,360/(F6/F42)) -> 0 | G43: =IF(ISERROR(360/(G6/G42)),0,360/(G6/G42)) -> 0 | H43: =IF(ISERROR(360/(H6/H42)),0,360/(H6/H42)) -> 0 | I43: =IF(ISERROR(360/(I6/I42)),0,360/(I6/I42)) -> 0 | J43: =IF(ISERROR(360/(J6/J42)),0,360/(J6/J42)) -> 0 | K43: =IF(ISERROR(360/(K6/K42)),0,360/(K6/K42)) -> 0
C44: 应付账款/营业成本（%） | F44: =IF(ISERROR(F42/F6),0,F42/F6) -> 0 | G44: =IF(ISERROR(G42/G6),0,G42/G6) -> 0 | H44: =IF(ISERROR(H42/H6),0,H42/H6) -> 0 | I44: =IF(ISERROR(I42/I6),0,I42/I6) -> 0 | J44: =IF(ISERROR(J42/J6),0,J42/J6) -> 0 | K44: =IF(ISERROR(K42/K6),0,K42/K6) -> 0 | L44: =IF(ISERROR(L42/L6),0,L42/L6) -> 0 | M44: =IF(ISERROR(M42/M6),0,M42/M6) -> 0 | ... U44: =IF(ISERROR(U42/U6),0,U42/U6) -> 0
B46: 预收账款 | F46: =资产负债表!Y54 -> 0 | G46: =资产负债表!AC54 -> 0 | H46: =资产负债表!AG54 -> 0 | I46: =资产负债表!AH54 -> 0 | J46: =资产负债表!AI54 -> 0 | K46: =资产负债表!AJ54 -> 0 | L46: =IF(ISERROR(L5*L47),0,L5*L47) -> 0 | M46: =IF(ISERROR(M5*M47),0,M5*M47) -> 0 | N46: =IF(ISERROR(N5*N47),0,N5*N47) -> 0 | O46: =IF(ISERROR(O5*O47),0,O5*O47) -> 0 | P46: =IF(ISERROR(P5*P47),0,P5*P47) -> 0 | Q46: =IF(ISERROR(Q5*Q47),0,Q5*Q47) -> 0 | R46: =IF(ISERROR(R5*R47),0,R5*R47) -> 0 | S46: =IF(ISERROR(S5*S47),0,S5*S47) -> 0 | ... U46: =IF(ISERROR(U5*U47),0,U5*U47) -> 0
C47: 比营业收入（%） | F47: =IF(ISERROR(F46/F5),0,F46/F5) -> 0 | G47: =IF(ISERROR(G46/G5),0,G46/G5) -> 0 | H47: =IF(ISERROR(H46/H5),0,H46/H5) -> 0 | I47: =IF(ISERROR(I46/I5),0,I46/I5) -> 0 | J47: =IF(ISERROR(J46/J5),0,J46/J5) -> 0 | K47: =IF(ISERROR(K46/K5),0,K46/K5) -> 0
B49: 合同负债 | F49: =资产负债表!Y55 -> 0 | G49: =资产负债表!AC55 -> 0 | H49: =资产负债表!AG55 -> 0 | I49: =资产负债表!AH55 -> 0 | J49: =资产负债表!AI55 -> 0 | K49: =资产负债表!AJ55 -> 0 | L49: =IF(ISERROR(L5*L50),0,L5*L50) -> 0 | M49: =IF(ISERROR(M5*M50),0,M5*M50) -> 0 | N49: =IF(ISERROR(N5*N50),0,N5*N50) -> 0 | O49: =IF(ISERROR(O5*O50),0,O5*O50) -> 0 | P49: =IF(ISERROR(P5*P50),0,P5*P50) -> 0 | Q49: =IF(ISERROR(Q5*Q50),0,Q5*Q50) -> 0 | R49: =IF(ISERROR(R5*R50),0,R5*R50) -> 0 | S49: =IF(ISERROR(S5*S50),0,S5*S50) -> 0 | ... U49: =IF(ISERROR(U5*U50),0,U5*U50) -> 0
C50: 比营业收入（%） | F50: =IF(ISERROR(F49/F5),0,F49/F5) -> 0 | G50: =IF(ISERROR(G49/G5),0,G49/G5) -> 0 | H50: =IF(ISERROR(H49/H5),0,H49/H5) -> 0 | I50: =IF(ISERROR(I49/I5),0,I49/I5) -> 0 | J50: =IF(ISERROR(J49/J5),0,J49/J5) -> 0 | K50: =IF(ISERROR(K49/K5),0,K49/K5) -> 0
B52: 应付职工薪酬 | F52: =资产负债表!Y56 -> 0 | G52: =资产负债表!AC56 -> 0 | H52: =资产负债表!AG56 -> 0 | I52: =资产负债表!AH56 -> 0 | J52: =资产负债表!AI56 -> 0 | K52: =资产负债表!AJ56 -> 0 | L52: =IF(ISERROR(L53*L6),0,L53*L6) -> 0 | M52: =IF(ISERROR(M53*M6),0,M53*M6) -> 0 | N52: =IF(ISERROR(N53*N6),0,N53*N6) -> 0 | O52: =IF(ISERROR(O53*O6),0,O53*O6) -> 0 | P52: =IF(ISERROR(P53*P6),0,P53*P6) -> 0 | Q52: =IF(ISERROR(Q53*Q6),0,Q53*Q6) -> 0 | R52: =IF(ISERROR(R53*R6),0,R53*R6) -> 0 | S52: =IF(ISERROR(S53*S6),0,S53*S6) -> 0 | ... U52: =IF(ISERROR(U53*U6),0,U53*U6) -> 0
C53: 比营业成本（%） | F53: =IF(ISERROR(F52/F6),0,F52/F6) -> 0 | G53: =IF(ISERROR(G52/G6),0,G52/G6) -> 0 | H53: =IF(ISERROR(H52/H6),0,H52/H6) -> 0 | I53: =IF(ISERROR(I52/I6),0,I52/I6) -> 0 | J53: =IF(ISERROR(J52/J6),0,J52/J6) -> 0 | K53: =IF(ISERROR(K52/K6),0,K52/K6) -> 0
B55: 应交税费 | F55: =资产负债表!Y57 -> 0 | G55: =资产负债表!AC57 -> 0 | H55: =资产负债表!AG57 -> 0 | I55: =资产负债表!AH57 -> 0 | J55: =资产负债表!AI57 -> 0 | K55: =资产负债表!AJ57 -> 0 | L55: =IF(ISERROR(L56*L5),0,L56*L5) -> 0 | M55: =IF(ISERROR(M56*M5),0,M56*M5) -> 0 | N55: =IF(ISERROR(N56*N5),0,N56*N5) -> 0 | O55: =IF(ISERROR(O56*O5),0,O56*O5) -> 0 | P55: =IF(ISERROR(P56*P5),0,P56*P5) -> 0 | Q55: =IF(ISERROR(Q56*Q5),0,Q56*Q5) -> 0 | R55: =IF(ISERROR(R56*R5),0,R56*R5) -> 0 | S55: =IF(ISERROR(S56*S5),0,S56*S5) -> 0 | ... U55: =IF(ISERROR(U56*U5),0,U56*U5) -> 0
C56: 比营业收入（%） | F56: =IF(ISERROR(F55/F5),0,F55/F5) -> 0 | G56: =IF(ISERROR(G55/G5),0,G55/G5) -> 0 | H56: =IF(ISERROR(H55/H5),0,H55/H5) -> 0 | I56: =IF(ISERROR(I55/I5),0,I55/I5) -> 0 | J56: =IF(ISERROR(J55/J5),0,J55/J5) -> 0 | K56: =IF(ISERROR(K55/K5),0,K55/K5) -> 0
...

Sheet 投资与减值
B2: 投资支出
B3: ="单位：人民币"&目录!D5 -> 单位：人民币百万元
B4: 会计年度截止日：12/31 | F4: =资产预测!F4 -> 2021 | G4: =资产预测!G4 -> 2022 | H4: =资产预测!H4 -> 2023 | I4: =资产预测!I4 -> 1Q24 | J4: =资产预测!J4 -> 1H24 | K4: =资产预测!K4 -> 3Q24 | L4: =资产预测!L4 -> 2024E | M4: =资产预测!M4 -> 2025 | ... U4: =资产预测!U4 -> 2033
B6: 一、固定资产
B7: 假设： | C7: 预计使用寿命 | D7: 10
C8: 预计净残值 | D8: 0.05
B10: 原值： | C10: 期初 | F10: =财务附注数据!Z6*目录!$D$6 -> 0 | G10: =财务附注数据!AD6*目录!$D$6 -> 0 | H10: =财务附注数据!AH6*目录!$D$6 -> 0 | J10: =H13 -> 0 | L10: =H13 -> 0 | M10: =L13 -> 0 | N10: =M13 -> 0 | O10: =N13 -> 0 | P10: =O13 -> 0 | Q10: =P13 -> 0 | R10: =Q13 -> 0 | S10: =R13 -> 0 | T10: =S13 -> 0 | U10: =T13 -> 0
C11: 本期增加(外购） | F11: =F13-F10 -> 0 | G11: =G13-G10 -> 0 | H11: =H13-H10 -> 0 | J11: =IF(财务基础数据!AM4<=1,0,J13-J10) -> 0
C12: 本期在建工程转固 | L12: =L44 -> 0 | M12: =M44 -> 0 | N12: =N44 -> 0 | O12: =O44 -> 0 | P12: =P44 -> 0 | Q12: =Q44 -> 0 | R12: =R44 -> 0 | S12: =S44 -> 0 | ... U12: =U44 -> 0 | V12: 在建工程转固金额请在下方填写预测参数，不要修改此处公式！
C13: 期末 | F13: =财务附注数据!AD6*目录!$D$6 -> 0 | G13: =财务附注数据!AH6*目录!$D$6 -> 0 | H13: =财务附注数据!AL6*目录!$D$6 -> 0 | J13: =财务附注数据!AN6*目录!$D$6 -> 0 | L13: =L10+L11+L12 -> 0 | M13: =M10+M11+M12 -> 0 | N13: =N10+N11+N12 -> 0 | O13: =O10+O11+O12 -> 0 | P13: =P10+P11+P12 -> 0 | Q13: =Q10+Q11+Q12 -> 0 | R13: =R10+R11+R12 -> 0 | S13: =S10+S11+S12 -> 0 | ... U13: =U10+U11+U12 -> 0
B15: 本期计提折旧： | F15: =IF(财务基础数据!AD282=0,财务基础数据!AD281*目录!$D$6-F99-F142-F151-F110,财务基础数据!AD281*目录!$D$6-F99-F142-F151) -> 0 | G15: =IF(财务基础数据!AH282=0,财务基础数据!AH281*目录!$D$6-G99-G142-G151-G110,财务基础数据!AH281*目录!$D$6-G99-G142-G151) -> 0 | H15: =IF(财务基础数据!AL282=0,财务基础数据!AL281*目录!$D$6-H99-H142-H151-H110,财务基础数据!AL281*目录!$D$6-H99-H142-H151) -> 0 | J15: =IF(财务基础数据!AN282=0,财务基础数据!AN281*目录!$D$6-J99-J142-J151-J110,财务基础数据!AN281*目录!$D$6-J99-J142-J151) -> 0 | L15: =L39 -> 0 | M15: =M39 -> 0 | N15: =N39 -> 0 | O15: =O39 -> 0 | P15: =P39 -> 0 | Q15: =Q39 -> 0 | R15: =R39 -> 0 | S15: =S39 -> 0 | ... U15: =U39 -> 0
C16: 折旧率% | D16: 0 | F16: =IF(ISERROR(F15/F10),0,F15/F10) -> 0 | G16: =IF(ISERROR(G15/G10),0,G15/G10) -> 0 | H16: =IF(ISERROR(H15/H10),0,H15/H10) -> 0 | J16: =IF(ISERROR(J15/J10*2),0,J15/J10*2) -> 0 | L16: =$D$16 -> 0 | M16: =$D$16 -> 0 | N16: =$D$16 -> 0 | O16: =$D$16 -> 0 | P16: =$D$16 -> 0 | Q16: =$D$16 -> 0 | R16: =$D$16 -> 0 | S16: =$D$16 -> 0 | ... U16: =$D$16 -> 0
B18: 减值： | C18: 期初 | F18: =财务附注数据!Z8*目录!$D$6 -> 0 | G18: =财务附注数据!AD8*目录!$D$6 -> 0 | H18: =财务附注数据!AH8*目录!$D$6 -> 0 | J18: =H20 -> 0 | L18: =H20 -> 0 | M18: =L20 -> 0 | N18: =M20 -> 0 | O18: =N20 -> 0 | P18: =O20 -> 0 | Q18: =P20 -> 0 | R18: =Q20 -> 0 | S18: =R20 -> 0 | T18: =S20 -> 0 | U18: =T20 -> 0
C19: 本期增加 | F19: =F20-F18 -> 0 | G19: =G20-G18 -> 0 | H19: =H20-H18 -> 0 | J19: =IF(财务基础数据!AM4<=1,0,J20-J18) -> 0
C20: 期末 | F20: =财务附注数据!AD8*目录!$D$6 -> 0 | G20: =财务附注数据!AH8*目录!$D$6 -> 0 | H20: =财务附注数据!AL8*目录!$D$6 -> 0 | J20: =财务附注数据!AN8*目录!$D$6 -> 0 | L20: =L18+L19 -> 0 | M20: =M18+M19 -> 0 | N20: =N18+N19 -> 0 | O20: =O18+O19 -> 0 | P20: =P18+P19 -> 0 | Q20: =Q18+Q19 -> 0 | R20: =R18+R19 -> 0 | S20: =S18+S19 -> 0 | ... U20: =U18+U19 -> 0
C22: 其他增减
B23: 期初固定资产净额 | F23: =资产负债表!U31 -> 0 | G23: =资产负债表!Y31 -> 0 | H23: =资产负债表!AC31 -> 0 | L23: =H24 -> 0 | M23: =L24 -> 0 | N23: =M24 -> 0 | O23: =N24 -> 0 | P23: =O24 -> 0 | Q23: =P24 -> 0 | R23: =Q24 -> 0 | S23: =R24 -> 0 | T23: =S24 -> 0 | U23: =T24 -> 0
B24: 期末固定资产净额 | F24: =资产负债表!Y31 -> 0 | G24: =资产负债表!AC31 -> 0 | H24: =资产负债表!AG31 -> 0 | I24: =资产负债表!AH31 -> 0 | J24: =资产负债表!AI31 -> 0 | K24: =资产负债表!AJ31 -> 0 | L24: =H24+L11+L12-L15-L19+L22 -> 0 | M24: =L24+M11+M12-M15-M19+M22 -> 0 | N24: =M24+N11+N12-N15-N19+N22 -> 0 | O24: =N24+O11+O12-O15-O19+O22 -> 0 | P24: =O24+P11+P12-P15-P19+P22 -> 0 | Q24: =P24+Q11+Q12-Q15-Q19+Q22 -> 0 | R24: =Q24+R11+R12-R15-R19+R22 -> 0 | S24: =R24+S11+S12-S15-S19+S22 -> 0 | T24: =S24+T11+T12-T15-T19+T22 -> 0 | U24: =T24+U11+U12-U15-U19+U22 -> 0
F26: 原有资产 | G26: 期末净额 | H26: 期末原值 | L26: =L4 -> 2024E | M26: =M4 -> 2025 | N26: =N4 -> 2026 | O26: =O4 -> 2027 | P26: =P4 -> 2028 | Q26: =Q4 -> 2029 | R26: =R4 -> 2030 | S26: =S4 -> 2031 | ... U26: =U4 -> 2033
G27: =H24 -> 0 | H27: =H13 -> 0 | L27: =IF(SUM($K$27:K27)=$G$27,0,IF($G$27-SUM($K$27:K27)<$H$27*L16,$G$27-SUM($K$27:K27),$H$27*L16)) -> 0 | M27: =IF(SUM($K$27:L27)=$G$27,0,IF($G$27-SUM($K$27:L27)<$H$27*M16,$G$27-SUM($K$27:L27),$H$27*M16)) -> 0 | N27: =IF(SUM($K$27:M27)=$G$27,0,IF($G$27-SUM($K$27:M27)<$H$27*N16,$G$27-SUM($K$27:M27),$H$27*N16)) -> 0 | O27: =IF(SUM($K$27:N27)=$G$27,0,IF($G$27-SUM($K$27:N27)<$H$27*O16,$G$27-SUM($K$27:N27),$H$27*O16)) -> 0 | P27: =IF(SUM($K$27:O27)=$G$27,0,IF($G$27-SUM($K$27:O27)<$H$27*P16,$G$27-SUM($K$27:O27),$H$27*P16)) -> 0 | Q27: =IF(SUM($K$27:P27)=$G$27,0,IF($G$27-SUM($K$27:P27)<$H$27*Q16,$G$27-SUM($K$27:P27),$H$27*Q16)) -> 0 | R27: =IF(SUM($K$27:Q27)=$G$27,0,IF($G$27-SUM($K$27:Q27)<$H$27*R16,$G$27-SUM($K$27:Q27),$H$27*R16)) -> 0 | S27: =IF(SUM($K$27:R27)=$G$27,0,IF($G$27-SUM($K$27:R27)<$H$27*S16,$G$27-SUM($K$27:R27),$H$27*S16)) -> 0 | ... U27: =IF(SUM($K$27:T27)=$G$27,0,IF($G$27-SUM($K$27:T27)<$H$27*U16,$G$27-SUM($K$27:T27),$H$27*U16)) -> 0
G28: 新增资产 | H28: 使用年限
F29: {=TRANSPOSE(L4:U4)} -> 2024E | G29: =L11+L12 -> 0 | H29: =$D$7 -> 10 | L29: =IF($H29>=1,$G29*(1-$D$8)/$H29,"") -> 0 | M29: =IF($H29>=2,$G29*(1-$D$8)/$H29,"") -> 0 | N29: =IF($H29>=3,$G29*(1-$D$8)/$H29,"") -> 0 | O29: =IF($H29>=4,$G29*(1-$D$8)/$H29,"") -> 0 | P29: =IF($H29>=5,$G29*(1-$D$8)/$H29,"") -> 0 | Q29: =IF($H29>=6,$G29*(1-$D$8)/$H29,"") -> 0 | R29: =IF($H29>=7,$G29*(1-$D$8)/$H29,"") -> 0 | S29: =IF($H29>=8,$G29*(1-$D$8)/$H29,"") -> 0 | T29: =IF($H29>=9,$G29*(1-$D$8)/$H29,"") -> 0 | U29: =IF($H29>=10,$G29*(1-$D$8)/$H29,"") -> 0
F30: 2025 | G30: =M11+M12 -> 0 | H30: =$D$7 -> 10 | M30: =IF($H30>=1,$G30*(1-$D$8)/$H30,"") -> 0 | N30: =IF($H30>=2,$G30*(1-$D$8)/$H30,"") -> 0 | O30: =IF($H30>=3,$G30*(1-$D$8)/$H30,"") -> 0 | P30: =IF($H30>=4,$G30*(1-$D$8)/$H30,"") -> 0 | Q30: =IF($H30>=5,$G30*(1-$D$8)/$H30,"") -> 0 | R30: =IF($H30>=6,$G30*(1-$D$8)/$H30,"") -> 0 | S30: =IF($H30>=7,$G30*(1-$D$8)/$H30,"") -> 0 | T30: =IF($H30>=8,$G30*(1-$D$8)/$H30,"") -> 0 | U30: =IF($H30>=9,$G30*(1-$D$8)/$H30,"") -> 0
