Workbook
Name 财务年度: IF('[1]图表输出-各种增长率对比图表'!$G$3=1,'[1]图表输出-各种增长率对比图表'!$B$2:$F$2,'[1]图表输出-各种增长率对比图表'!$D$2:$F$2)
Name 指标2: IF('[1]图表输出-各种增长率对比图表'!$G$3=1,'[1]图表输出-各种增长率对比图表'!$M$7:$Q$7,'[1]图表输出-各种增长率对比图表'!$O$7:$Q$7)
Name 指标3: IF('[1]图表输出-各种增长率对比图表'!$G$3=1,'[1]图表输出-各种增长率对比图表'!$M$8:$Q$8,'[1]图表输出-各种增长率对比图表'!$O$8:$Q$8)
Name 指标4: IF('[1]图表输出-各种增长率对比图表'!$G$3=1,'[1]图表输出-各种增长率对比图表'!$M$44:$Q$44,'[1]图表输出-各种增长率对比图表'!$O$44:$Q$44)
Name 指标5: IF('[1]图表输出-各种增长率对比图表'!$G$3=1,'[1]图表输出-各种增长率对比图表'!$M$45:$Q$45,'[1]图表输出-各种增长率对比图表'!$O$45:$Q$45)
Name 指标6: IF('[1]图表输出-各种增长率对比图表'!$G$3=1,'[1]图表输出-各种增长率对比图表'!$M$46:$Q$46,'[1]图表输出-各种增长率对比图表'!$O$46:$Q$46)
Name 指标7: IF('[1]图表输出-各种增长率对比图表'!$G$3=1,'[1]图表输出-各种增长率对比图表'!$M$82:$Q$82,'[1]图表输出-各种增长率对比图表'!$O$82:$Q$82)
Name 指标8: IF('[1]图表输出-各种增长率对比图表'!$G$3=1,'[1]图表输出-各种增长率对比图表'!$M$83:$Q$83,'[1]图表输出-各种增长率对比图表'!$O$83:$Q$83)
Name 指标9: IF('[1]图表输出-各种增长率对比图表'!$G$3=1,'[1]图表输出-各种增长率对比图表'!$M$84:$Q$84,'[1]图表输出-各种增长率对比图表'!$O$84:$Q$84)

Sheet 目录
D2: 百万股 | E2: 股票名称 | F2: XXXX
D3: 3 | E3: 最新报告期 | F3: XXXX-XX-XX
D4: 3 | E4: 最新年报报告期 | F4: XXXX-XX-XX
D5: 百万元 | E5: 估值日期 | F5: XXXX-XX-XX
B6: 版权所有： 上海携宁计算机科技股份有限公司 | D6: 1e-06 | E6: 最新收盘价(港元） | F6: XXXX
B7: 联系电话： 18101638931(工作日)，18117554345(值班) | D7: =LEFT(D5,LEN(D5)-1) -> 百万 | E7: 最新总股本（百万） | F7: XXXX
B8: E-mail ： modelsupport@sinitek.com | E8: 货币单位 | F8: XXXX
B9: WebSite： www.sinitek.com | E9: 最新行情日 | F9: XXXX-XX-XX | G9: 收盘价默认货币单位为港币，若与模型货币单位不一致，请在F10填写汇率。
B10: 下载地址： https://cloudmodel.sinitek.com | E10: 汇率 | G10: 如：模型货币单位为CNY，1HKD=0.92CNY,则在此填写0.92
B12: 使用步骤： | E12: 重要提示：
B13: 1.使用本模型前请确保已下载并安装估值模型插件(携宁科技云估值)； | E13: 1.修改股票代码或重新选择历史数据年数后，需重新点击“提取历史数据”按钮来更新数据；
B14: 2.点击“提取历史数据”，在股票代码框中输入代码或名称，支持模糊搜索； | E14: 2.不能修改单元格内的公式，否则可能导致报表不平；
B15: 选择历史数据年数、货币单位等选项，可以设置更新范围； | E15: 3.不能增加/删除已有sheet及已有Sheet中的行或列；
B16: 3.点击“预测数据设置”按钮可实现两张预测sheet的参数设置； | E16: 4.不能删除模型中原有Sheet；
B17: 4.点击“添加输出表”可进行输出表更新； | E17: 5.如有需要，可以自由增加Sheet，但不能修改已有sheet名；
B18: 5.点击“导入历史模型”可实现历史预测数据迁移，支持v2/v3版本导入。 | E18: 6.若资产负债表不平，请打开空模型并通过"导入历史模型"功能将未配平模型导入。
B20: 销售预测 | C20: 用户填写相关假设，自动生成数据 | E20: 黄色底纹需手工填写数据 | F20: 金色边框可自由修改参数
B21: 资产预测 | C21: 用户填写相关假设，自动生成数据 | E21: 黄色底纹需手工填写数据 | F21: 金色边框可自由修改参数 | G21: 蓝色底纹可以手工填写数据
B22: 主要财务摘要 | C22: 自动生成的财务指标计算结果 | G22: 蓝色底纹可以手工填写数据
B23: 报表摘要 | C23: 自动生成的财务指标计算结果
B24: 资产负债表 | C24: 用户填写相关假设，自动生成数据 | E24: 黄色底纹需手工填写数据
B25: 利润表 | C25: 用户填写相关假设，自动生成数据 | E25: 黄色底纹需手工填写数据
B26: 现金流量表 | C26: 用户填写相关假设，自动生成数据 | E26: 黄色底纹需手工填写数据
B27: 估值 | C27: 用户填写相关假设，自动生成数据 | E27: 黄色底纹需手工填写数据 | F27: 金色边框可自由修改参数
B28: 财务基础数据 | C28: 自动生成的财务基础数据

Sheet 销售预测
A1: 收入成本预测
A2: =主要财务摘要!H2 -> 单位：港币(百万) | G2: 注意：预测前三年可按照季度数据进行预测（如当前三季报已出，可直接在蓝色单元格填写第四季度数据），也可直接在黄色单元格填写年度预测数据 | AJ2: 此页季度数据为单季度数据，增长率为环比口径；请注意：若利润表季度数据缺失可能导致单季度数据显示为负数！
A3: 项 目 | G3: =利润表!O4 -> 2019 | H3: =利润表!S4 -> 2020 | I3: =利润表!W4 -> 2021 | J3: =利润表!AA4 -> 2022E | K3: =利润表!AB4 -> 2023 | L3: =利润表!AC4 -> 2024 | M3: =利润表!AD4 -> 2025 | N3: =利润表!AE4 -> 2026 | O3: =利润表!AF4 -> 2027 | P3: =利润表!AG4 -> 2028 | Q3: =利润表!AH4 -> 2029 | ... S3: =利润表!AJ4 -> 2031 | U3: ="1Q"&RIGHT(利润表!L4,2) -> 1Q19 | V3: ="2Q"&RIGHT(利润表!M4,2) -> 2Q19 | W3: ="3Q"&RIGHT(利润表!N4,2) -> 3Q19 | X3: ="4Q"&RIGHT(利润表!O4,2) -> 4Q19 | Y3: ="1Q"&RIGHT(利润表!P4,2) -> 1Q20 | Z3: ="2Q"&RIGHT(利润表!Q4,2) -> 2Q20 | AA3: ="3Q"&RIGHT(利润表!R4,2) -> 3Q20 | AB3: ="4Q"&RIGHT(利润表!S4,2) -> 4Q20 | AC3: ="1Q"&RIGHT(利润表!T4,2) -> 1Q21 | AD3: ="2Q"&RIGHT(利润表!U4,2) -> 2Q21 | AE3: ="3Q"&RIGHT(利润表!V4,2) -> 3Q21 | AF3: ="4Q"&RIGHT(利润表!W4,2) -> 4Q21 | AG3: ="1Q"&RIGHT(利润表!X4,2) -> 1Q22 | AH3: ="2Q"&RIGHT(利润表!Y4,2) -> 2Q22 | AI3: ="3Q"&RIGHT(利润表!Z4,2) -> 3Q22 | AJ3: ="1Q"&LEFT(利润表!$AA$4,4) -> 1Q2022 | AK3: ="2Q"&LEFT(利润表!$AA$4,4) -> 2Q2022 | AL3: ="3Q"&LEFT(利润表!$AA$4,4) -> 3Q2022 | AM3: ="4Q"&LEFT(利润表!$AA$4,4) -> 4Q2022 | AN3: ="1Q"&LEFT(利润表!$AB$4,4) -> 1Q2023 | AO3: ="2Q"&LEFT(利润表!$AB$4,4) -> 2Q2023 | AP3: ="3Q"&LEFT(利润表!$AB$4,4) -> 3Q2023 | AQ3: ="4Q"&LEFT(利润表!$AB$4,4) -> 4Q2023 | AR3: ="1Q"&LEFT(利润表!$AC$4,4) -> 1Q2024 | AS3: ="2Q"&LEFT(利润表!$AC$4,4) -> 2Q2024 | AT3: ="3Q"&LEFT(利润表!$AC$4,4) -> 3Q2024 | AU3: ="4Q"&LEFT(利润表!$AC$4,4) -> 4Q2024
A4: 营业收入小计 | G4: =利润表!O6 -> 0 | H4: =利润表!S6 -> 0 | I4: =利润表!W6 -> 0 | J4: =IF(COUNT(AJ4:AM4)=4,SUM(AJ4:AM4),0) -> 0 | K4: =IF(COUNT(AN4:AQ4)=4,SUM(AN4:AQ4),0) -> 0 | L4: =IF(COUNT(AR4:AU4)=4,SUM(AR4:AU4),0) -> 0 | U4: =利润表!L6 -> 0 | V4: =利润表!M6-利润表!L6 -> 0 | W4: =利润表!N6-利润表!M6 -> 0 | X4: =利润表!O6-利润表!N6 -> 0 | Y4: =利润表!P6 -> 0 | Z4: =利润表!Q6-利润表!P6 -> 0 | AA4: =利润表!R6-利润表!Q6 -> 0 | AB4: =利润表!S6-利润表!R6 -> 0 | AC4: =利润表!T6 -> 0 | AD4: =利润表!U6-利润表!T6 -> 0 | AE4: =利润表!V6-利润表!U6 -> 0 | AF4: =利润表!W6-利润表!V6 -> 0 | AG4: =IF(财务基础数据!$W$2=0,0,利润表!X6) -> 0 | AH4: =IF(财务基础数据!$W$2<=1,0,利润表!Y6-利润表!X6) -> 0 | AI4: =IF(财务基础数据!$W$2<=2,0,利润表!Z6-利润表!Y6) -> 0 | AJ4: =IF(财务基础数据!$W$2=0," ",AG4) | AK4: =IF(财务基础数据!$W$2<=1," ",AH4) | AL4: =IF(财务基础数据!$W$2<=2," ",AI4)
A5: 增长率% | G5: =IF(ISERROR((G4-利润表!K6)/ABS(利润表!K6)),"—",(G4-利润表!K6)/ABS(利润表!K6)) -> — | H5: =IF(ISERROR((H4-G4)/ABS(G4)),"—",(H4-G4)/ABS(G4)) -> — | I5: =IF(ISERROR((I4-H4)/ABS(H4)),"—",(I4-H4)/ABS(H4)) -> — | J5: =IF(ISERROR((J4-I4)/ABS(I4)),"—",(J4-I4)/ABS(I4)) -> — | K5: =IF(ISERROR((K4-J4)/ABS(J4)),"—",(K4-J4)/ABS(J4)) -> — | L5: =IF(ISERROR((L4-K4)/ABS(K4)),"—",(L4-K4)/ABS(K4)) -> — | M5: =IF(ISERROR((M4-L4)/ABS(L4)),"—",(M4-L4)/ABS(L4)) -> — | N5: =IF(ISERROR((N4-M4)/ABS(M4)),"—",(N4-M4)/ABS(M4)) -> — | O5: =IF(ISERROR((O4-N4)/ABS(N4)),"—",(O4-N4)/ABS(N4)) -> — | ... S5: =IF(ISERROR((S4-R4)/ABS(R4)),"—",(S4-R4)/ABS(R4)) -> — | V5: =IF(ISERROR((V4-U4)/ABS(U4)),"—",(V4-U4)/ABS(U4)) -> — | W5: =IF(ISERROR((W4-V4)/ABS(V4)),"—",(W4-V4)/ABS(V4)) -> — | X5: =IF(ISERROR((X4-W4)/ABS(W4)),"—",(X4-W4)/ABS(W4)) -> — | Y5: =IF(ISERROR((Y4-X4)/ABS(X4)),"—",(Y4-X4)/ABS(X4)) -> — | Z5: =IF(ISERROR((Z4-Y4)/ABS(Y4)),"—",(Z4-Y4)/ABS(Y4)) -> — | AA5: =IF(ISERROR((AA4-Z4)/ABS(Z4)),"—",(AA4-Z4)/ABS(Z4)) -> — | AB5: =IF(ISERROR((AB4-AA4)/ABS(AA4)),"—",(AB4-AA4)/ABS(AA4)) -> — | AC5: =IF(ISERROR((AC4-AB4)/ABS(AB4)),"—",(AC4-AB4)/ABS(AB4)) -> — | ... AI5: =IF(ISERROR((AI4-AH4)/ABS(AH4)),"—",(AI4-AH4)/ABS(AH4)) -> — | AJ5: =IF(ISERROR((AJ4-AF4)/ABS(AF4)),"—",(AJ4-AF4)/ABS(AF4)) -> — | AK5: =IF(ISERROR((AK4-AJ4)/ABS(AJ4)),"—",(AK4-AJ4)/ABS(AJ4)) -> — | AL5: =IF(ISERROR((AL4-AK4)/ABS(AK4)),"—",(AL4-AK4)/ABS(AK4)) -> — | AM5: =IF(ISERROR((AM4-AL4)/ABS(AL4)),"—",(AM4-AL4)/ABS(AL4)) -> — | AN5: =IF(ISERROR((AN4-AM4)/ABS(AM4)),"—",(AN4-AM4)/ABS(AM4)) -> — | AO5: =IF(ISERROR((AO4-AN4)/ABS(AN4)),"—",(AO4-AN4)/ABS(AN4)) -> — | AP5: =IF(ISERROR((AP4-AO4)/ABS(AO4)),"—",(AP4-AO4)/ABS(AO4)) -> — | AQ5: =IF(ISERROR((AQ4-AP4)/ABS(AP4)),"—",(AQ4-AP4)/ABS(AP4)) -> — | AR5: =IF(ISERROR((AR4-AQ4)/ABS(AQ4)),"—",(AR4-AQ4)/ABS(AQ4)) -> — | ... AU5: =IF(ISERROR((AU4-AT4)/ABS(AT4)),"—",(AU4-AT4)/ABS(AT4)) -> —
A6: 其他收入小计 | G6: =利润表!O7 -> 0 | H6: =利润表!S7 -> 0 | I6: =利润表!W7 -> 0 | J6: =IF(COUNT(AJ6:AM6)=4,SUM(AJ6:AM6),0) -> 0 | K6: =IF(COUNT(AN6:AQ6)=4,SUM(AN6:AQ6),0) -> 0 | L6: =IF(COUNT(AR6:AU6)=4,SUM(AR6:AU6),0) -> 0 | U6: =利润表!L7 -> 0 | V6: =利润表!M7-利润表!L7 -> 0 | W6: =利润表!N7-利润表!M7 -> 0 | X6: =利润表!O7-利润表!N7 -> 0 | Y6: =利润表!P7 -> 0 | Z6: =利润表!Q7-利润表!P7 -> 0 | AA6: =利润表!R7-利润表!Q7 -> 0 | AB6: =利润表!S7-利润表!R7 -> 0 | AC6: =利润表!T7 -> 0 | AD6: =利润表!U7-利润表!T7 -> 0 | AE6: =利润表!V7-利润表!U7 -> 0 | AF6: =利润表!W7-利润表!V7 -> 0 | AG6: =IF(财务基础数据!$W$2=0,0,利润表!X7) -> 0 | AH6: =IF(财务基础数据!$W$2<=1,0,利润表!Y7-利润表!X7) -> 0 | AI6: =IF(财务基础数据!$W$2<=2,0,利润表!Z7-利润表!Y7) -> 0 | AJ6: =IF(财务基础数据!$W$2=0,"",AG6) | AK6: =IF(财务基础数据!$W$2<=1,"",AH6) | AL6: =IF(财务基础数据!$W$2<=2,"",AI6)
A7: 营业成本小计 | G7: =利润表!O9 -> 0 | H7: =利润表!S9 -> 0 | I7: =利润表!W9 -> 0 | J7: =IF(COUNT(AJ7:AM7)=4,SUM(AJ7:AM7),0) -> 0 | K7: =IF(COUNT(AN7:AQ7)=4,SUM(AN7:AQ7),0) -> 0 | L7: =IF(COUNT(AR7:AU7)=4,SUM(AR7:AU7),0) -> 0 | U7: =利润表!L9 -> 0 | V7: =利润表!M9-利润表!L9 -> 0 | W7: =利润表!N9-利润表!M9 -> 0 | X7: =利润表!O9-利润表!N9 -> 0 | Y7: =利润表!P9 -> 0 | Z7: =利润表!Q9-利润表!P9 -> 0 | AA7: =利润表!R9-利润表!Q9 -> 0 | AB7: =利润表!S9-利润表!R9 -> 0 | AC7: =利润表!T9 -> 0 | AD7: =利润表!U9-利润表!T9 -> 0 | AE7: =利润表!V9-利润表!U9 -> 0 | AF7: =利润表!W9-利润表!V9 -> 0 | AG7: =IF(财务基础数据!$W$2=0,0,利润表!X9) -> 0 | AH7: =IF(财务基础数据!$W$2<=1,0,利润表!Y9-利润表!X9) -> 0 | AI7: =IF(财务基础数据!$W$2<=2,0,利润表!Z9-利润表!Y9) -> 0 | AJ7: =IF(财务基础数据!$W$2=0,"",AG7) | AK7: =IF(财务基础数据!$W$2<=2,"",AH7) | AL7: =IF(财务基础数据!$W$2<=2,"",AI7)
A8: 增长率% | G8: =IF(ISERROR((G7-利润表!K9)/ABS(利润表!K9)),"—",(G7-利润表!K9)/ABS(利润表!K9)) -> — | H8: =IF(ISERROR((H7-G7)/ABS(G7)),"—",(H7-G7)/ABS(G7)) -> — | I8: =IF(ISERROR((I7-H7)/ABS(H7)),"—",(I7-H7)/ABS(H7)) -> — | J8: =IF(ISERROR((J7-I7)/ABS(I7)),"—",(J7-I7)/ABS(I7)) -> — | K8: =IF(ISERROR((K7-J7)/ABS(J7)),"—",(K7-J7)/ABS(J7)) -> — | L8: =IF(ISERROR((L7-K7)/ABS(K7)),"—",(L7-K7)/ABS(K7)) -> — | M8: =IF(ISERROR((M7-L7)/ABS(L7)),"—",(M7-L7)/ABS(L7)) -> — | N8: =IF(ISERROR((N7-M7)/ABS(M7)),"—",(N7-M7)/ABS(M7)) -> — | O8: =IF(ISERROR((O7-N7)/ABS(N7)),"—",(O7-N7)/ABS(N7)) -> — | ... S8: =IF(ISERROR((S7-R7)/ABS(R7)),"—",(S7-R7)/ABS(R7)) -> — | V8: =IF(ISERROR((V7-U7)/ABS(U7)),"—",(V7-U7)/ABS(U7)) -> — | W8: =IF(ISERROR((W7-V7)/ABS(V7)),"—",(W7-V7)/ABS(V7)) -> — | X8: =IF(ISERROR((X7-W7)/ABS(W7)),"—",(X7-W7)/ABS(W7)) -> — | Y8: =IF(ISERROR((Y7-X7)/ABS(X7)),"—",(Y7-X7)/ABS(X7)) -> — | Z8: =IF(ISERROR((Z7-Y7)/ABS(Y7)),"—",(Z7-Y7)/ABS(Y7)) -> — | AA8: =IF(ISERROR((AA7-Z7)/ABS(Z7)),"—",(AA7-Z7)/ABS(Z7)) -> — | AB8: =IF(ISERROR((AB7-AA7)/ABS(AA7)),"—",(AB7-AA7)/ABS(AA7)) -> — | AC8: =IF(ISERROR((AC7-AB7)/ABS(AB7)),"—",(AC7-AB7)/ABS(AB7)) -> — | ... AI8: =IF(ISERROR((AI7-AH7)/ABS(AH7)),"—",(AI7-AH7)/ABS(AH7)) -> — | AJ8: =IF(ISERROR((AJ7-AF7)/ABS(AF7)),"—",(AJ7-AF7)/ABS(AF7)) -> — | AK8: =IF(ISERROR((AK7-AJ7)/ABS(AJ7)),"—",(AK7-AJ7)/ABS(AJ7)) -> — | AL8: =IF(ISERROR((AL7-AK7)/ABS(AK7)),"—",(AL7-AK7)/ABS(AK7)) -> — | AM8: =IF(ISERROR((AM7-AL7)/ABS(AL7)),"—",(AM7-AL7)/ABS(AL7)) -> — | AN8: =IF(ISERROR((AN7-AM7)/ABS(AM7)),"—",(AN7-AM7)/ABS(AM7)) -> — | AO8: =IF(ISERROR((AO7-AN7)/ABS(AN7)),"—",(AO7-AN7)/ABS(AN7)) -> — | AP8: =IF(ISERROR((AP7-AO7)/ABS(AO7)),"—",(AP7-AO7)/ABS(AO7)) -> — | AQ8: =IF(ISERROR((AQ7-AP7)/ABS(AP7)),"—",(AQ7-AP7)/ABS(AP7)) -> — | AR8: =IF(ISERROR((AR7-AQ7)/ABS(AQ7)),"—",(AR7-AQ7)/ABS(AQ7)) -> — | ... AU8: =IF(ISERROR((AU7-AT7)/ABS(AT7)),"—",(AU7-AT7)/ABS(AT7)) -> —
A9: 毛利 | G9: =利润表!O16 -> 0 | H9: =利润表!S16 -> 0 | I9: =利润表!W16 -> 0 | J9: =J4-J7 -> 0 | K9: =K4-K7 -> 0 | L9: =L4-L7 -> 0 | M9: =M4-M7 -> 0 | N9: =N4-N7 -> 0 | O9: =O4-O7 -> 0 | P9: =P4-P7 -> 0 | Q9: =Q4-Q7 -> 0 | ... S9: =S4-S7 -> 0 | U9: =利润表!L16 -> 0 | V9: =利润表!M16-利润表!L16 -> 0 | W9: =利润表!N16-利润表!M16 -> 0 | X9: =利润表!O16-利润表!N16 -> 0 | Y9: =利润表!P16 -> 0 | Z9: =利润表!Q16-利润表!P16 -> 0 | AA9: =利润表!R16-利润表!Q16 -> 0 | AB9: =利润表!S16-利润表!R16 -> 0 | AC9: =利润表!T16 -> 0 | AD9: =利润表!U16-利润表!T16 -> 0 | AE9: =利润表!V16-利润表!U16 -> 0 | AF9: =利润表!W16-利润表!V16 -> 0 | AG9: =IF(财务基础数据!$W$2=0,0,利润表!X16) -> 0 | AH9: =IF(财务基础数据!$W$2<=1,0,利润表!Y16-利润表!X16) -> 0 | AI9: =IF(财务基础数据!$W$2<=2,0,利润表!Z16-利润表!Y16) -> 0 | AJ9: =IF(ISERROR(AJ4-AJ7),"—",AJ4-AJ7) -> — | AK9: =IF(ISERROR(AK4-AK7),"—",AK4-AK7) -> — | AL9: =IF(ISERROR(AL4-AL7),"—",AL4-AL7) -> — | AM9: =IF(ISERROR(AM4-AM7),"—",AM4-AM7) -> 0 | AN9: =IF(ISERROR(AN4-AN7),"—",AN4-AN7) -> 0 | AO9: =IF(ISERROR(AO4-AO7),"—",AO4-AO7) -> 0 | AP9: =IF(ISERROR(AP4-AP7),"—",AP4-AP7) -> 0 | AQ9: =IF(ISERROR(AQ4-AQ7),"—",AQ4-AQ7) -> 0 | ... AU9: =IF(ISERROR(AU4-AU7),"—",AU4-AU7) -> 0
A10: 毛利率 | G10: =IF(ISERROR(G9/G4),"—",G9/G4) -> — | H10: =IF(ISERROR(H9/H4),"—",H9/H4) -> — | I10: =IF(ISERROR(I9/I4),"—",I9/I4) -> — | J10: =IF(ISERROR(J9/J4),"—",J9/J4) -> — | K10: =IF(ISERROR(K9/K4),"—",K9/K4) -> — | L10: =IF(ISERROR(L9/L4),"—",L9/L4) -> — | M10: =IF(ISERROR(M9/M4),"—",M9/M4) -> — | N10: =IF(ISERROR(N9/N4),"—",N9/N4) -> — | ... S10: =IF(ISERROR(S9/S4),"—",S9/S4) -> — | U10: =IF(ISERROR(U9/U4),"—",U9/U4) -> — | V10: =IF(ISERROR(V9/V4),"—",V9/V4) -> — | W10: =IF(ISERROR(W9/W4),"—",W9/W4) -> — | X10: =IF(ISERROR(X9/X4),"—",X9/X4) -> — | Y10: =IF(ISERROR(Y9/Y4),"—",Y9/Y4) -> — | Z10: =IF(ISERROR(Z9/Z4),"—",Z9/Z4) -> — | AA10: =IF(ISERROR(AA9/AA4),"—",AA9/AA4) -> — | AB10: =IF(ISERROR(AB9/AB4),"—",AB9/AB4) -> — | ... AU10: =IF(ISERROR(AU9/AU4),"—",AU9/AU4) -> —
A12: 经营收益的其他假设 | G12: 说明：季度数据预测和年度数据预测不可同时生效，只可选择其中一种预测方式
A13: 项 目 | G13: =G3 -> 2019 | H13: =H3 -> 2020 | I13: =I3 -> 2021 | J13: =J3 -> 2022E | K13: =K3 -> 2023 | L13: =L3 -> 2024 | M13: =M3 -> 2025 | N13: =N3 -> 2026 | ... S13: =S3 -> 2031 | U13: =U3 -> 1Q19 | V13: =V3 -> 2Q19 | W13: =W3 -> 3Q19 | X13: =X3 -> 4Q19 | Y13: =Y3 -> 1Q20 | Z13: =Z3 -> 2Q20 | AA13: =AA3 -> 3Q20 | AB13: =AB3 -> 4Q20 | ... AU13: =AU3 -> 4Q2024
A15: 营销费用 | G15: =利润表!O12 -> 0 | H15: =利润表!S12 -> 0 | I15: =利润表!W12 -> 0 | J15: =IF(COUNT(AJ16:AM16)=4,SUM(AJ15:AM15),J4*J16) -> 0 | K15: =IF(COUNT(AN16:AQ16)=4,SUM(AN15:AQ15),K4*K16) -> 0 | L15: =IF(COUNT(AR16:AU16)=4,SUM(AR15:AU15),L4*L16) -> 0 | M15: =IF(ISERROR(M4*M16),"—",M4*M16) -> 0 | N15: =IF(ISERROR(N4*N16),"—",N4*N16) -> 0 | O15: =IF(ISERROR(O4*O16),"—",O4*O16) -> 0 | P15: =IF(ISERROR(P4*P16),"—",P4*P16) -> 0 | Q15: =IF(ISERROR(Q4*Q16),"—",Q4*Q16) -> 0 | R15: =IF(ISERROR(R4*R16),"—",R4*R16) -> 0 | S15: =IF(ISERROR(S4*S16),"—",S4*S16) -> 0 | U15: =利润表!L12 -> 0 | V15: =利润表!M12-利润表!L12 -> 0 | W15: =利润表!N12-利润表!M12 -> 0 | X15: =利润表!O12-利润表!N12 -> 0 | Y15: =利润表!P12 -> 0 | Z15: =利润表!Q12-利润表!P12 -> 0 | AA15: =利润表!R12-利润表!Q12 -> 0 | AB15: =利润表!S12-利润表!R12 -> 0 | AC15: =利润表!T12 -> 0 | AD15: =利润表!U12-利润表!T12 -> 0 | AE15: =利润表!V12-利润表!U12 -> 0 | AF15: =利润表!W12-利润表!V12 -> 0 | AG15: =IF(财务基础数据!$W$2=0,0,利润表!X12) -> 0 | AH15: =IF(财务基础数据!$W$2<=1,0,利润表!Y12-利润表!X12) -> 0 | AI15: =IF(财务基础数据!$W$2<=2,0,利润表!Z12-利润表!Y12) -> 0 | AJ15: =IF(ISERROR(AJ16*AJ4),"—",AJ16*AJ4) -> — | AK15: =IF(ISERROR(AK16*AK4),"—",AK16*AK4) -> — | AL15: =IF(ISERROR(AL16*AL4),"—",AL16*AL4) -> — | AM15: =IF(ISERROR(AM16*AM4),"—",AM16*AM4) -> 0 | AN15: =IF(ISERROR(AN16*AN4),"—",AN16*AN4) -> 0 | AO15: =IF(ISERROR(AO16*AO4),"—",AO16*AO4) -> 0 | AP15: =IF(ISERROR(AP16*AP4),"—",AP16*AP4) -> 0 | AQ15: =IF(ISERROR(AQ16*AQ4),"—",AQ16*AQ4) -> 0 | ... AU15: =IF(ISERROR(AU16*AU4),"—",AU16*AU4) -> 0
A16: 占销售收入% | G16: =IF(ISERROR(G15/G4),"—",G15/G4) -> — | H16: =IF(ISERROR(H15/H4),"—",H15/H4) -> — | I16: =IF(ISERROR(I15/I4),"—",I15/I4) -> — | U16: =IF(ISERROR(U15/U4),"—",U15/U4) -> — | V16: =IF(ISERROR(V15/V4),"—",V15/V4) -> — | W16: =IF(ISERROR(W15/W4),"—",W15/W4) -> — | X16: =IF(ISERROR(X15/X4),"—",X15/X4) -> — | Y16: =IF(ISERROR(Y15/Y4),"—",Y15/Y4) -> — | Z16: =IF(ISERROR(Z15/Z4),"—",Z15/Z4) -> — | AA16: =IF(ISERROR(AA15/AA4),"—",AA15/AA4) -> — | AB16: =IF(ISERROR(AB15/AB4),"—",AB15/AB4) -> — | ... AI16: =IF(ISERROR(AI15/AI4),"—",AI15/AI4) -> — | AJ16: =IF(财务基础数据!$W$2=0," ",AG16) | AK16: =IF(财务基础数据!$W$2<=1," ",AH16) | AL16: =IF(财务基础数据!$W$2<=2," ",AI16)
A18: 管理费用 | G18: =利润表!O13 -> 0 | H18: =利润表!S13 -> 0 | I18: =利润表!W13 -> 0 | J18: =IF(COUNT(AJ19:AM19)=4,SUM(AJ18:AM18),J4*J19) -> 0 | K18: =IF(COUNT(AN19:AQ19)=4,SUM(AN18:AQ18),K4*K19) -> 0 | L18: =IF(COUNT(AR19:AU19)=4,SUM(AR18:AU18),L4*L19) -> 0 | M18: =IF(ISERROR(M4*M19),"—",M4*M19) -> 0 | N18: =IF(ISERROR(N4*N19),"—",N4*N19) -> 0 | O18: =IF(ISERROR(O4*O19),"—",O4*O19) -> 0 | P18: =IF(ISERROR(P4*P19),"—",P4*P19) -> 0 | Q18: =IF(ISERROR(Q4*Q19),"—",Q4*Q19) -> 0 | R18: =IF(ISERROR(R4*R19),"—",R4*R19) -> 0 | S18: =IF(ISERROR(S4*S19),"—",S4*S19) -> 0 | U18: =利润表!L13 -> 0 | V18: =利润表!M13-利润表!L13 -> 0 | W18: =利润表!N13-利润表!M13 -> 0 | X18: =利润表!O13-利润表!N13 -> 0 | Y18: =利润表!P13 -> 0 | Z18: =利润表!Q13-利润表!P13 -> 0 | AA18: =利润表!R13-利润表!Q13 -> 0 | AB18: =利润表!S13-利润表!R13 -> 0 | AC18: =利润表!T13 -> 0 | AD18: =利润表!U13-利润表!T13 -> 0 | AE18: =利润表!V13-利润表!U13 -> 0 | AF18: =利润表!W13-利润表!V13 -> 0 | AG18: =IF(财务基础数据!$W$2=0,0,利润表!X13) -> 0 | AH18: =IF(财务基础数据!$W$2<=1,0,利润表!Y13-利润表!X12) -> 0 | AI18: =IF(财务基础数据!$W$2<=2,0,利润表!Z13-利润表!Y12) -> 0 | AJ18: =IF(ISERROR(AJ19*AJ4),"—",AJ19*AJ4) -> — | AK18: =IF(ISERROR(AK19*AK4),"—",AK19*AK4) -> — | AL18: =IF(ISERROR(AL19*AL4),"—",AL19*AL4) -> — | AM18: =IF(ISERROR(AM19*AM4),"—",AM19*AM4) -> 0 | AN18: =IF(ISERROR(AN19*AN4),"—",AN19*AN4) -> 0 | AO18: =IF(ISERROR(AO19*AO4),"—",AO19*AO4) -> 0 | AP18: =IF(ISERROR(AP19*AP4),"—",AP19*AP4) -> 0 | AQ18: =IF(ISERROR(AQ19*AQ4),"—",AQ19*AQ4) -> 0 | ... AU18: =IF(ISERROR(AU19*AU4),"—",AU19*AU4) -> 0
A19: 占销售收入% | G19: =IF(ISERROR(G18/G4),"—",G18/G4) -> — | H19: =IF(ISERROR(H18/H4),"—",H18/H4) -> — | I19: =IF(ISERROR(I18/I4),"—",I18/I4) -> — | U19: =IF(ISERROR(U18/U4),"—",U18/U4) -> — | V19: =IF(ISERROR(V18/V4),"—",V18/V4) -> — | W19: =IF(ISERROR(W18/W4),"—",W18/W4) -> — | X19: =IF(ISERROR(X18/X4),"—",X18/X4) -> — | Y19: =IF(ISERROR(Y18/Y4),"—",Y18/Y4) -> — | Z19: =IF(ISERROR(Z18/Z4),"—",Z18/Z4) -> — | AA19: =IF(ISERROR(AA18/AA4),"—",AA18/AA4) -> — | AB19: =IF(ISERROR(AB18/AB4),"—",AB18/AB4) -> — | ... AI19: =IF(ISERROR(AI18/AI4),"—",AI18/AI4) -> — | AJ19: =IF(财务基础数据!$W$2=0," ",AG19) | AK19: =IF(财务基础数据!$W$2<=1," ",AH19) | AL19: =IF(财务基础数据!$W$2<=2," ",AI19)
A21: 研发费用 | G21: =利润表!O14 -> 0 | H21: =利润表!S14 -> 0 | I21: =利润表!W14 -> 0 | J21: =IF(COUNT(AJ22:AM22)=4,SUM(AJ21:AM21),J4*J22) -> 0 | K21: =IF(COUNT(AN22:AQ22)=4,SUM(AN21:AQ21),K4*K22) -> 0 | L21: =IF(COUNT(AR22:AU22)=4,SUM(AR21:AU21),L4*L22) -> 0 | M21: =IF(ISERROR(M4*M22),"—",M4*M22) -> 0 | N21: =IF(ISERROR(N4*N22),"—",N4*N22) -> 0 | O21: =IF(ISERROR(O4*O22),"—",O4*O22) -> 0 | P21: =IF(ISERROR(P4*P22),"—",P4*P22) -> 0 | Q21: =IF(ISERROR(Q4*Q22),"—",Q4*Q22) -> 0 | R21: =IF(ISERROR(R4*R22),"—",R4*R22) -> 0 | S21: =IF(ISERROR(S4*S22),"—",S4*S22) -> 0 | U21: =利润表!L14 -> 0 | V21: =利润表!M14-利润表!L14 -> 0 | W21: =利润表!N14-利润表!M14 -> 0 | X21: =利润表!O14-利润表!N14 -> 0 | Y21: =利润表!P14 -> 0 | Z21: =利润表!Q14-利润表!P14 -> 0 | AA21: =利润表!R14-利润表!Q14 -> 0 | AB21: =利润表!S14-利润表!R14 -> 0 | AC21: =利润表!T14 -> 0 | AD21: =利润表!U14-利润表!T14 -> 0 | AE21: =利润表!V14-利润表!U14 -> 0 | AF21: =利润表!W14-利润表!V14 -> 0 | AG21: =IF(财务基础数据!$W$2=0,0,利润表!X14) -> 0 | AH21: =IF(财务基础数据!$W$2<=1,0,利润表!Y14-利润表!X14) -> 0 | AI21: =IF(财务基础数据!$W$2<=2,0,利润表!Z14-利润表!Y14) -> 0 | AJ21: =IF(ISERROR(AJ22*AJ4),"—",AJ22*AJ4) -> — | AK21: =IF(ISERROR(AK22*AK4),"—",AK22*AK4) -> — | AL21: =IF(ISERROR(AL22*AL4),"—",AL22*AL4) -> — | AM21: =IF(ISERROR(AM22*AM4),"—",AM22*AM4) -> 0 | AN21: =IF(ISERROR(AN22*AN4),"—",AN22*AN4) -> 0 | AO21: =IF(ISERROR(AO22*AO4),"—",AO22*AO4) -> 0 | AP21: =IF(ISERROR(AP22*AP4),"—",AP22*AP4) -> 0 | AQ21: =IF(ISERROR(AQ22*AQ4),"—",AQ22*AQ4) -> 0 | ... AU21: =IF(ISERROR(AU22*AU4),"—",AU22*AU4) -> 0
A22: 占销售收入% | G22: =IF(ISERROR(G21/G4),"—",G21/G4) -> — | H22: =IF(ISERROR(H21/H4),"—",H21/H4) -> — | I22: =IF(ISERROR(I21/I4),"—",I21/I4) -> — | U22: =IF(ISERROR(U21/U4),"—",U21/U4) -> — | V22: =IF(ISERROR(V21/V4),"—",V21/V4) -> — | W22: =IF(ISERROR(W21/W4),"—",W21/W4) -> — | X22: =IF(ISERROR(X21/X4),"—",X21/X4) -> — | Y22: =IF(ISERROR(Y21/Y4),"—",Y21/Y4) -> — | Z22: =IF(ISERROR(Z21/Z4),"—",Z21/Z4) -> — | AA22: =IF(ISERROR(AA21/AA4),"—",AA21/AA4) -> — | AB22: =IF(ISERROR(AB21/AB4),"—",AB21/AB4) -> — | ... AI22: =IF(ISERROR(AI21/AI4),"—",AI21/AI4) -> — | AJ22: =IF(财务基础数据!$W$2=0," ",AG22) | AK22: =IF(财务基础数据!$W$2<=1," ",AH22) | AL22: =IF(财务基础数据!$W$2<=2," ",AI22)
A24: 其他费用 | G24: =利润表!O15 -> 0 | H24: =利润表!S15 -> 0 | I24: =利润表!W15 -> 0 | J24: =IF(COUNT(AJ25:AM25)=4,SUM(AJ24:AM24),J4*J25) -> 0 | K24: =IF(COUNT(AN25:AQ25)=4,SUM(AN24:AQ24),K4*K25) -> 0 | L24: =IF(COUNT(AR25:AU25)=4,SUM(AR24:AU24),L4*L25) -> 0 | M24: =IF(ISERROR(M4*M25),"—",M4*M25) -> 0 | N24: =IF(ISERROR(N4*N25),"—",N4*N25) -> 0 | O24: =IF(ISERROR(O4*O25),"—",O4*O25) -> 0 | P24: =IF(ISERROR(P4*P25),"—",P4*P25) -> 0 | Q24: =IF(ISERROR(Q4*Q25),"—",Q4*Q25) -> 0 | R24: =IF(ISERROR(R4*R25),"—",R4*R25) -> 0 | S24: =IF(ISERROR(S4*S25),"—",S4*S25) -> 0 | U24: =利润表!L15 -> 0 | V24: =利润表!M15-利润表!L15 -> 0 | W24: =利润表!N15-利润表!M15 -> 0 | X24: =利润表!O15-利润表!N15 -> 0 | Y24: =利润表!P15 -> 0 | Z24: =利润表!Q15-利润表!P15 -> 0 | AA24: =利润表!R15-利润表!Q15 -> 0 | AB24: =利润表!S15-利润表!R15 -> 0 | AC24: =利润表!T15 -> 0 | AD24: =利润表!U15-利润表!T15 -> 0 | AE24: =利润表!V15-利润表!U15 -> 0 | AF24: =利润表!W15-利润表!V15 -> 0 | AG24: =IF(财务基础数据!$W$2=0,0,利润表!X15) -> 0 | AH24: =IF(财务基础数据!$W$2<=1,0,利润表!Y15-利润表!X15) -> 0 | AI24: =IF(财务基础数据!$W$2<=2,0,利润表!Z15-利润表!Y15) -> 0 | AJ24: =IF(ISERROR(AJ25*AJ4),"—",AJ25*AJ4) -> — | AK24: =IF(ISERROR(AK25*AK4),"—",AK25*AK4) -> — | AL24: =IF(ISERROR(AL25*AL4),"—",AL25*AL4) -> — | AM24: =IF(ISERROR(AM25*AM4),"—",AM25*AM4) -> 0 | AN24: =IF(ISERROR(AN25*AN4),"—",AN25*AN4) -> 0 | AO24: =IF(ISERROR(AO25*AO4),"—",AO25*AO4) -> 0 | AP24: =IF(ISERROR(AP25*AP4),"—",AP25*AP4) -> 0 | AQ24: =IF(ISERROR(AQ25*AQ4),"—",AQ25*AQ4) -> 0 | ... AU24: =IF(ISERROR(AU25*AU4),"—",AU25*AU4) -> 0
A25: 占销售收入% | G25: =IF(ISERROR(G24/G4),"—",G24/G4) -> — | H25: =IF(ISERROR(H24/H4),"—",H24/H4) -> — | I25: =IF(ISERROR(I24/I4),"—",I24/I4) -> — | U25: =IF(ISERROR(U24/U4),"—",U24/U4) -> — | V25: =IF(ISERROR(V24/V4),"—",V24/V4) -> — | W25: =IF(ISERROR(W24/W4),"—",W24/W4) -> — | X25: =IF(ISERROR(X24/X4),"—",X24/X4) -> — | Y25: =IF(ISERROR(Y24/Y4),"—",Y24/Y4) -> — | Z25: =IF(ISERROR(Z24/Z4),"—",Z24/Z4) -> — | AA25: =IF(ISERROR(AA24/AA4),"—",AA24/AA4) -> — | AB25: =IF(ISERROR(AB24/AB4),"—",AB24/AB4) -> — | ... AI25: =IF(ISERROR(AI24/AI4),"—",AI24/AI4) -> — | AJ25: =IF(财务基础数据!$W$2=0," ",AG25) | AK25: =IF(财务基础数据!$W$2<=1," ",AH25) | AL25: =IF(财务基础数据!$W$2<=2," ",AI25)
A27: 权益性投资损益 | G27: =利润表!O20 -> 0 | H27: =利润表!S20 -> 0 | I27: =利润表!W20 -> 0 | J27: =IF(COUNT(AJ28:AM28)=4,SUM(AJ27:AM27),资产负债表!AA16*J28) -> 0 | K27: =IF(COUNT(AN28:AQ28)=4,SUM(AN27:AQ27),资产负债表!AB16*K28) -> 0 | L27: =IF(COUNT(AR28:AU28)=4,SUM(AR27:AU27),资产负债表!AC16*L28) -> 0 | M27: =IF(ISERROR(资产负债表!AD16*M28),"—",资产负债表!AD16*M28) -> 0 | N27: =IF(ISERROR(资产负债表!AE16*N28),"—",资产负债表!AE16*N28) -> 0 | O27: =IF(ISERROR(资产负债表!AF16*O28),"—",资产负债表!AF16*O28) -> 0 | P27: =IF(ISERROR(资产负债表!AG16*P28),"—",资产负债表!AG16*P28) -> 0 | Q27: =IF(ISERROR(资产负债表!AH16*Q28),"—",资产负债表!AH16*Q28) -> 0 | R27: =IF(ISERROR(资产负债表!AI16*R28),"—",资产负债表!AI16*R28) -> 0 | S27: =IF(ISERROR(资产负债表!AJ16*S28),"—",资产负债表!AJ16*S28) -> 0 | U27: =利润表!L20 -> 0 | V27: =利润表!M20-利润表!L20 -> 0 | W27: =利润表!N20-利润表!M20 -> 0 | X27: =利润表!O20-利润表!N20 -> 0 | Y27: =利润表!P20 -> 0 | Z27: =利润表!Q20-利润表!P20 -> 0 | AA27: =利润表!R20-利润表!Q20 -> 0 | AB27: =利润表!S20-利润表!R20 -> 0 | AC27: =利润表!T20 -> 0 | AD27: =利润表!U20-利润表!T20 -> 0 | AE27: =利润表!V20-利润表!U20 -> 0 | AF27: =利润表!W20-利润表!V20 -> 0 | AG27: =IF(财务基础数据!$W$2=0,0,利润表!X20) -> 0 | AH27: =IF(财务基础数据!$W$2<=1,0,利润表!Y20-利润表!X20) -> 0 | AI27: =IF(财务基础数据!$W$2<=2,0,利润表!Z20-利润表!Y20) -> 0 | AJ27: =IF(ISERROR(AJ28*资产负债表!$AA$16),"—",AJ28*资产负债表!$AA$16) -> — | AK27: =IF(ISERROR(AK28*资产负债表!$AA$16),"—",AK28*资产负债表!$AA$16) -> — | AL27: =IF(ISERROR(AL28*资产负债表!$AA$16),"—",AL28*资产负债表!$AA$16) -> — | AM27: =IF(ISERROR(AM28*资产负债表!$AA$16),"—",AM28*资产负债表!$AA$16) -> 0 | AN27: =IF(ISERROR(AN28*资产负债表!$AB$16),"—",AN28*资产负债表!$AB$16) -> 0 | AO27: =IF(ISERROR(AO28*资产负债表!$AB$16),"—",AO28*资产负债表!$AB$16) -> 0 | AP27: =IF(ISERROR(AP28*资产负债表!$AB$16),"—",AP28*资产负债表!$AB$16) -> 0 | AQ27: =IF(ISERROR(AQ28*资产负债表!$AB$16),"—",AQ28*资产负债表!$AB$16) -> 0 | AR27: =IF(ISERROR(AR28*资产负债表!$AC$16),"—",AR28*资产负债表!$AC$16) -> 0 | AS27: =IF(ISERROR(AS28*资产负债表!$AC$16),"—",AS28*资产负债表!$AC$16) -> 0 | AT27: =IF(ISERROR(AT28*资产负债表!$AC$16),"—",AT28*资产负债表!$AC$16) -> 0 | AU27: =IF(ISERROR(AU28*资产负债表!$AC$16),"—",AU28*资产负债表!$AC$16) -> 0
A28: 占权益性投资% | G28: =IF(ISERROR(G27/资产负债表!O16),0,G27/资产负债表!O16) -> 0 | H28: =IF(ISERROR(H27/资产负债表!S16),0,H27/资产负债表!S16) -> 0 | I28: =IF(ISERROR(I27/资产负债表!W16),0,I27/资产负债表!W16) -> 0 | U28: =IF(ISERROR(U27/资产负债表!$O$16),"—",U27/资产负债表!$O$16) -> — | V28: =IF(ISERROR(V27/资产负债表!$O$16),"—",V27/资产负债表!$O$16) -> — | W28: =IF(ISERROR(W27/资产负债表!$O$16),"—",W27/资产负债表!$O$16) -> — | X28: =IF(ISERROR(X27/资产负债表!$O$16),"—",X27/资产负债表!$O$16) -> — | Y28: =IF(ISERROR(Y27/资产负债表!$S$16),"—",Y27/资产负债表!$S$16) -> — | Z28: =IF(ISERROR(Z27/资产负债表!$S$16),"—",Z27/资产负债表!$S$16) -> — | AA28: =IF(ISERROR(AA27/资产负债表!$S$16),"—",AA27/资产负债表!$S$16) -> — | AB28: =IF(ISERROR(AB27/资产负债表!$S$16),"—",AB27/资产负债表!$S$16) -> — | AC28: =IF(ISERROR(AC27/资产负债表!$W$16),"—",AC27/资产负债表!$W$16) -> — | AD28: =IF(ISERROR(AD27/资产负债表!$W$16),"—",AD27/资产负债表!$W$16) -> — | AE28: =IF(ISERROR(AE27/资产负债表!$W$16),"—",AE27/资产负债表!$W$16) -> — | AF28: =IF(ISERROR(AF27/资产负债表!$W$16),"—",AF27/资产负债表!$W$16) -> — | AG28: =IF(ISERROR(AG27/资产负债表!$AA$16),"—",AG27/资产负债表!$AA$16) -> — | AH28: =IF(ISERROR(AH27/资产负债表!$AA$16),"—",AH27/资产负债表!$AA$16) -> — | AI28: =IF(ISERROR(AI27/资产负债表!$AA$16),"—",AI27/资产负债表!$AA$16) -> — | AJ28: =IF(财务基础数据!$W$2=0," ",AG28) | AK28: =IF(财务基础数据!$W$2<=1," ",AH28) | AL28: =IF(财务基础数据!$W$2<=2," ",AI28)
A30: 其他非经营性损益 | G30: =利润表!O21 -> 0 | H30: =利润表!S21 -> 0 | I30: =利润表!W21 -> 0 | J30: =IF(COUNT(AJ31:AM31)=4,SUM(AJ30:AM30),J4*J31) -> 0 | K30: =IF(COUNT(AN31:AQ31)=4,SUM(AN30:AQ30),K4*K31) -> 0 | L30: =IF(COUNT(AR31:AU31)=4,SUM(AR30:AU30),L4*L31) -> 0 | M30: =IF(ISERROR(M4*M31),"—",M4*M31) -> 0 | N30: =IF(ISERROR(N4*N31),"—",N4*N31) -> 0 | O30: =IF(ISERROR(O4*O31),"—",O4*O31) -> 0 | P30: =IF(ISERROR(P4*P31),"—",P4*P31) -> 0 | Q30: =IF(ISERROR(Q4*Q31),"—",Q4*Q31) -> 0 | R30: =IF(ISERROR(R4*R31),"—",R4*R31) -> 0 | S30: =IF(ISERROR(S4*S31),"—",S4*S31) -> 0 | U30: =利润表!L21 -> 0 | V30: =利润表!M21-利润表!L21 -> 0 | W30: =利润表!N21-利润表!M21 -> 0 | X30: =利润表!O21-利润表!N21 -> 0 | Y30: =利润表!P21 -> 0 | Z30: =利润表!Q21-利润表!P21 -> 0 | AA30: =利润表!R21-利润表!Q21 -> 0 | AB30: =利润表!S21-利润表!R21 -> 0 | AC30: =利润表!T21 -> 0 | AD30: =利润表!U21-利润表!T21 -> 0 | AE30: =利润表!V21-利润表!U21 -> 0 | AF30: =利润表!W21-利润表!V21 -> 0 | AG30: =IF(财务基础数据!$W$2=0,0,利润表!X21) -> 0 | AH30: =IF(财务基础数据!$W$2<=1,0,利润表!Y21-利润表!X21) -> 0 | AI30: =IF(财务基础数据!$W$2<=2,0,利润表!Z21-利润表!Y21) -> 0 | AJ30: =IF(ISERROR(AJ31*AJ4),"—",AJ31*AJ4) -> — | AK30: =IF(ISERROR(AK31*AK4),"—",AK31*AK4) -> — | AL30: =IF(ISERROR(AL31*AL4),"—",AL31*AL4) -> — | AM30: =IF(ISERROR(AM31*AM4),"—",AM31*AM4) -> 0 | AN30: =IF(ISERROR(AN31*AN4),"—",AN31*AN4) -> 0 | AO30: =IF(ISERROR(AO31*AO4),"—",AO31*AO4) -> 0 | AP30: =IF(ISERROR(AP31*AP4),"—",AP31*AP4) -> 0 | AQ30: =IF(ISERROR(AQ31*AQ4),"—",AQ31*AQ4) -> 0 | ... AU30: =IF(ISERROR(AU31*AU4),"—",AU31*AU4) -> 0
A31: 占销售收入% | G31: =IF(ISERROR(G30/G4),"—",G30/G4) -> — | H31: =IF(ISERROR(H30/H4),"—",H30/H4) -> — | I31: =IF(ISERROR(I30/I4),"—",I30/I4) -> — | U31: =IF(ISERROR(U30/U4),"—",U30/U4) -> — | V31: =IF(ISERROR(V30/V4),"—",V30/V4) -> — | W31: =IF(ISERROR(W30/W4),"—",W30/W4) -> — | X31: =IF(ISERROR(X30/X4),"—",X30/X4) -> — | Y31: =IF(ISERROR(Y30/Y4),"—",Y30/Y4) -> — | Z31: =IF(ISERROR(Z30/Z4),"—",Z30/Z4) -> — | AA31: =IF(ISERROR(AA30/AA4),"—",AA30/AA4) -> — | AB31: =IF(ISERROR(AB30/AB4),"—",AB30/AB4) -> — | ... AI31: =IF(ISERROR(AI30/AI4),"—",AI30/AI4) -> — | AJ31: =IF(财务基础数据!$W$2=0," ",AG31) | AK31: =IF(财务基础数据!$W$2<=1," ",AH31) | AL31: =IF(财务基础数据!$W$2<=2," ",AI31)
A33: 所得税支出 | G33: =利润表!O25 -> 0 | H33: =利润表!S25 -> 0 | I33: =利润表!W25 -> 0 | J33: =IF(COUNT(AJ33:AM33)=4,SUM(AJ33:AM33),J34*利润表!AA24) -> 0 | K33: =IF(COUNT(AN33:AQ33)=4,SUM(AN33:AQ33),K34*利润表!AB24) -> 0 | L33: =IF(COUNT(AR33:AU33)=4,SUM(AR33:AU33),L34*利润表!AC24) -> 0 | M33: =IF(ISERROR(M34*利润表!AD24),"0",M34*利润表!AD24) -> 0 | N33: =IF(ISERROR(N34*利润表!AE24),"0",N34*利润表!AE24) -> 0 | O33: =IF(ISERROR(O34*利润表!AF24),"0",O34*利润表!AF24) -> 0 | P33: =IF(ISERROR(P34*利润表!AG24),"0",P34*利润表!AG24) -> 0 | Q33: =IF(ISERROR(Q34*利润表!AH24),"0",Q34*利润表!AH24) -> 0 | R33: =IF(ISERROR(R34*利润表!AI24),"0",R34*利润表!AI24) -> 0 | S33: =IF(ISERROR(S34*利润表!AJ24),"0",S34*利润表!AJ24) -> 0 | U33: =利润表!L25 -> 0 | V33: =利润表!M25-利润表!L25 -> 0 | W33: =利润表!N25-利润表!M25 -> 0 | X33: =利润表!O25-利润表!N25 -> 0 | Y33: =利润表!P25 -> 0 | Z33: =利润表!Q25-利润表!P25 -> 0 | AA33: =利润表!R25-利润表!Q25 -> 0 | AB33: =利润表!S25-利润表!R25 -> 0 | AC33: =利润表!T25 -> 0 | AD33: =利润表!U25-利润表!T25 -> 0 | AE33: =利润表!V25-利润表!U25 -> 0 | AF33: =利润表!W25-利润表!V25 -> 0 | AG33: =IF(财务基础数据!$W$2=0,0,利润表!X25) -> 0 | AH33: =IF(财务基础数据!$W$2<=1,0,利润表!Y25-利润表!X25) -> 0 | AI33: =IF(财务基础数据!$W$2<=2,0,利润表!Z25-利润表!Y25) -> 0 | AJ33: =IF(财务基础数据!$W$2=0,"",AG33) | AK33: =IF(财务基础数据!$W$2<=1,"",AH33) | AL33: =IF(财务基础数据!$W$2<=2,"",AI33)
A34: 所得税税率 | G34: =IF(ISERROR(G33/利润表!O24),"—",G33/利润表!O24) -> — | H34: =IF(ISERROR(H33/利润表!S24),"—",H33/利润表!S24) -> — | I34: =IF(ISERROR(I33/利润表!W24),"—",I33/利润表!W24) -> —
A36: 少数股东损益 | G36: =利润表!O27 -> 0 | H36: =利润表!S27 -> 0 | I36: =利润表!W27 -> 0 | J36: =IF(COUNT(AJ36:AM36)=4,SUM(AJ36:AM36),J37*(利润表!AA26)) -> 0 | K36: =IF(COUNT(AN36:AQ36)=4,SUM(AN36:AQ36),K37*(利润表!AB26)) -> 0 | L36: =IF(COUNT(AR36:AU36)=4,SUM(AR36:AU36),L37*(利润表!AC26)) -> 0 | M36: =IF(ISERROR(M37*(利润表!AD26)),"—",M37*(利润表!AD26)) -> 0 | N36: =IF(ISERROR(N37*(利润表!AE26)),"—",N37*(利润表!AE26)) -> 0 | O36: =IF(ISERROR(O37*(利润表!AF26)),"—",O37*(利润表!AF26)) -> 0 | P36: =IF(ISERROR(P37*(利润表!AG26)),"—",P37*(利润表!AG26)) -> 0 | Q36: =IF(ISERROR(Q37*(利润表!AH26)),"—",Q37*(利润表!AH26)) -> 0 | R36: =IF(ISERROR(R37*(利润表!AI26)),"—",R37*(利润表!AI26)) -> 0 | S36: =IF(ISERROR(S37*(利润表!AJ26)),"—",S37*(利润表!AJ26)) -> 0 | U36: =利润表!L27 -> 0 | V36: =利润表!M27-利润表!L27 -> 0 | W36: =利润表!N27-利润表!M27 -> 0 | X36: =利润表!O27-利润表!N27 -> 0 | Y36: =利润表!P27 -> 0 | Z36: =利润表!Q27-利润表!P27 -> 0 | AA36: =利润表!R27-利润表!Q27 -> 0 | AB36: =利润表!S27-利润表!R27 -> 0 | AC36: =利润表!T27 -> 0 | AD36: =利润表!U27-利润表!T27 -> 0 | AE36: =利润表!V27-利润表!U27 -> 0 | AF36: =利润表!W27-利润表!V27 -> 0 | AG36: =IF(财务基础数据!$W$2=0,0,利润表!X27) -> 0 | AH36: =IF(财务基础数据!$W$2<=1,0,利润表!Y27-利润表!X27) -> 0 | AI36: =IF(财务基础数据!$W$2<=2,0,利润表!Z27-利润表!Y27) -> 0 | AJ36: =IF(财务基础数据!$W$2=0,"",AG36) | AK36: =IF(财务基础数据!$W$2<=1,"",AH36) | AL36: =IF(财务基础数据!$W$2<=2,"",AI36)
A37: 少数股东损益/净利润 | G37: =IF(ISERROR(G36/(利润表!O26)),"—",G36/(利润表!O26)) -> — | H37: =IF(ISERROR(H36/(利润表!S26)),"—",H36/(利润表!S26)) -> — | I37: =IF(ISERROR(I36/(利润表!W26)),"—",I36/(利润表!W26)) -> —

Sheet 资产预测
A2: 营运资金
A3: =主要财务摘要!H2 -> 单位：港币(百万)
A4: 会计年度： | D4: =资产负债表!O4 -> 2019 | E4: =资产负债表!S4 -> 2020 | F4: =资产负债表!W4 -> 2021 | G4: =资产负债表!X4 -> 1Q22 | H4: =资产负债表!Y4 -> 1H22 | I4: =资产负债表!Z4 -> 3Q22 | J4: =资产负债表!AA4 -> 2022E | K4: =资产负债表!AB4 -> 2023 | L4: =资产负债表!AC4 -> 2024 | M4: =资产负债表!AD4 -> 2025 | ... S4: =资产负债表!AJ4 -> 2031
A5: 营业收入 | D5: =利润表!O6 -> 0 | E5: =利润表!S6 -> 0 | F5: =利润表!W6 -> 0 | G5: =利润表!X6 -> 0 | H5: =利润表!Y6 -> 0 | I5: =利润表!Z6 -> 0 | J5: =利润表!AA6 -> 0 | K5: =利润表!AB6 -> 0 | L5: =利润表!AC6 -> 0 | M5: =利润表!AD6 -> 0 | ... S5: =利润表!AJ6 -> 0
A6: 营业成本 | D6: =利润表!O9 -> 0 | E6: =利润表!S9 -> 0 | F6: =利润表!W9 -> 0 | G6: =利润表!X9 -> 0 | H6: =利润表!Y9 -> 0 | I6: =利润表!Z9 -> 0 | J6: =利润表!AA9 -> 0 | K6: =利润表!AB9 -> 0 | L6: =利润表!AC9 -> 0 | M6: =利润表!AD9 -> 0 | ... S6: =利润表!AJ9 -> 0
A8: （一）流动资产
A9: 应收账款及票据 | D9: =资产负债表!O9 -> 0 | E9: =资产负债表!S9 -> 0 | F9: =资产负债表!W9 -> 0 | G9: =资产负债表!X9 -> 0 | H9: =资产负债表!Y9 -> 0 | I9: =资产负债表!Z9 -> 0 | J9: =IF(ISERROR(J5/(360/J10)),0,J5/(360/J10)) -> 0 | K9: =IF(ISERROR(K5/(360/K10)),0,K5/(360/K10)) -> 0 | L9: =IF(ISERROR(L5/(360/L10)),0,L5/(360/L10)) -> 0 | M9: =IF(ISERROR(M5/(360/M10)),0,M5/(360/M10)) -> 0 | N9: =IF(ISERROR(N5/(360/N10)),0,N5/(360/N10)) -> 0 | O9: =IF(ISERROR(O5/(360/O10)),0,O5/(360/O10)) -> 0 | P9: =IF(ISERROR(P5/(360/P10)),0,P5/(360/P10)) -> 0 | Q9: =IF(ISERROR(Q5/(360/Q10)),0,Q5/(360/Q10)) -> 0 | ... S9: =IF(ISERROR(S5/(360/S10)),0,S5/(360/S10)) -> 0
A10: 周转天数（相对于销售收入） | D10: =IF(ISERROR(360/(D5/D9)),"—",360/(D5/D9)) -> — | E10: =IF(ISERROR(360/(E5/E9)),"—",360/(E5/E9)) -> — | F10: =IF(ISERROR(360/(F5/F9)),"—",360/(F5/F9)) -> — | G10: =IF(ISERROR(360/(G5/G9)),"—",360/(G5/G9)) -> — | H10: =IF(ISERROR(360/(H5/H9)),"—",360/(H5/H9)) -> — | I10: =IF(ISERROR(360/(I5/I9)),"—",360/(I5/I9)) -> — | T10: 说明：此处周转天数按照期末值计算
A11: 应收帐款/销售收入（%） | D11: =IF(ISERROR(D9/D5),"—",D9/D5) -> — | E11: =IF(ISERROR(E9/E5),"—",E9/E5) -> — | F11: =IF(ISERROR(F9/F5),"—",F9/F5) -> — | G11: =IF(ISERROR(G9/G5),"—",G9/G5) -> — | H11: =IF(ISERROR(H9/H5),"—",H9/H5) -> — | I11: =IF(ISERROR(I9/I5),"—",I9/I5) -> — | J11: =IF(ISERROR(J9/J5),"—",J9/J5) -> — | K11: =IF(ISERROR(K9/K5),"—",K9/K5) -> — | ... S11: =IF(ISERROR(S9/S5),"—",S9/S5) -> —
A13: 存货 | D13: =资产负债表!O11 -> 0 | E13: =资产负债表!S11 -> 0 | F13: =资产负债表!W11 -> 0 | G13: =资产负债表!X11 -> 0 | H13: =资产负债表!Y11 -> 0 | I13: =资产负债表!Z11 -> 0 | J13: =IF(ISERROR(J6/(360/J14)),0,J6/(360/J14)) -> 0 | K13: =IF(ISERROR(K6/(360/K14)),0,K6/(360/K14)) -> 0 | L13: =IF(ISERROR(L6/(360/L14)),0,L6/(360/L14)) -> 0 | M13: =IF(ISERROR(M6/(360/M14)),0,M6/(360/M14)) -> 0 | N13: =IF(ISERROR(N6/(360/N14)),0,N6/(360/N14)) -> 0 | O13: =IF(ISERROR(O6/(360/O14)),0,O6/(360/O14)) -> 0 | P13: =IF(ISERROR(P6/(360/P14)),0,P6/(360/P14)) -> 0 | Q13: =IF(ISERROR(Q6/(360/Q14)),0,Q6/(360/Q14)) -> 0 | ... S13: =IF(ISERROR(S6/(360/S14)),0,S6/(360/S14)) -> 0
A14: 周转天数（相对于销售成本） | D14: =IF(ISERROR(360/(D6/D13)),"—",360/(D6/D13)) -> — | E14: =IF(ISERROR(360/(E6/E13)),"—",360/(E6/E13)) -> — | F14: =IF(ISERROR(360/(F6/F13)),"—",360/(F6/F13)) -> — | G14: =IF(ISERROR(360/(G6/G13)),"—",360/(G6/G13)) -> — | H14: =IF(ISERROR(360/(H6/H13)),"—",360/(H6/H13)) -> — | I14: =IF(ISERROR(360/(I6/I13)),"—",360/(I6/I13)) -> — | T14: 说明：此处周转天数按照期末值计算
A15: 存货/销售成本（%） | D15: =IF(ISERROR(D13/D6),"—",D13/D6) -> — | E15: =IF(ISERROR(E13/E6),"—",E13/E6) -> — | F15: =IF(ISERROR(F13/F6),"—",F13/F6) -> — | G15: =IF(ISERROR(G13/G6),"—",G13/G6) -> — | H15: =IF(ISERROR(H13/H6),"—",H13/H6) -> — | I15: =IF(ISERROR(I13/I6),"—",I13/I6) -> — | J15: =IF(ISERROR(J13/J6),"—",J13/J6) -> — | K15: =IF(ISERROR(K13/K6),"—",K13/K6) -> — | ... S15: =IF(ISERROR(S13/S6),"—",S13/S6) -> —
A17: 其他应收款 | D17: =资产负债表!O10 -> 0 | E17: =资产负债表!S10 -> 0 | F17: =资产负债表!W10 -> 0 | G17: =资产负债表!X10 -> 0 | H17: =资产负债表!Y10 -> 0 | I17: =资产负债表!Z10 -> 0 | J17: =IF(ISERROR(J18*J5),0,J18*J5) -> 0 | K17: =IF(ISERROR(K18*K5),0,K18*K5) -> 0 | L17: =IF(ISERROR(L18*L5),0,L18*L5) -> 0 | M17: =IF(ISERROR(M18*M5),0,M18*M5) -> 0 | N17: =IF(ISERROR(N18*N5),0,N18*N5) -> 0 | O17: =IF(ISERROR(O18*O5),0,O18*O5) -> 0 | P17: =IF(ISERROR(P18*P5),0,P18*P5) -> 0 | Q17: =IF(ISERROR(Q18*Q5),0,Q18*Q5) -> 0 | ... S17: =IF(ISERROR(S18*S5),0,S18*S5) -> 0
A18: 比销售收入（%） | D18: =IF(ISERROR(D17/D5),"—",D17/D5) -> — | E18: =IF(ISERROR(E17/E5),"—",E17/E5) -> — | F18: =IF(ISERROR(F17/F5),"—",F17/F5) -> — | G18: =IF(ISERROR(G17/G5),"—",G17/G5) -> — | H18: =IF(ISERROR(H17/H5),"—",H17/H5) -> — | I18: =IF(ISERROR(I17/I5),"—",I17/I5) -> —
A20: 其他流动资产 | D20: =资产负债表!O12 -> 0 | E20: =资产负债表!S12 -> 0 | F20: =资产负债表!W12 -> 0 | G20: =资产负债表!X12 -> 0 | H20: =资产负债表!Y12 -> 0 | I20: =资产负债表!Z12 -> 0 | J20: =IF(ISERROR(J21*J5),0,J21*J5) -> 0 | K20: =IF(ISERROR(K21*K5),0,K21*K5) -> 0 | L20: =IF(ISERROR(L21*L5),0,L21*L5) -> 0 | M20: =IF(ISERROR(M21*M5),0,M21*M5) -> 0 | N20: =IF(ISERROR(N21*N5),0,N21*N5) -> 0 | O20: =IF(ISERROR(O21*O5),0,O21*O5) -> 0 | P20: =IF(ISERROR(P21*P5),0,P21*P5) -> 0 | Q20: =IF(ISERROR(Q21*Q5),0,Q21*Q5) -> 0 | ... S20: =IF(ISERROR(S21*S5),0,S21*S5) -> 0
A21: 比销售收入（%） | D21: =IF(ISERROR(D20/D5),"—",D20/D5) -> — | E21: =IF(ISERROR(E20/E5),"—",E20/E5) -> — | F21: =IF(ISERROR(F20/F5),"—",F20/F5) -> — | G21: =IF(ISERROR(G20/G5),"—",G20/G5) -> — | H21: =IF(ISERROR(H20/H5),"—",H20/H5) -> — | I21: =IF(ISERROR(I20/I5),"—",I20/I5) -> —
A23: （二）流动负债
A24: 应付账款及票据 | D24: =资产负债表!O28 -> 0 | E24: =资产负债表!S28 -> 0 | F24: =资产负债表!W28 -> 0 | G24: =资产负债表!X28 -> 0 | H24: =资产负债表!Y28 -> 0 | I24: =资产负债表!Z28 -> 0 | J24: =IF(ISERROR(J6/(360/J25)),0,J6/(360/J25)) -> 0 | K24: =IF(ISERROR(K6/(360/K25)),0,K6/(360/K25)) -> 0 | L24: =IF(ISERROR(L6/(360/L25)),0,L6/(360/L25)) -> 0 | M24: =IF(ISERROR(M6/(360/M25)),0,M6/(360/M25)) -> 0 | N24: =IF(ISERROR(N6/(360/N25)),0,N6/(360/N25)) -> 0 | O24: =IF(ISERROR(O6/(360/O25)),0,O6/(360/O25)) -> 0 | P24: =IF(ISERROR(P6/(360/P25)),0,P6/(360/P25)) -> 0 | Q24: =IF(ISERROR(Q6/(360/Q25)),0,Q6/(360/Q25)) -> 0 | ... S24: =IF(ISERROR(S6/(360/S25)),0,S6/(360/S25)) -> 0
A25: 周转天数（相对于销售成本） | D25: =IF(ISERROR(360/(D6/D24)),"—",360/(D6/D24)) -> — | E25: =IF(ISERROR(360/(E6/E24)),"—",360/(E6/E24)) -> — | F25: =IF(ISERROR(360/(F6/F24)),"—",360/(F6/F24)) -> — | G25: =IF(ISERROR(360/(G6/G24)),"—",360/(G6/G24)) -> — | H25: =IF(ISERROR(360/(H6/H24)),"—",360/(H6/H24)) -> — | I25: =IF(ISERROR(360/(I6/I24)),"—",360/(I6/I24)) -> — | T25: 说明：此处周转天数按照期末值计算
A26: 应付帐款/销售成本（%） | D26: =IF(ISERROR(D24/D6),"—",D24/D6) -> — | E26: =IF(ISERROR(E24/E6),"—",E24/E6) -> — | F26: =IF(ISERROR(F24/F6),"—",F24/F6) -> — | G26: =IF(ISERROR(G24/G6),"—",G24/G6) -> — | H26: =IF(ISERROR(H24/H6),"—",H24/H6) -> — | I26: =IF(ISERROR(I24/I6),"—",I24/I6) -> — | J26: =IF(ISERROR(J24/J6),"—",J24/J6) -> — | K26: =IF(ISERROR(K24/K6),"—",K24/K6) -> — | ... S26: =IF(ISERROR(S24/S6),"—",S24/S6) -> —
A28: 其他流动负债 | D28: =资产负债表!O32 -> 0 | E28: =资产负债表!S32 -> 0 | F28: =资产负债表!W32 -> 0 | G28: =资产负债表!X32 -> 0 | H28: =资产负债表!Y32 -> 0 | I28: =资产负债表!Z32 -> 0 | J28: =IF(ISERROR(J29*J5),0,J29*J5) -> 0 | K28: =IF(ISERROR(K29*K5),0,K29*K5) -> 0 | L28: =IF(ISERROR(L29*L5),0,L29*L5) -> 0 | M28: =IF(ISERROR(M29*M5),0,M29*M5) -> 0 | N28: =IF(ISERROR(N29*N5),0,N29*N5) -> 0 | O28: =IF(ISERROR(O29*O5),0,O29*O5) -> 0 | P28: =IF(ISERROR(P29*P5),0,P29*P5) -> 0 | Q28: =IF(ISERROR(Q29*Q5),0,Q29*Q5) -> 0 | ... S28: =IF(ISERROR(S29*S5),0,S29*S5) -> 0
A29: 比销售收入（%） | D29: =IF(ISERROR(D28/D5),"—",D28/D5) -> — | E29: =IF(ISERROR(E28/E5),"—",E28/E5) -> — | F29: =IF(ISERROR(F28/F5),"—",F28/F5) -> — | G29: =IF(ISERROR(G28/G5),"—",G28/G5) -> — | H29: =IF(ISERROR(H28/H5),"—",H28/H5) -> — | I29: =IF(ISERROR(I28/I5),"—",I28/I5) -> —
A31: 应交税金 | D31: =资产负债表!O29 -> 0 | E31: =资产负债表!S29 -> 0 | F31: =资产负债表!W29 -> 0 | G31: =资产负债表!X29 -> 0 | H31: =资产负债表!Y29 -> 0 | I31: =资产负债表!Z29 -> 0 | J31: =IF(ISERROR(J32*J5),0,J32*J5) -> 0 | K31: =IF(ISERROR(K32*K5),0,K32*K5) -> 0 | L31: =IF(ISERROR(L32*L5),0,L32*L5) -> 0 | M31: =IF(ISERROR(M32*M5),0,M32*M5) -> 0 | N31: =IF(ISERROR(N32*N5),0,N32*N5) -> 0 | O31: =IF(ISERROR(O32*O5),0,O32*O5) -> 0 | P31: =IF(ISERROR(P32*P5),0,P32*P5) -> 0 | Q31: =IF(ISERROR(Q32*Q5),0,Q32*Q5) -> 0 | ... S31: =IF(ISERROR(S32*S5),0,S32*S5) -> 0
A32: 比销售收入（%） | D32: =IF(ISERROR(D31/D5),"—",D31/D5) -> — | E32: =IF(ISERROR(E31/E5),"—",E31/E5) -> — | F32: =IF(ISERROR(F31/F5),"—",F31/F5) -> — | G32: =IF(ISERROR(G31/G5),"—",G31/G5) -> — | H32: =IF(ISERROR(H31/H5),"—",H31/H5) -> — | I32: =IF(ISERROR(I31/I5),"—",I31/I5) -> —
A35: 投资预测
A36: =A3 -> 单位：港币(百万)
A37: 会计年度截止日：12/31 | D37: =D4 -> 2019 | E37: =E4 -> 2020 | F37: =F4 -> 2021 | G37: =G4 -> 1Q22 | H37: =H4 -> 1H22 | I37: =I4 -> 3Q22 | J37: =J4 -> 2022E | K37: =K4 -> 2023 | ... S37: =S4 -> 2031
A39: （一）短期投资
A40: 交易性金融资产 | D40: =资产负债表!O7 -> 0 | E40: =资产负债表!S7 -> 0 | F40: =资产负债表!W7 -> 0 | G40: =资产负债表!X7 -> 0 | H40: =资产负债表!Y7 -> 0 | I40: =资产负债表!Z7 -> 0 | J40: =IF(ISERROR(F40+J41),"—",F40+J41) -> 0 | K40: =IF(ISERROR(J40+K41),"—",J40+K41) -> 0 | L40: =IF(ISERROR(K40+L41),"—",K40+L41) -> 0 | M40: =IF(ISERROR(L40+M41),"—",L40+M41) -> 0 | N40: =IF(ISERROR(M40+N41),"—",M40+N41) -> 0 | O40: =IF(ISERROR(N40+O41),"—",N40+O41) -> 0 | P40: =IF(ISERROR(O40+P41),"—",O40+P41) -> 0 | Q40: =IF(ISERROR(P40+Q41),"—",P40+Q41) -> 0 | R40: =IF(ISERROR(Q40+R41),"—",Q40+R41) -> 0 | S40: =IF(ISERROR(R40+S41),"—",R40+S41) -> 0
A41: 当期增减 | D41: =D40-资产负债表!K7 -> 0 | E41: =E40-D40 -> 0 | F41: =F40-E40 -> 0 | G41: =IF(财务基础数据!$W$2=0,0,G40-F40) -> 0 | H41: =IF(财务基础数据!$W$2<=1,0,H40-G40) -> 0 | I41: =IF(财务基础数据!$W$2<=2,0,I40-H40) -> 0
A43: 其他短期投资 | D43: =资产负债表!O8 -> 0 | E43: =资产负债表!S8 -> 0 | F43: =资产负债表!W8 -> 0 | G43: =资产负债表!X8 -> 0 | H43: =资产负债表!Y8 -> 0 | I43: =资产负债表!Z8 -> 0 | J43: =IF(ISERROR(F43+J44),"—",F43+J44) -> 0 | K43: =IF(ISERROR(J43+K44),"—",J43+K44) -> 0 | L43: =IF(ISERROR(K43+L44),"—",K43+L44) -> 0 | M43: =IF(ISERROR(L43+M44),"—",L43+M44) -> 0 | N43: =IF(ISERROR(M43+N44),"—",M43+N44) -> 0 | O43: =IF(ISERROR(N43+O44),"—",N43+O44) -> 0 | P43: =IF(ISERROR(O43+P44),"—",O43+P44) -> 0 | Q43: =IF(ISERROR(P43+Q44),"—",P43+Q44) -> 0 | R43: =IF(ISERROR(Q43+R44),"—",Q43+R44) -> 0 | S43: =IF(ISERROR(R43+S44),"—",R43+S44) -> 0
A44: 当期增减 | D44: =D43-资产负债表!K8 -> 0 | E44: =E43-D43 -> 0 | F44: =F43-E43 -> 0 | G44: =IF(财务基础数据!$W$2=0,0,G43-F43) -> 0 | H44: =IF(财务基础数据!$W$2<=1,0,H43-G43) -> 0 | I44: =IF(财务基础数据!$W$2<=2,0,I43-H43) -> 0
A46: 交易性金融负债 | D46: =资产负债表!O30 -> 0 | E46: =资产负债表!S30 -> 0 | F46: =资产负债表!W30 -> 0 | G46: =资产负债表!X30 -> 0 | H46: =资产负债表!Y30 -> 0 | I46: =资产负债表!Z30 -> 0 | J46: =IF(ISERROR(F46+J47),"—",F46+J47) -> 0 | K46: =IF(ISERROR(J46+K47),"—",J46+K47) -> 0 | L46: =IF(ISERROR(K46+L47),"—",K46+L47) -> 0 | M46: =IF(ISERROR(L46+M47),"—",L46+M47) -> 0 | N46: =IF(ISERROR(M46+N47),"—",M46+N47) -> 0 | O46: =IF(ISERROR(N46+O47),"—",N46+O47) -> 0 | P46: =IF(ISERROR(O46+P47),"—",O46+P47) -> 0 | Q46: =IF(ISERROR(P46+Q47),"—",P46+Q47) -> 0 | R46: =IF(ISERROR(Q46+R47),"—",Q46+R47) -> 0 | S46: =IF(ISERROR(R46+S47),"—",R46+S47) -> 0
A47: 当期增减 | D47: =D46-资产负债表!K30 -> 0 | E47: =E46-D46 -> 0 | F47: =F46-E46 -> 0 | G47: =IF(财务基础数据!$W$2=0,0,G46-F46) -> 0 | H47: =IF(财务基础数据!$W$2<=1,0,H46-G46) -> 0 | I47: =IF(财务基础数据!$W$2<=2,0,I46-H46) -> 0
A50: （二）长期投资
A51: 权益性投资 | D51: =资产负债表!O16 -> 0 | E51: =资产负债表!S16 -> 0 | F51: =资产负债表!W16 -> 0 | G51: =资产负债表!X16 -> 0 | H51: =资产负债表!Y16 -> 0 | I51: =资产负债表!Z16 -> 0 | J51: =IF(ISERROR(F51+J52),"—",F51+J52) -> 0 | K51: =IF(ISERROR(J51+K52),"—",J51+K52) -> 0 | L51: =IF(ISERROR(K51+L52),"—",K51+L52) -> 0 | M51: =IF(ISERROR(L51+M52),"—",L51+M52) -> 0 | N51: =IF(ISERROR(M51+N52),"—",M51+N52) -> 0 | O51: =IF(ISERROR(N51+O52),"—",N51+O52) -> 0 | P51: =IF(ISERROR(O51+P52),"—",O51+P52) -> 0 | Q51: =IF(ISERROR(P51+Q52),"—",P51+Q52) -> 0 | R51: =IF(ISERROR(Q51+R52),"—",Q51+R52) -> 0 | S51: =IF(ISERROR(R51+S52),"—",R51+S52) -> 0
A52: 当期增减 | D52: =D51-资产负债表!K16 -> 0 | E52: =E51-D51 -> 0 | F52: =F51-E51 -> 0 | G52: =IF(财务基础数据!$W$2=0,0,G51-F51) -> 0 | H52: =IF(财务基础数据!$W$2<=1,0,H51-G51) -> 0 | I52: =IF(财务基础数据!$W$2<=2,0,I51-H51) -> 0
A54: 债务工具 | D54: =资产负债表!O17 -> 0 | E54: =资产负债表!S17 -> 0 | F54: =资产负债表!W17 -> 0 | G54: =资产负债表!X17 -> 0 | H54: =资产负债表!Y17 -> 0 | I54: =资产负债表!Z17 -> 0 | J54: =IF(ISERROR(F54+J55),"—",F54+J55) -> 0 | K54: =IF(ISERROR(J54+K55),"—",J54+K55) -> 0 | L54: =IF(ISERROR(K54+L55),"—",K54+L55) -> 0 | M54: =IF(ISERROR(L54+M55),"—",L54+M55) -> 0 | N54: =IF(ISERROR(M54+N55),"—",M54+N55) -> 0 | O54: =IF(ISERROR(N54+O55),"—",N54+O55) -> 0 | P54: =IF(ISERROR(O54+P55),"—",O54+P55) -> 0 | Q54: =IF(ISERROR(P54+Q55),"—",P54+Q55) -> 0 | R54: =IF(ISERROR(Q54+R55),"—",Q54+R55) -> 0 | S54: =IF(ISERROR(R54+S55),"—",R54+S55) -> 0
A55: 当期增减 | D55: =D54-资产负债表!K17 -> 0 | E55: =E54-D54 -> 0 | F55: =F54-E54 -> 0 | G55: =IF(财务基础数据!$W$2=0,0,G54-F54) -> 0 | H55: =IF(财务基础数据!$W$2<=1,0,H54-G54) -> 0 | I55: =IF(财务基础数据!$W$2<=2,0,I54-H54) -> 0
A57: 可供出售投资 | D57: =资产负债表!O18 -> 0 | E57: =资产负债表!S18 -> 0 | F57: =资产负债表!W18 -> 0 | G57: =资产负债表!X18 -> 0 | H57: =资产负债表!Y18 -> 0 | I57: =资产负债表!Z18 -> 0 | J57: =IF(ISERROR(F57+J58),"—",F57+J58) -> 0 | K57: =IF(ISERROR(J57+K58),"—",J57+K58) -> 0 | L57: =IF(ISERROR(K57+L58),"—",K57+L58) -> 0 | M57: =IF(ISERROR(L57+M58),"—",L57+M58) -> 0 | N57: =IF(ISERROR(M57+N58),"—",M57+N58) -> 0 | O57: =IF(ISERROR(N57+O58),"—",N57+O58) -> 0 | P57: =IF(ISERROR(O57+P58),"—",O57+P58) -> 0 | Q57: =IF(ISERROR(P57+Q58),"—",P57+Q58) -> 0 | R57: =IF(ISERROR(Q57+R58),"—",Q57+R58) -> 0 | S57: =IF(ISERROR(R57+S58),"—",R57+S58) -> 0
...

Sheet 主要财务摘要
B1: 说明：历史年份的收盘价默认为当年最后一个交易日的价格，如需按照最新股价计算历史的每股指标，可在蓝色单元格内手工输入。
H2: =IF(目录!F8="CNY","单位：人民币",IF(目录!F8="USD","单位：美元","单位：港币"))&"("&IF(目录!D7="","元",目录!D7)&")" -> 单位：港币(百万)
B3: 项目\年度 | C3: =利润表!O4 -> 2019 | D3: =利润表!S4 -> 2020 | E3: =利润表!W4 -> 2021 | F3: =利润表!AA4 -> 2022E | G3: =利润表!AB4 -> 2023 | H3: =利润表!AC4 -> 2024
B4: ="总股本("&目录!D7&")" -> 总股本(百万) | C4: =IF(财务基础数据!O128="",目录!F7*1000000*目录!D6,财务基础数据!O128*目录!D6) -> #VALUE! | D4: =IF(财务基础数据!S128="",目录!F7*1000000*目录!D6,财务基础数据!S128*目录!D6) -> #VALUE! | E4: =IF(财务基础数据!W128="",目录!F7*1000000*目录!D6,财务基础数据!W128*目录!D6) -> #VALUE! | F4: =IF(ISERROR(目录!F7*1000000*目录!D6),"—",目录!F7*1000000*目录!D6) -> — | G4: =F4 -> — | H4: =G4 -> —
B5: 收盘价（港币） | C5: =财务基础数据!$O$129 -> 0 | D5: =财务基础数据!$S$129 -> 0 | E5: =财务基础数据!$W$129 -> 0 | F5: =目录!$F$6 -> XXXX | G5: =目录!$F$6 -> XXXX | H5: =目录!$F$6 -> XXXX
B6: 收盘价（汇率换算后） | C6: =IF(目录!$F$10=0,C5,C5*目录!$F$10) -> 0 | D6: =IF(目录!$F$10=0,D5,D5*目录!$F$10) -> 0 | E6: =IF(目录!$F$10=0,E5,E5*目录!$F$10) -> 0 | F6: =IF(目录!$F$10=0,F5,F5*目录!$F$10) -> XXXX | G6: =F6 -> XXXX | H6: =G6 -> XXXX
B7: EV/EBITDA | C7: =IF(ISERROR(((C4*C6)+资产负债表!O55-资产负债表!O6)/利润表!O34),"—",((C4*C6)+资产负债表!O55-资产负债表!O6)/利润表!O34) -> — | D7: =IF(ISERROR(((D4*D6)+资产负债表!S55-资产负债表!S6)/利润表!S34),"—",((D4*D6)+资产负债表!S55-资产负债表!S6)/利润表!S34) -> — | E7: =IF(ISERROR(((E4*E6)+资产负债表!W55-资产负债表!W6)/利润表!W34),"—",((E4*E6)+资产负债表!W55-资产负债表!W6)/利润表!W34) -> — | F7: =IF(ISERROR(((F4*F6)+资产负债表!AA55-资产负债表!AA6)/利润表!AA34),"—",((F4*F6)+资产负债表!AA55-资产负债表!AA6)/利润表!AA34) -> — | G7: =IF(ISERROR(((G4*G6)+资产负债表!AB55-资产负债表!AB6)/利润表!AB34),"—",((G4*G6)+资产负债表!AB55-资产负债表!AB6)/利润表!AB34) -> — | H7: =IF(ISERROR(((H4*H6)+资产负债表!AC55-资产负债表!AC6)/利润表!AC34),"—",((H4*H6)+资产负债表!AC55-资产负债表!AC6)/利润表!AC34) -> —
B8: EV/销售收入 | C8: =IF(ISERROR(((C4*C6)+资产负债表!O55-资产负债表!O6)/利润表!O6),"—",((C4*C6)+资产负债表!O55-资产负债表!O6)/利润表!O6) -> — | D8: =IF(ISERROR(((D4*D6)+资产负债表!S55-资产负债表!S6)/利润表!S6),"—",((D4*D6)+资产负债表!S55-资产负债表!S6)/利润表!S6) -> — | E8: =IF(ISERROR(((E4*E6)+资产负债表!W55-资产负债表!W6)/利润表!W6),"—",((E4*E6)+资产负债表!W55-资产负债表!W6)/利润表!W6) -> — | F8: =IF(ISERROR(((F4*F6)+资产负债表!AA55-资产负债表!AA6)/利润表!AA6),"—",((F4*F6)+资产负债表!AA55-资产负债表!AA6)/利润表!AA6) -> — | G8: =IF(ISERROR(((G4*G6)+资产负债表!AB55-资产负债表!AB6)/利润表!AB6),"—",((G4*G6)+资产负债表!AB55-资产负债表!AB6)/利润表!AB6) -> — | H8: =IF(ISERROR(((H4*H6)+资产负债表!AC55-资产负债表!AC6)/利润表!AC6),"—",((H4*H6)+资产负债表!AC55-资产负债表!AC6)/利润表!AC6) -> —
B9: 营业收入增长率 | C9: =C16 -> — | D9: =D16 -> — | E9: =E16 -> — | F9: =F16 -> — | G9: =G16 -> — | H9: =H16 -> —
B10: 归母净利润增长率 | C10: =C19 -> — | D10: =D19 -> — | E10: =E19 -> — | F10: =F19 -> — | G10: =G19 -> — | H10: =H19 -> —
B11: 净资产收益率ROE | C11: =报表摘要!K35 -> — | D11: =报表摘要!L35 -> — | E11: =报表摘要!M35 -> — | F11: =报表摘要!N35 -> — | G11: =报表摘要!O35 -> — | H11: =报表摘要!P35 -> —
B12: 总资产收益率ROA | C12: =报表摘要!K36 -> — | D12: =报表摘要!L36 -> — | E12: =报表摘要!M36 -> — | F12: =报表摘要!N36 -> — | G12: =报表摘要!O36 -> — | H12: =报表摘要!P36 -> —
B14: 盈利预测 | C14: =C3 -> 2019 | D14: =D3 -> 2020 | E14: =E3 -> 2021 | F14: =F3 -> 2022E | G14: =G3 -> 2023 | H14: =H3 -> 2024
B15: 营业总收入 | C15: =利润表!O6+利润表!O7 -> 0 | D15: =利润表!S6+利润表!S7 -> 0 | E15: =利润表!W6+利润表!W7 -> 0 | F15: =利润表!AA6+利润表!AA7 -> 0 | G15: =利润表!AB6+利润表!AB7 -> 0 | H15: =利润表!AC6+利润表!AC7 -> 0
B16: 增长率（%） | C16: =IF(ISERROR((利润表!O6+利润表!O7-利润表!K6-利润表!K7)/ABS(利润表!K6+利润表!K7)),"—",(利润表!O6+利润表!O7-利润表!K6-利润表!K7)/ABS(利润表!K6+利润表!K7)) -> — | D16: =IF(ISERROR((D15-C15)/ABS(C15)),"—",(D15-C15)/ABS(C15)) -> — | E16: =IF(ISERROR((E15-D15)/ABS(D15)),"—",(E15-D15)/ABS(D15)) -> — | F16: =IF(ISERROR((F15-E15)/ABS(E15)),"—",(F15-E15)/ABS(E15)) -> — | G16: =IF(ISERROR((G15-F15)/ABS(F15)),"—",(G15-F15)/ABS(F15)) -> — | H16: =IF(ISERROR((H15-G15)/ABS(G15)),"—",(H15-G15)/ABS(G15)) -> —
B17: EBITDA | C17: =利润表!O34 -> 0 | D17: =利润表!S34 -> 0 | E17: =利润表!W34 -> 0 | F17: =利润表!AA34 -> 0 | G17: =利润表!AB34 -> 0 | H17: =利润表!AC34 -> 0
B18: 归母净利润 | C18: =利润表!O29 -> 0 | D18: =利润表!S29 -> 0 | E18: =利润表!W29 -> 0 | F18: =利润表!AA29 -> 0 | G18: =利润表!AB29 -> 0 | H18: =利润表!AC29 -> 0
B19: 增长率（%） | C19: =报表摘要!K41 -> — | D19: =报表摘要!L41 -> — | E19: =报表摘要!M41 -> — | F19: =报表摘要!N41 -> — | G19: =报表摘要!O41 -> — | H19: =报表摘要!P41 -> —
B20: 每股收益EPS | C20: =IF(ISERROR(财务基础数据!$O$32),"—",财务基础数据!$O$32) -> 0 | D20: =IF(ISERROR(财务基础数据!$S$32),"—",财务基础数据!$S$32) -> 0 | E20: =IF(ISERROR(财务基础数据!$W$32),"—",财务基础数据!$W$32) -> 0 | F20: =IF(ISERROR(F18/F4),"—",F18/F4) -> — | G20: =IF(ISERROR(G18/G4),"—",G18/G4) -> — | H20: =IF(ISERROR(H18/H4),"—",H18/H4) -> —
B21: 每股净资产 | C21: =IF(ISERROR((资产负债表!O45)/C4),"—",(资产负债表!O45)/C4) -> — | D21: =IF(ISERROR((资产负债表!S45)/D4),"—",(资产负债表!S45)/D4) -> — | E21: =IF(ISERROR((资产负债表!W45)/E4),"—",(资产负债表!W45)/E4) -> — | F21: =IF(ISERROR((资产负债表!AA45)/F4),"—",(资产负债表!AA45)/F4) -> — | G21: =IF(ISERROR((资产负债表!AB45)/G4),"—",(资产负债表!AB45)/G4) -> — | H21: =IF(ISERROR((资产负债表!AC45)/H4),"—",(资产负债表!AC45)/H4) -> —
B22: 市盈率（P/E） | C22: =IF(ISERROR(C6/C20),"—",C6/C20) -> — | D22: =IF(ISERROR(D6/D20),"—",D6/D20) -> — | E22: =IF(ISERROR(E6/E20),"—",E6/E20) -> — | F22: =IF(ISERROR(F6/F20),"—",F6/F20) -> — | G22: =IF(ISERROR(G6/G20),"—",G6/G20) -> — | H22: =IF(ISERROR(H6/H20),"—",H6/H20) -> —
B23: 市净率（P/B） | C23: =IF(ISERROR(C6/C21),"—",C6/C21) -> — | D23: =IF(ISERROR(D6/D21),"—",D6/D21) -> — | E23: =IF(ISERROR(E6/E21),"—",E6/E21) -> — | F23: =IF(ISERROR(F6/F21),"—",F6/F21) -> — | G23: =IF(ISERROR(G6/G21),"—",G6/G21) -> — | H23: =IF(ISERROR(H6/H21),"—",H6/H21) -> —
B24: PE/G | C24: =IF(OR(ISERROR(C22/(C19*100)),C10<0),"—",C22/(C19*100)) -> — | D24: =IF(OR(ISERROR(D22/(D19*100)),D10<0),"—",D22/(D19*100)) -> — | E24: =IF(OR(ISERROR(E22/(E19*100)),E10<0),"—",E22/(E19*100)) -> — | F24: =IF(OR(ISERROR(F22/(F19*100)),F10<0),"—",F22/(F19*100)) -> — | G24: =IF(OR(ISERROR(G22/(G19*100)),G10<0),"—",G22/(G19*100)) -> — | H24: =IF(OR(ISERROR(H22/(H19*100)),H10<0),"—",H22/(H19*100)) -> —
B25: 每股经营性现金流 | C25: =IF(ISERROR(现金流量表!O16/C4),"—",现金流量表!O16/C4) -> — | D25: =IF(ISERROR(现金流量表!S16/D4),"—",现金流量表!S16/D4) -> — | E25: =IF(ISERROR(现金流量表!W16/E4),"—",现金流量表!W16/E4) -> — | F25: =IF(ISERROR(现金流量表!AA16/F4),"—",现金流量表!AA16/F4) -> — | G25: =IF(ISERROR(现金流量表!AB16/G4),"—",现金流量表!AB16/G4) -> — | H25: =IF(ISERROR(现金流量表!AC16/H4),"—",现金流量表!AC16/H4) -> —
E129: =财务基础数据!$S$128 -> 0

Sheet 报表摘要
B3: 损益表 | H3: =主要财务摘要!$H$2 -> 单位：港币(百万) | J3: 资产负债表 | P3: =主要财务摘要!$H$2 -> 单位：港币(百万)
C4: =利润表!O4 -> 2019 | D4: =利润表!S4 -> 2020 | E4: =利润表!W4 -> 2021 | F4: =利润表!AA4 -> 2022E | G4: =利润表!AB4 -> 2023 | H4: =利润表!AC4 -> 2024 | K4: =C4 -> 2019 | L4: =D4 -> 2020 | M4: =E4 -> 2021 | N4: =F4 -> 2022E | O4: =G4 -> 2023 | P4: =H4 -> 2024
B5: 营业收入 | C5: =利润表!O6 -> 0 | D5: =利润表!S6 -> 0 | E5: =利润表!W6 -> 0 | F5: =利润表!AA6 -> 0 | G5: =利润表!AB6 -> 0 | H5: =利润表!AC6 -> 0 | J5: 货币资金 | K5: =资产负债表!O6 -> 0 | L5: =资产负债表!S6 -> 0 | M5: =资产负债表!W6 -> 0 | N5: =资产负债表!AA6 -> 0 | O5: =资产负债表!AB6 -> 0 | P5: =资产负债表!AC6 -> 0
B6: 增长率 | C6: =IF(ISERROR((利润表!O6-利润表!K6)/ABS(利润表!K6)),"—",(利润表!O6-利润表!K6)/ABS(利润表!K6)) -> — | D6: =IF(ISERROR((D5-C5)/ABS(C5)),"—",(D5-C5)/ABS(C5)) -> — | E6: =IF(ISERROR((E5-D5)/ABS(D5)),"—",(E5-D5)/ABS(D5)) -> — | F6: =IF(ISERROR((F5-E5)/ABS(E5)),"—",(F5-E5)/ABS(E5)) -> — | G6: =IF(ISERROR((G5-F5)/ABS(F5)),"—",(G5-F5)/ABS(F5)) -> — | H6: =IF(ISERROR((H5-G5)/ABS(G5)),"—",(H5-G5)/ABS(G5)) -> — | J6: 应收款项 | K6: =资产负债表!O9+资产负债表!O10 -> 0 | L6: =资产负债表!S9+资产负债表!S10 -> 0 | M6: =资产负债表!W9+资产负债表!W10 -> 0 | N6: =资产负债表!AA9+资产负债表!AA10 -> 0 | O6: =资产负债表!AB9+资产负债表!AB10 -> 0 | P6: =资产负债表!AC9+资产负债表!AC10 -> 0
B7: 营业成本 | C7: =利润表!O9 -> 0 | D7: =利润表!S9 -> 0 | E7: =利润表!W9 -> 0 | F7: =利润表!AA9 -> 0 | G7: =利润表!AB9 -> 0 | H7: =利润表!AC9 -> 0 | J7: 存货 | K7: =资产负债表!O11 -> 0 | L7: =资产负债表!S11 -> 0 | M7: =资产负债表!W11 -> 0 | N7: =资产负债表!AA11 -> 0 | O7: =资产负债表!AB11 -> 0 | P7: =资产负债表!AC11 -> 0
B8: %销售收入 | C8: =IF(ISERROR(C7/C5),"—",C7/C5) -> — | D8: =IF(ISERROR(D7/D5),"—",D7/D5) -> — | E8: =IF(ISERROR(E7/E5),"—",E7/E5) -> — | F8: =IF(ISERROR(F7/F5),"—",F7/F5) -> — | G8: =IF(ISERROR(G7/G5),"—",G7/G5) -> — | H8: =IF(ISERROR(H7/H5),"—",H7/H5) -> — | J8: 其他流动资产 | K8: =K9-K5-K6-K7 -> 0 | L8: =L9-L5-L6-L7 -> 0 | M8: =M9-M5-M6-M7 -> 0 | N8: =N9-N5-N6-N7 -> 0 | O8: =O9-O5-O6-O7 -> 0 | P8: =P9-P5-P6-P7 -> 0
B9: 毛利 | C9: =利润表!O16 -> 0 | D9: =利润表!S16 -> 0 | E9: =利润表!W16 -> 0 | F9: =利润表!AA16 -> 0 | G9: =利润表!AB16 -> 0 | H9: =利润表!AC16 -> 0 | J9: 流动资产 | K9: =资产负债表!O13 -> 0 | L9: =资产负债表!S13 -> 0 | M9: =资产负债表!W13 -> 0 | N9: =资产负债表!AA13 -> 0 | O9: =资产负债表!AB13 -> 0 | P9: =资产负债表!AC13 -> 0
B10: %销售收入 | C10: =IF(ISERROR(C9/C5),"—",C9/C5) -> — | D10: =IF(ISERROR(D9/D5),"—",D9/D5) -> — | E10: =IF(ISERROR(E9/E5),"—",E9/E5) -> — | F10: =IF(ISERROR(F9/F5),"—",F9/F5) -> — | G10: =IF(ISERROR(G9/G5),"—",G9/G5) -> — | H10: =IF(ISERROR(H9/H5),"—",H9/H5) -> — | J10: 权益性投资 | K10: =资产负债表!O16 -> 0 | L10: =资产负债表!S16 -> 0 | M10: =资产负债表!W16 -> 0 | N10: =资产负债表!AA16 -> 0 | O10: =资产负债表!AB16 -> 0 | P10: =资产负债表!AC16 -> 0
B11: 其他收入 | C11: =利润表!O7 -> 0 | D11: =利润表!S7 -> 0 | E11: =利润表!W7 -> 0 | F11: =利润表!AA7 -> 0 | G11: =利润表!AB7 -> 0 | H11: =利润表!AC7 -> 0 | J11: 固定资产 | K11: =资产负债表!O15 -> 0 | L11: =资产负债表!S15 -> 0 | M11: =资产负债表!W15 -> 0 | N11: =资产负债表!AA15 -> 0 | O11: =资产负债表!AB15 -> 0 | P11: =资产负债表!AC15 -> 0
B12: %销售收入 | C12: =IF(ISERROR(C11/C5),"—",C11/C5) -> — | D12: =IF(ISERROR(D11/D5),"—",D11/D5) -> — | E12: =IF(ISERROR(E11/E5),"—",E11/E5) -> — | F12: =IF(ISERROR(F11/F5),"—",F11/F5) -> — | G12: =IF(ISERROR(G11/G5),"—",G11/G5) -> — | H12: =IF(ISERROR(H11/H5),"—",H11/H5) -> — | J12: 无形资产 | K12: =资产负债表!O20 -> 0 | L12: =资产负债表!S20 -> 0 | M12: =资产负债表!W20 -> 0 | N12: =资产负债表!AA20 -> 0 | O12: =资产负债表!AB20 -> 0 | P12: =资产负债表!AC20 -> 0
B13: 销售费用 | C13: =利润表!O12 -> 0 | D13: =利润表!S12 -> 0 | E13: =利润表!W12 -> 0 | F13: =利润表!AA12 -> 0 | G13: =利润表!AB12 -> 0 | H13: =利润表!AC12 -> 0 | J13: 非流动资产 | K13: =资产负债表!O23 -> 0 | L13: =资产负债表!S23 -> 0 | M13: =资产负债表!W23 -> 0 | N13: =资产负债表!AA23 -> 0 | O13: =资产负债表!AB23 -> 0 | P13: =资产负债表!AC23 -> 0
B14: %销售收入 | C14: =IF(ISERROR(C13/C5),"—",C13/C5) -> — | D14: =IF(ISERROR(D13/D5),"—",D13/D5) -> — | E14: =IF(ISERROR(E13/E5),"—",E13/E5) -> — | F14: =IF(ISERROR(F13/F5),"—",F13/F5) -> — | G14: =IF(ISERROR(G13/G5),"—",G13/G5) -> — | H14: =IF(ISERROR(H13/H5),"—",H13/H5) -> — | J14: 资产总计 | K14: =资产负债表!O24 -> 0 | L14: =资产负债表!S24 -> 0 | M14: =资产负债表!W24 -> 0 | N14: =资产负债表!AA24 -> 0 | O14: =资产负债表!AB24 -> 0 | P14: =资产负债表!AC24 -> 0
B15: 管理费用 | C15: =利润表!O13 -> 0 | D15: =利润表!S13 -> 0 | E15: =利润表!W13 -> 0 | F15: =利润表!AA13 -> 0 | G15: =利润表!AB13 -> 0 | H15: =利润表!AC13 -> 0 | J15: 应付款项 | K15: =资产负债表!O28 -> 0 | L15: =资产负债表!S28 -> 0 | M15: =资产负债表!W28 -> 0 | N15: =资产负债表!AA28 -> 0 | O15: =资产负债表!AB28 -> 0 | P15: =资产负债表!AC28 -> 0
B16: %销售收入 | C16: =IF(ISERROR(C15/C5),"—",C15/C5) -> — | D16: =IF(ISERROR(D15/D5),"—",D15/D5) -> — | E16: =IF(ISERROR(E15/E5),"—",E15/E5) -> — | F16: =IF(ISERROR(F15/F5),"—",F15/F5) -> — | G16: =IF(ISERROR(G15/G5),"—",G15/G5) -> — | H16: =IF(ISERROR(H15/H5),"—",H15/H5) -> — | J16: 短期借款 | K16: =资产负债表!O31 -> 0 | L16: =资产负债表!S31 -> 0 | M16: =资产负债表!W31 -> 0 | N16: =资产负债表!AA31 -> 0 | O16: =资产负债表!AB31 -> 0 | P16: =资产负债表!AC31 -> 0
B17: 研发费用 | C17: =利润表!O14 -> 0 | D17: =利润表!S14 -> 0 | E17: =利润表!W14 -> 0 | F17: =利润表!AA14 -> 0 | G17: =利润表!AB14 -> 0 | H17: =利润表!AC14 -> 0 | J17: 其他流动负债 | K17: =K18-K15-K16 -> 0 | L17: =L18-L15-L16 -> 0 | M17: =M18-M15-M16 -> 0 | N17: =N18-N15-N16 -> 0 | O17: =O18-O15-O16 -> 0 | P17: =P18-P15-P16 -> 0
B18: %销售收入 | C18: =IF(ISERROR(C17/C5),"—",C17/C5) -> — | D18: =IF(ISERROR(D17/D5),"—",D17/D5) -> — | E18: =IF(ISERROR(E17/E5),"—",E17/E5) -> — | F18: =IF(ISERROR(F17/F5),"—",F17/F5) -> — | G18: =IF(ISERROR(G17/G5),"—",G17/G5) -> — | H18: =IF(ISERROR(H17/H5),"—",H17/H5) -> — | J18: 流动负债 | K18: =资产负债表!O33 -> 0 | L18: =资产负债表!S33 -> 0 | M18: =资产负债表!W33 -> 0 | N18: =资产负债表!AA33 -> 0 | O18: =资产负债表!AB33 -> 0 | P18: =资产负债表!AC33 -> 0
B19: 财务费用 | C19: =利润表!O19-利润表!O18 -> 0 | D19: =利润表!S19-利润表!S18 -> 0 | E19: =利润表!W19-利润表!W18 -> 0 | F19: =利润表!AA19-利润表!AA18 -> 0 | G19: =利润表!AB19-利润表!AB18 -> 0 | H19: =利润表!AC19-利润表!AC18 -> 0 | J19: 长期债务 | K19: =资产负债表!O35 -> 0 | L19: =资产负债表!S35 -> 0 | M19: =资产负债表!W35 -> 0 | N19: =资产负债表!AA35 -> 0 | O19: =资产负债表!AB35 -> 0 | P19: =资产负债表!AC35 -> 0
B20: %销售收入 | C20: =IF(ISERROR(C19/C5),"—",C19/C5) -> — | D20: =IF(ISERROR(D19/D5),"—",D19/D5) -> — | E20: =IF(ISERROR(E19/E5),"—",E19/E5) -> — | F20: =IF(ISERROR(F19/F5),"—",F19/F5) -> — | G20: =IF(ISERROR(G19/G5),"—",G19/G5) -> — | H20: =IF(ISERROR(H19/H5),"—",H19/H5) -> — | J20: 其他长期负债 | K20: =K21-K19 -> 0 | L20: =L21-L19 -> 0 | M20: =M21-M19 -> 0 | N20: =N21-N19 -> 0 | O20: =O21-O19 -> 0 | P20: =P21-P19 -> 0
B21: 息税前利润（EBIT） | C21: =利润表!O35 -> 0 | D21: =利润表!S35 -> 0 | E21: =利润表!W35 -> 0 | F21: =利润表!AA35 -> 0 | G21: =利润表!AB35 -> 0 | H21: =利润表!AC35 -> 0 | J21: 非流动负债 | K21: =资产负债表!O37 -> 0 | L21: =资产负债表!S37 -> 0 | M21: =资产负债表!W37 -> 0 | N21: =资产负债表!AA37 -> 0 | O21: =资产负债表!AB37 -> 0 | P21: =资产负债表!AC37 -> 0
B22: %销售收入 | C22: =IF(ISERROR(C21/C5),"—",C21/C5) -> — | D22: =IF(ISERROR(D21/D5),"—",D21/D5) -> — | E22: =IF(ISERROR(E21/E5),"—",E21/E5) -> — | F22: =IF(ISERROR(F21/F5),"—",F21/F5) -> — | G22: =IF(ISERROR(G21/G5),"—",G21/G5) -> — | H22: =IF(ISERROR(H21/H5),"—",H21/H5) -> — | J22: 负债总计 | K22: =资产负债表!O38 -> 0 | L22: =资产负债表!S38 -> 0 | M22: =资产负债表!W38 -> 0 | N22: =资产负债表!AA38 -> 0 | O22: =资产负债表!AB38 -> 0 | P22: =资产负债表!AC38 -> 0
B23: 投资收益 | C23: =利润表!O20 -> 0 | D23: =利润表!S20 -> 0 | E23: =利润表!W20 -> 0 | F23: =利润表!AA20 -> 0 | G23: =利润表!AB20 -> 0 | H23: =利润表!AC20 -> 0 | J23: 归属母公司股东权益 | K23: =资产负债表!O45 -> 0 | L23: =资产负债表!S45 -> 0 | M23: =资产负债表!W45 -> 0 | N23: =资产负债表!AA45 -> 0 | O23: =资产负债表!AB45 -> 0 | P23: =资产负债表!AC45 -> 0
B24: %税前利润 | C24: =IF(ISERROR(C23/C25),"—",C23/C25) -> — | D24: =IF(ISERROR(D23/D25),"—",D23/D25) -> — | E24: =IF(ISERROR(E23/E25),"—",E23/E25) -> — | F24: =IF(ISERROR(F23/F25),"—",F23/F25) -> — | G24: =IF(ISERROR(G23/G25),"—",G23/G25) -> — | H24: =IF(ISERROR(H23/H25),"—",H23/H25) -> — | J24: 少数股东权益 | K24: =资产负债表!O46 -> 0 | L24: =资产负债表!S46 -> 0 | M24: =资产负债表!W46 -> 0 | N24: =资产负债表!AA46 -> 0 | O24: =资产负债表!AB46 -> 0 | P24: =资产负债表!AC46 -> 0
B25: 除税前利润 | C25: =利润表!O24 -> 0 | D25: =利润表!S24 -> 0 | E25: =利润表!W24 -> 0 | F25: =利润表!AA24 -> 0 | G25: =利润表!AB24 -> 0 | H25: =利润表!AC24 -> 0 | J25: 负债股东权益合计 | K25: =资产负债表!O48 -> 0 | L25: =资产负债表!S48 -> 0 | M25: =资产负债表!W48 -> 0 | N25: =资产负债表!AA48 -> 0 | O25: =资产负债表!AB48 -> 0 | P25: =资产负债表!AC48 -> 0
B26: 利润率 | C26: =IF(ISERROR(C25/C5),"—",C25/C5) -> — | D26: =IF(ISERROR(D25/D5),"—",D25/D5) -> — | E26: =IF(ISERROR(E25/E5),"—",E25/E5) -> — | F26: =IF(ISERROR(F25/F5),"—",F25/F5) -> — | G26: =IF(ISERROR(G25/G5),"—",G25/G5) -> — | H26: =IF(ISERROR(H25/H5),"—",H25/H5) -> —
B27: 所得税 | C27: =利润表!O25 -> 0 | D27: =利润表!S25 -> 0 | E27: =利润表!W25 -> 0 | F27: =利润表!AA25 -> 0 | G27: =利润表!AB25 -> 0 | H27: =利润表!AC25 -> 0 | J27: 比率分析
B28: 所得税率 | C28: =IF(ISERROR(C27/C25),"—",C27/C25) -> — | D28: =IF(ISERROR(D27/D25),"—",D27/D25) -> — | E28: =IF(ISERROR(E27/E25),"—",E27/E25) -> — | F28: =IF(ISERROR(F27/F25),"—",F27/F25) -> — | G28: =IF(ISERROR(G27/G25),"—",G27/G25) -> — | H28: =IF(ISERROR(H27/H25),"—",H27/H25) -> — | K28: =C4 -> 2019 | L28: =D4 -> 2020 | M28: =E4 -> 2021 | N28: =F4 -> 2022E | O28: =G4 -> 2023 | P28: =H4 -> 2024
B29: 净利润(含少数股东损益) | C29: =C25-C27 -> 0 | D29: =D25-D27 -> 0 | E29: =E25-E27 -> 0 | F29: =F25-F27 -> 0 | G29: =G25-G27 -> 0 | H29: =H25-H27 -> 0 | J29: 每股指标
B30: 少数股东损益 | C30: =利润表!O27 -> 0 | D30: =利润表!S27 -> 0 | E30: =利润表!W27 -> 0 | F30: =利润表!AA27 -> 0 | G30: =利润表!AB27 -> 0 | H30: =利润表!AC27 -> 0 | J30: 每股收益 | K30: =主要财务摘要!C20 -> 0 | L30: =主要财务摘要!D20 -> 0 | M30: =主要财务摘要!E20 -> 0 | N30: =主要财务摘要!F20 -> — | O30: =主要财务摘要!G20 -> — | P30: =主要财务摘要!H20 -> —
B31: 归属于母公司的净利润 | C31: =利润表!O29 -> 0 | D31: =利润表!S29 -> 0 | E31: =利润表!W29 -> 0 | F31: =利润表!AA29 -> 0 | G31: =利润表!AB29 -> 0 | H31: =利润表!AC29 -> 0 | J31: 每股净资产 | K31: =主要财务摘要!C21 -> — | L31: =主要财务摘要!D21 -> — | M31: =主要财务摘要!E21 -> — | N31: =主要财务摘要!F21 -> — | O31: =主要财务摘要!G21 -> — | P31: =主要财务摘要!H21 -> —
B32: 增长率 | C32: =IF(ISERROR((利润表!O29-利润表!K29)/ABS(利润表!K29)),"—",(利润表!O29-利润表!K29)/ABS(利润表!K29)) -> — | D32: =IF(ISERROR((D31-C31)/ABS(C31)),"—",(D31-C31)/ABS(C31)) -> — | E32: =IF(ISERROR((E31-D31)/ABS(D31)),"—",(E31-D31)/ABS(D31)) -> — | F32: =IF(ISERROR((F31-E31)/ABS(E31)),"—",(F31-E31)/ABS(E31)) -> — | G32: =IF(ISERROR((G31-F31)/ABS(F31)),"—",(G31-F31)/ABS(F31)) -> — | H32: =IF(ISERROR((H31-G31)/ABS(G31)),"—",(H31-G31)/ABS(G31)) -> — | J32: 每股经营现金净流 | K32: =主要财务摘要!C25 -> — | L32: =主要财务摘要!D25 -> — | M32: =主要财务摘要!E25 -> — | N32: =主要财务摘要!F25 -> — | O32: =主要财务摘要!G25 -> — | P32: =主要财务摘要!H25 -> —
B33: 净利率 | C33: =IF(ISERROR(C31/C5),"—",C31/C5) -> — | D33: =IF(ISERROR(D31/D5),"—",D31/D5) -> — | E33: =IF(ISERROR(E31/E5),"—",E31/E5) -> — | F33: =IF(ISERROR(F31/F5),"—",F31/F5) -> — | G33: =IF(ISERROR(G31/G5),"—",G31/G5) -> — | H33: =IF(ISERROR(H31/H5),"—",H31/H5) -> — | J33: 每股股利 | K33: =资产预测!D100 -> 0 | L33: =资产预测!E100 -> 0 | M33: =资产预测!F100 -> 0 | N33: =IF(ISERROR(资产预测!J100),"—",资产预测!J100) -> 0 | O33: =IF(ISERROR(资产预测!K100),"—",资产预测!K100) -> 0 | P33: =IF(ISERROR(资产预测!L100),"—",资产预测!L100) -> 0
J34: 回报率
J35: 净资产收益率 | K35: =IF(ISERROR(C31/K23),"—",C31/K23) -> — | L35: =IF(ISERROR(D31/L23),"—",D31/L23) -> — | M35: =IF(ISERROR(E31/M23),"—",E31/M23) -> — | N35: =IF(ISERROR(F31/N23),"—",F31/N23) -> — | O35: =IF(ISERROR(G31/O23),"—",G31/O23) -> — | P35: =IF(ISERROR(H31/P23),"—",H31/P23) -> —
J36: 总资产收益率 | K36: =IF(ISERROR(C31/K25),"—",C31/K25) -> — | L36: =IF(ISERROR(D31/L25),"—",D31/L25) -> — | M36: =IF(ISERROR(E31/M25),"—",E31/M25) -> — | N36: =IF(ISERROR(F31/N25),"—",F31/N25) -> — | O36: =IF(ISERROR(G31/O25),"—",G31/O25) -> — | P36: =IF(ISERROR(H31/P25),"—",H31/P25) -> —
